Workbook
Name FairValuePerShare: Valuation!$B$6
Name CurrentPrice: Valuation!$B$7
Name UpsidePct: Valuation!$B$8
Name SnapshotId: Summary!$B$39
Name SnapshotHash: Summary!$B$40
Name Years_Header: 'Income Statement'!$B$4:$I$4
Name Revenue_Series: 'Income Statement'!$B$5:$I$5
Name EBITDA_Series: 'Income Statement'!$B$10:$I$10
Name NetIncome_Series: 'Income Statement'!$B$20:$I$20
Name EPS_Series: 'Income Statement'!$B$25:$I$25
Name CFO_Series: 'Cash Flow'!$B$13:$I$13
Name Capex_Series: 'Cash Flow'!$B$15:$I$15

Sheet Summary
A1: Bajaj Finance Limited (BAJFINANCE.NS)
A2: Non-Banking Financial Company (NBFC) . NSE . base period FY26 . ₹ Crores unless stated
A5: VALUATION AND DECISION
A6: Current price (INR) | B6: ='Valuation'!B7 -> 939.1
A7: Fair value per share (INR) | B7: ='Valuation'!B6 -> 364.92
A8: Model valuation spread vs price (an unaudited model output, not a rating; not independently audited) | B8: ='Valuation'!B8 -> -0.61141518
A9: Primary method | B9: RESIDUAL_INCOME_PB - Multi-Stage Residual Income (100%)
A10: Confidence | B10: HIGH
A11: Status | B11: Non-Banking Financial Company (NBFC) valued via RESIDUAL_INCOME_PB. 54/54 accounting invariants passed; reasonableness assessment ECONOMICALLY_SOUND.
A13: KEY FINANCIALS (₹ Crores)
B14: Source sheet | C14: FY24A | D14: FY25A | E14: FY26A | F14: FY27E | G14: FY28E | H14: FY29E | I14: FY30E | J14: FY31E
A15: Revenue from operations | B15: Income Statement | C15: ='Income Statement'!B5 -> 48319.6 | D15: ='Income Statement'!C5 -> 61204.9 | E15: ='Income Statement'!D5 -> 72783.1 | F15: n/a | G15: n/a | H15: n/a | I15: n/a | J15: n/a
A16: EBITDA | B16: Income Statement | C16: n/a | D16: n/a | E16: n/a | F16: n/a | G16: n/a | H16: n/a | I16: n/a | J16: n/a
A17: EBITDA margin | B17: Income Statement | C17: n/a | D17: n/a | E17: n/a | F17: n/a | G17: n/a | H17: n/a | I17: n/a | J17: n/a
A18: Net income | B18: Income Statement | C18: ='Income Statement'!B20 -> 14451.2 | D18: ='Income Statement'!C20 -> 16637.8 | E18: ='Income Statement'!D20 -> 19017.4 | F18: n/a | G18: n/a | H18: n/a | I18: n/a | J18: n/a
A19: Diluted EPS (INR) | B19: Income Statement | C19: n/a | D19: n/a | E19: n/a | F19: n/a | G19: n/a | H19: n/a | I19: n/a | J19: n/a
A20: Free cash flow (CFO - CapEx) | B20: Cash Flow | C20: n/a | D20: n/a | E20: n/a | F20: n/a | G20: n/a | H20: n/a | I20: n/a | J20: n/a
A21: Return on equity | B21: engine ratio | C21: n/a | D21: n/a | E21: n/a | F21: n/a | G21: n/a | H21: n/a | I21: n/a | J21: n/a
A23: RELATIVE POSITION (subject vs peer median; detail on the Peers sheet)
A24: Metric | B24: Subject | C24: Peer median | D24: Peers (n)
A25: P/E | B25: 30.244103 | C25: ='Peers'!C14 -> 12.716183 | D25: 5
A26: P/B | B26: 4.7465802 | C26: ='Peers'!D14 -> 1.5308752 | D26: 4
A27: ROE | B27: 15.694234 | C27: ='Peers'!F14 -> 11.590021 | D27: 4
A29: RISKS AND INVALIDATORS
A30: - Withheld: Historical EPS (share basis)
A31: - Withheld: DCF cross-check
A32: - Withheld: Segment analysis
A33: - Withheld: Line-by-line statutory statements
A35: Every figure on this sheet links to its source sheet; nothing is calculated here. Formulas appear only where they reproduce the engine's own figure.
A36: Research only; not investment advice. A withheld, low-confidence or experimental output says so rather than offering a number.
A38: EXPORT SNAPSHOT (one immutable analysis behind every export of this model)
A39: Snapshot ID | B39: snap_BAJFINANCE_NS_14a597949db9
A40: Snapshot SHA-256 | B40: 14a597949db9912c1fbde077b91e080580c0a1d505ad2f73993429b3fce0ad91
A41: Built at | B41: 2026-11-01T15:05:35.584Z
A42: Analysis status | B42: SUCCESS
A43: Price | B43: INR 939.1
A44: Price as of | B44: 2026-10-30T00:00:00.000Z
A45: Price stale | B45: false
A46: Price source | B46: NSE official close (UDiFF bhavcopy) + Screener.in structured dataset
A47: Assumptions SHA-256 | B47: 74234e98afe7498fb5daf1f36ac2d78acc339464f950703b8c019892f982b90b
...

Sheet Income Statement
A1: Income Statement (₹ Crores)
A2: Bajaj Finance Limited (BAJFINANCE.NS) . Consolidated . base period FY26 . LENDER/INSURER: generic operating layout, total income shown as revenue, lines do not foot; see Lender Statements
A3: A = reported . E = forecast . "n/a" = the source does not carry the line (never zero)
B4: FY24A | C4: FY25A | D4: FY26A | E4: FY27E | F4: FY28E | G4: FY29E | H4: FY30E | I4: FY31E
A5: Revenue from operations | B5: 48319.6 | C5: 61204.9 | D5: 72783.1 | E5: n/a | F5: n/a | G5: n/a | H5: n/a | I5: n/a
A6: growth (%) | B6: n/a | C6: =C5/B5-1 -> 0.26666818 | D6: =D5/C5-1 -> 0.18917113 | E6: n/a | F6: n/a | G6: n/a | H6: n/a | I6: n/a
A7: Employee benefit expenses | B7: n/a | C7: n/a | D7: n/a | E7: n/a | F7: n/a | G7: n/a | H7: n/a | I7: n/a
A8: Other operating expenses | B8: n/a | C8: n/a | D8: n/a | E8: n/a | F8: n/a | G8: n/a | H8: n/a | I8: n/a
A9: Total operating expenses | B9: n/a | C9: n/a | D9: n/a | E9: n/a | F9: n/a | G9: n/a | H9: n/a | I9: n/a
A10: EBITDA (operating profit before D&A) | B10: n/a | C10: n/a | D10: n/a | E10: n/a | F10: n/a | G10: n/a | H10: n/a | I10: n/a
A11: EBITDA margin (%) | B11: n/a | C11: n/a | D11: n/a | E11: n/a | F11: n/a | G11: n/a | H11: n/a | I11: n/a
A12: Depreciation & amortisation | B12: n/a | C12: n/a | D12: n/a | E12: n/a | F12: n/a | G12: n/a | H12: n/a | I12: n/a
A13: EBIT (operating profit) | B13: n/a | C13: n/a | D13: n/a | E13: n/a | F13: n/a | G13: n/a | H13: n/a | I13: n/a
A14: EBIT margin (%) | B14: n/a | C14: n/a | D14: n/a | E14: n/a | F14: n/a | G14: n/a | H14: n/a | I14: n/a
A15: Other non-operating income | B15: 48306.6 | C15: 61163.6 | D15: 72776 | E15: n/a | F15: n/a | G15: n/a | H15: n/a | I15: n/a
A16: Finance costs | B16: 18724.7 | C16: 24770.8 | D16: 28666 | E16: n/a | F16: n/a | G16: n/a | H16: n/a | I16: n/a
A17: Exceptional items (before tax; charge negative) | B17: n/a | C17: n/a | D17: n/a | E17: n/a | F17: n/a | G17: n/a | H17: n/a | I17: n/a
A18: Profit before tax | B18: 19301.9 | C18: 22061.8 | D18: 25800.2 | E18: n/a | F18: n/a | G18: n/a | H18: n/a | I18: n/a
A19: Tax expense | B19: 4858.4 | C19: 5300.2 | D19: 6484.3 | E19: n/a | F19: n/a | G19: n/a | H19: n/a | I19: n/a
A20: Net income / profit after tax | B20: 14451.2 | C20: 16637.8 | D20: 19017.4 | E20: n/a | F20: n/a | G20: n/a | H20: n/a | I20: n/a
A21: net margin (%) | B21: =B20/B5 -> 0.29907532 | C21: =C20/C5 -> 0.27183771 | D21: =D20/D5 -> 0.26128868 | E21: n/a | F21: n/a | G21: n/a | H21: n/a | I21: n/a
A22: Minority interest | B22: n/a | C22: n/a | D22: n/a | E22: n/a | F22: n/a | G22: n/a | H22: n/a | I22: n/a
A23: Profit attributable to shareholders | B23: n/a | C23: n/a | D23: n/a | E23: n/a | F23: n/a | G23: n/a | H23: n/a | I23: n/a
A24: Diluted shares (crore) | B24: 61.8 | C24: 61.8 | D24: 61.8 | E24: n/a | F24: n/a | G24: n/a | H24: n/a | I24: n/a
A25: Diluted EPS (INR) | B25: n/a | C25: n/a | D25: n/a | E25: n/a | F25: n/a | G25: n/a | H25: n/a | I25: n/a

Sheet Balance Sheet
A1: Balance Sheet (₹ Crores)
A2: Bajaj Finance Limited (BAJFINANCE.NS) . Consolidated . base period FY26
A3: A = reported . E = forecast . "n/a" = the source does not carry the line (never zero)
B4: FY24A | C4: FY25A | D4: FY26A | E4: FY27E | F4: FY28E | G4: FY29E | H4: FY30E | I4: FY31E
A5: CURRENT ASSETS
A6: Cash and cash equivalents | B6: n/a | C6: n/a | D6: n/a | E6: n/a | F6: n/a | G6: n/a | H6: n/a | I6: n/a
A7: Short-term investments | B7: n/a | C7: n/a | D7: n/a | E7: n/a | F7: n/a | G7: n/a | H7: n/a | I7: n/a
A8: Trade receivables | B8: n/a | C8: n/a | D8: n/a | E8: n/a | F8: n/a | G8: n/a | H8: n/a | I8: n/a
A9: Inventories | B9: n/a | C9: n/a | D9: n/a | E9: n/a | F9: n/a | G9: n/a | H9: n/a | I9: n/a
A10: Other current assets | B10: n/a | C10: n/a | D10: n/a | E10: n/a | F10: n/a | G10: n/a | H10: n/a | I10: n/a
A11: Total current assets | B11: n/a | C11: n/a | D11: n/a | E11: n/a | F11: n/a | G11: n/a | H11: n/a | I11: n/a
A12: NON-CURRENT ASSETS
A13: Property, plant & equipment (net) | B13: n/a | C13: n/a | D13: n/a | E13: n/a | F13: n/a | G13: n/a | H13: n/a | I13: n/a
A14: Intangibles & goodwill | B14: n/a | C14: n/a | D14: n/a | E14: n/a | F14: n/a | G14: n/a | H14: n/a | I14: n/a
A15: Non-current investments | B15: n/a | C15: n/a | D15: n/a | E15: n/a | F15: n/a | G15: n/a | H15: n/a | I15: n/a
A16: Other non-current assets | B16: n/a | C16: n/a | D16: n/a | E16: n/a | F16: n/a | G16: n/a | H16: n/a | I16: n/a
A17: Total non-current assets | B17: n/a | C17: n/a | D17: n/a | E17: n/a | F17: n/a | G17: n/a | H17: n/a | I17: n/a
A18: TOTAL ASSETS | B18: 375741.6 | C18: 466126.8 | D18: 559952.4 | E18: n/a | F18: n/a | G18: n/a | H18: n/a | I18: n/a
A19: CURRENT LIABILITIES
A20: Trade payables | B20: n/a | C20: n/a | D20: n/a | E20: n/a | F20: n/a | G20: n/a | H20: n/a | I20: n/a
A21: Short-term borrowings | B21: n/a | C21: n/a | D21: n/a | E21: n/a | F21: n/a | G21: n/a | H21: n/a | I21: n/a
A22: Other current liabilities | B22: n/a | C22: n/a | D22: n/a | E22: n/a | F22: n/a | G22: n/a | H22: n/a | I22: n/a
A23: Total current liabilities | B23: n/a | C23: n/a | D23: n/a | E23: n/a | F23: n/a | G23: n/a | H23: n/a | I23: n/a
A24: NON-CURRENT LIABILITIES
A25: Long-term debt | B25: n/a | C25: n/a | D25: n/a | E25: n/a | F25: n/a | G25: n/a | H25: n/a | I25: n/a
A26: Lease liabilities | B26: n/a | C26: n/a | D26: n/a | E26: n/a | F26: n/a | G26: n/a | H26: n/a | I26: n/a
A27: Deferred tax liabilities | B27: n/a | C27: n/a | D27: n/a | E27: n/a | F27: n/a | G27: n/a | H27: n/a | I27: n/a
A28: Other non-current liabilities | B28: n/a | C28: n/a | D28: n/a | E28: n/a | F28: n/a | G28: n/a | H28: n/a | I28: n/a
A29: Total non-current liabilities | B29: n/a | C29: n/a | D29: n/a | E29: n/a | F29: n/a | G29: n/a | H29: n/a | I29: n/a
A30: TOTAL LIABILITIES | B30: n/a | C30: n/a | D30: n/a | E30: n/a | F30: n/a | G30: n/a | H30: n/a | I30: n/a
A31: EQUITY
A32: Share capital | B32: n/a | C32: n/a | D32: n/a | E32: n/a | F32: n/a | G32: n/a | H32: n/a | I32: n/a
A33: Reserves & surplus | B33: n/a | C33: n/a | D33: n/a | E33: n/a | F33: n/a | G33: n/a | H33: n/a | I33: n/a
A34: Other equity | B34: n/a | C34: n/a | D34: n/a | E34: n/a | F34: n/a | G34: n/a | H34: n/a | I34: n/a
A35: Non-controlling interests | B35: n/a | C35: n/a | D35: n/a | E35: n/a | F35: n/a | G35: n/a | H35: n/a | I35: n/a
A36: TOTAL EQUITY | B36: 76695.4 | C36: 96692.9 | D36: 113999 | E36: n/a | F36: n/a | G36: n/a | H36: n/a | I36: n/a
A37: TOTAL LIABILITIES AND EQUITY | B37: n/a | C37: n/a | D37: n/a | E37: n/a | F37: n/a | G37: n/a | H37: n/a | I37: n/a
A38: Balance check (assets - liabilities - equity) | B38: n/a | C38: n/a | D38: n/a | E38: n/a | F38: n/a | G38: n/a | H38: n/a | I38: n/a

Sheet Cash Flow
A1: Cash Flow (₹ Crores)
A2: Bajaj Finance Limited (BAJFINANCE.NS) . Consolidated . base period FY26
A3: A = reported . E = forecast . "n/a" = the source does not carry the line (never zero)
B4: FY24A | C4: FY25A | D4: FY26A | E4: FY27E | F4: FY28E | G4: FY29E | H4: FY30E | I4: FY31E
A5: OPERATING ACTIVITIES
A6: Net income | B6: 14451.2 | C6: 16637.8 | D6: 19017.4 | E6: n/a | F6: n/a | G6: n/a | H6: n/a | I6: n/a
A7: Depreciation & amortisation | B7: n/a | C7: n/a | D7: n/a | E7: n/a | F7: n/a | G7: n/a | H7: n/a | I7: n/a
A8: Other non-cash adjustments | B8: n/a | C8: n/a | D8: n/a | E8: n/a | F8: n/a | G8: n/a | H8: n/a | I8: n/a
A9: Change in trade receivables | B9: n/a | C9: n/a | D9: n/a | E9: n/a | F9: n/a | G9: n/a | H9: n/a | I9: n/a
A10: Change in inventories | B10: n/a | C10: n/a | D10: n/a | E10: n/a | F10: n/a | G10: n/a | H10: n/a | I10: n/a
A11: Change in trade payables | B11: n/a | C11: n/a | D11: n/a | E11: n/a | F11: n/a | G11: n/a | H11: n/a | I11: n/a
A12: Change in other working capital | B12: n/a | C12: n/a | D12: n/a | E12: n/a | F12: n/a | G12: n/a | H12: n/a | I12: n/a
A13: Cash from operations (CFO) | B13: n/a | C13: n/a | D13: n/a | E13: n/a | F13: n/a | G13: n/a | H13: n/a | I13: n/a
A14: INVESTING ACTIVITIES
A15: Capital expenditure | B15: n/a | C15: n/a | D15: n/a | E15: n/a | F15: n/a | G15: n/a | H15: n/a | I15: n/a
A16: Net purchase / sale of investments | B16: n/a | C16: n/a | D16: n/a | E16: n/a | F16: n/a | G16: n/a | H16: n/a | I16: n/a
A17: Other investing activities | B17: n/a | C17: n/a | D17: n/a | E17: n/a | F17: n/a | G17: n/a | H17: n/a | I17: n/a
A18: Cash from investing (CFI) | B18: n/a | C18: n/a | D18: n/a | E18: n/a | F18: n/a | G18: n/a | H18: n/a | I18: n/a
A19: FINANCING ACTIVITIES
A20: Debt issued / (repaid) | B20: n/a | C20: n/a | D20: n/a | E20: n/a | F20: n/a | G20: n/a | H20: n/a | I20: n/a
A21: Dividends paid | B21: -1814.6 | C21: -2225.2 | D21: -3476.6 | E21: n/a | F21: n/a | G21: n/a | H21: n/a | I21: n/a
A22: Share issuance / (repurchase) | B22: n/a | C22: n/a | D22: n/a | E22: n/a | F22: n/a | G22: n/a | H22: n/a | I22: n/a
A23: Lease payments & other financing | B23: n/a | C23: n/a | D23: n/a | E23: n/a | F23: n/a | G23: n/a | H23: n/a | I23: n/a
A24: Cash from financing (CFF) | B24: n/a | C24: n/a | D24: n/a | E24: n/a | F24: n/a | G24: n/a | H24: n/a | I24: n/a
A25: Net change in cash | B25: n/a | C25: n/a | D25: n/a | E25: n/a | F25: n/a | G25: n/a | H25: n/a | I25: n/a
A26: Opening cash | B26: n/a | C26: n/a | D26: n/a | E26: n/a | F26: n/a | G26: n/a | H26: n/a | I26: n/a
A27: Closing cash | B27: n/a | C27: n/a | D27: n/a | E27: n/a | F27: n/a | G27: n/a | H27: n/a | I27: n/a
A29: FREE CASH FLOW (CFO - CapEx; CapEx a positive outflow; INR crore)
A30: Free cash flow (FCF) | B30: n/a | C30: n/a | D30: n/a | E30: n/a | F30: n/a | G30: n/a | H30: n/a | I30: n/a
A31: FCF margin (FCF / revenue) | B31: n/a | C31: n/a | D31: n/a | E31: n/a | F31: n/a | G31: n/a | H31: n/a | I31: n/a
A32: FCF conversion (FCF / net income) | B32: n/a | C32: n/a | D32: n/a | E32: n/a | F32: n/a | G32: n/a | H32: n/a | I32: n/a
A33: Not applicable as a valuation input for a regulated financial: its operating cash flow includes deposit and loan flows.

Sheet Operating Drivers
A1: Operating Drivers
A2: The economic drivers the forecast is built from: what history shows, what the model assumes, and why. To change a driver, use the Model Builder in the application: it rebuilds the model and re-exports (a rebuilt state is labelled).
A4: Driver | B4: Unit | C4: History (reported / derived) | D4: FY27E (model) | E4: FY28E (model) | F4: FY29E (model) | G4: FY30E (model) | H4: FY31E (model) | I4: Tag | J4: Confidence | K4: Why this value
A5: AUM growth | B5: % per year | C5: policy (no history series) | D5: 23.657826 | E5: 23.657826 | F5: 23.657826 | G5: 23.657826 | H5: 23.657826 | I5: DERIVED | J5: MEDIUM | K5: History-derived value; no override applied.
A6: Lending yield | B6: % of average AUM | C6: policy (no history series) | D6: 16.051388 | E6: 16.051388 | F6: 16.051388 | G6: 16.051388 | H6: 16.051388 | I6: DERIVED | J6: MEDIUM | K6: History-derived value; no override applied.
A7: Borrowing cost | B7: % of average borrowings | C7: policy (no history series) | D7: 7.2530626 | E7: 7.2530626 | F7: 7.2530626 | G7: 7.2530626 | H7: 7.2530626 | I7: DERIVED | J7: MEDIUM | K7: History-derived value; no override applied.
A8: Operating cost | B8: % of average AUM | C8: policy (no history series) | D8: 3.9207197 | E8: 3.9207197 | F8: 3.9207197 | G8: 3.9207197 | H8: 3.9207197 | I8: DERIVED | J8: MEDIUM | K8: History-derived value; no override applied.
A9: Credit cost | B9: bps of average AUM | C9: policy (no history series) | D9: 209.13166 | E9: 209.13166 | F9: 209.13166 | G9: 209.13166 | H9: 209.13166 | I9: DERIVED | J9: MEDIUM | K9: History-derived value; no override applied.
A10: Fee income | B10: % of average AUM | C10: policy (no history series) | D10: 0.0039841456 | E10: 0.0039841456 | F10: 0.0039841456 | G10: 0.0039841456 | H10: 0.0039841456 | I10: DERIVED | J10: MEDIUM | K10: History-derived value; no override applied.
A11: Dividend payout | B11: ratio of profit | C11: policy (no history series) | D11: 0.13374364 | E11: 0.13374364 | F11: 0.13374364 | G11: 0.13374364 | H11: 0.13374364 | I11: DERIVED | J11: MEDIUM | K11: History-derived value; no override applied.
A12: Effective tax rate | B12: % of PBT | C12: policy (no history series) | D12: 25.132751 | E12: 25.132751 | F12: 25.132751 | G12: 25.132751 | H12: 25.132751 | I12: DERIVED | J12: MEDIUM | K12: History-derived value; no override applied.
A15: Revenue driver (provenance of the topline)
A16: Basis | C16: NOT_APPLICABLE: no sector volume x price driver; revenue grows on own reported history
A17: Unit | C17: n/a
A18: Provenance | C18: AUM x spread; AUM growth is the modelled driver

Sheet Valuation
A1: Valuation
A2: One primary method, routed by the company's economics; the rest are cross-checks and are never averaged into it. A withheld valuation states why and publishes no value.
A4: PRIMARY VALUATION
A5: Method | B5: RESIDUAL_INCOME_PB - Multi-Stage Residual Income (100%)
A6: Fair value per share (INR) | B6: 364.92
A7: Current price (INR) | B7: 939.1
A8: Model valuation spread vs price (an unaudited model output, not a rating; not independently audited) | B8: =B6/B7-1 -> -0.61141518
A9: Confidence | B9: HIGH | C9: Confidence of the primary method as stated by the model (HIGH).
A10: Status | B10: VALID
A11: Price basis | B11: NSE official close of 2026-10-30
A14: METHOD RANGES (INR per share) -- cross-checks beside the primary method
A15: Method | B15: Low | C15: Base | D15: High | E15: Weight % | F15: Role
A16: Multi-Stage Residual Income (13.83% Ke, 5.0% g) | B16: 318.32 | C16: 364.92 | D16: 423.95 | E16: 100 | F16: PRIMARY
A17: Fundamental Justified P/B (20.6% stable ROE -> 1.76x P/B) | B17: 290.22 | C17: 323.08 | D17: 364.35 | E17: 0 | F17: cross-check
A18: Dividend Discount Model (13% forecast payout, 76% sustainable terminal payout) | B18: 297.01 | C18: 342.65 | D18: 400.68 | E18: 0 | F18: cross-check
A20: MARKET CROSS-CHECKS
A21: Trading comparables (implied price) | B21: n/a | C21: consolidated trading comps are not the method for this archetype (RESIDUAL_INCOME_PB); segment peers are shown inside the SOTP
A22: Reverse valuation (what the price implies) | B22: AVAILABLE | C22: At 939.10 the market pays +157.3% against the model's 364.92. Cost of equity at which the forecast is worth the market price: 8.9792% (published 13.83%); Multiple of the forecast profit path the market price requires: 2.3455x (published 1x); Terminal growth at which the forecast is worth the market price: 11.9927% (published 5%). This describes market EXPECTATIONS, not fair value.
A24: NOT MEASURED -- stated, bounded where a bound exists, never filled
A25: Item | B25: Direction | C25: Bound (INR/share) | D25: Why
A26: Historical EPS (share basis) | B26: withheld | D26: the statement share count (61.8 Cr) is 10.06x away from the valuation's 622 Cr, so FY24, FY25, FY26 EPS is withheld rather than shown on a basis the per-share fair value does not use. Confirm the dated split / bonus from the exchange record, then restate onto one basis.
A27: DCF cross-check | B27: withheld | D27: Not eligible by methodology: valuation methodology routes this archetype (NBFC) to RESIDUAL_INCOME_PB and prohibits the consolidated FCFF DCF . It is not forced to populate a sheet, and no DCF reading is published.
A28: Segment analysis | B28: withheld | D28: no Ind AS 108 segment disclosure was read for this issuer and the provider published no split
A29: Line-by-line statutory statements | B29: withheld | D29: no audited statutory XBRL filing was served for this issuer; the statements are not laid out line by line

Sheet Peers
A1: Peers
A2: One peer payload, one statistic definition: the median is the headline; quartiles and the sample size sit beside it. Outliers (Tukey fences, 5+ peers) are shown struck from the statistics and listed. Statistics are live formulas over the peer cells.
A4: Whole-company comparable set . 5 peer(s) . analyst-defined NBFC universe, subject excluded
A5: Listed Indian non-bank lenders: borrowed-funds balance sheets valued on book value and return on equity; a bank is not in the set because deposits and regulation differ.
A6: Basis: P/E and P/B for the subject and every peer are the provider's own figures, not recomputed from the model's FY26 EPS and BVPS, so the subject can differ from price / FY26 EPS (provider EPS and book-value dates are not stated by the provider).
A7: Company | B7: Comparability | C7: P/E | D7: P/B | E7: Div. yield % | F7: ROE %
A8: BAJFINANCE.NS (subject) | B8: subject | C8: 30.244103 | D8: 4.7465802 | E8: 0.58 | F8: 15.694234
A9: CHOLAFIN.NS | B9: HIGH (4/4) | C9: 25.896618 | D9: 3.92 (outlier, excluded) | E9: 0.13 | F9: 15.15406
A10: LICHSGFIN.NS | B10: MEDIUM (3/4) | C10: 4.8460029 | D10: 0.61890654 | E10: 2.03 | F10: 12.771485
A11: M&MFIN.NS | B11: MEDIUM (3/4) | C11: 12.716183 | D11: 1.3235711 | E11: 2.87 | F11: 10.408557
A12: MUTHOOTFIN.NS | B12: MEDIUM (3/4) | C12: 9.1164325 | D12: 2.2013841 | E12: 1.25 | F12: 24.15 (outlier, excluded)
A13: SHRIRAMFIN.NS | B13: HIGH (4/4) | C13: 19.323025 | D13: 1.7381792 | E13: 1.31 | F13: 8.9953785
A14: Peer median | C14: =MEDIAN(C9:C13) -> 12.716183 | D14: =MEDIAN(D9:D13) -> 1.5308752 | E14: =MEDIAN(E9:E13) -> 1.31 | F14: =MEDIAN(F9:F13) -> 11.590021
A15: 25th percentile | C15: =QUARTILE(C9:C13,1) -> 9.1164325 | D15: =QUARTILE(D9:D13,1) -> 1.147405 | E15: =QUARTILE(E9:E13,1) -> 1.25 | F15: =QUARTILE(F9:F13,1) -> 10.055262
A16: 75th percentile | C16: =QUARTILE(C9:C13,3) -> 19.323025 | D16: =QUARTILE(D9:D13,3) -> 1.8539804 | E16: =QUARTILE(E9:E13,3) -> 2.03 | F16: =QUARTILE(F9:F13,3) -> 13.367129
A17: Mean | C17: =AVERAGE(C9:C13) -> 14.379652 | D17: =AVERAGE(D9:D13) -> 1.4705103 | E17: =AVERAGE(E9:E13) -> 1.518 | F17: =AVERAGE(F9:F13) -> 11.83237
A18: Peers used (n) | C18: =COUNT(C9:C13) -> 5 | D18: =COUNT(D9:D13) -> 4 | E18: =COUNT(E9:E13) -> 5 | F18: =COUNT(F9:F13) -> 4
A19: Sample state | C19: VALID | D19: LOW SAMPLE | E19: VALID | F19: LOW SAMPLE
A20: Subject vs median (%) | C20: =C8/C14-1 -> 1.3783947 | D20: =D8/D14-1 -> 2.1005664 | E20: =E8/E14-1 -> -0.55725191 | F20: =F8/F14-1 -> 0.35411606
A21: Not applicable here: EV/EBITDA, EV/EBIT, EV/Sales, FCF yield, FCFE yield, ROIC, EBITDA margin, FCF margin, CFO / EBITDA, Cash conversion (FCF / PAT), EBITDA growth (latest FY), FCF growth (latest FY), FCF CAGR (3y), Net debt / EBITDA, Debt / equity, Interest coverage (regulated financial: EV/EBITDA is not defined for it).
A22: Measured vs median: P/E +17.5x . P/B +3.2x . Dividend yield -0.7pp . ROE +4.1pp . ROA +1.2pp . Revenue growth (latest FY) +7.5pp . EPS growth (latest FY) +1.2pp
A24: mean / median / p25 / p75 use linear-interpolation quantiles (spreadsheet QUARTILE.INC / MEDIAN); non-finite values are dropped, never zeroed; a duplicated peer counts once. Tukey fences (Q1 - 1.5 x IQR, Q3 + 1.5 x IQR) applied only with 5 or more values; outliers are excluded from the statistics and listed.
A25: FCF = CFO - CapEx (latest annual fiscal year, INR crore, CapEx a positive outflow); FCF margin = FCF / revenue; FCF conversion = FCF / net profit; FCF yield = FCF / market cap; FCFE = FCF + net borrowing (needs both borrowing balances); FCF CAGR over 3 fiscal years needs both endpoints > 0. Regulated financials carry no corporate FCF.

Sheet Scenarios & Assumptions
A1: Scenarios & Assumptions
A2: What would change the answer: scenarios, the discount-rate / growth grid, what the price implies, and the assumptions and limits behind it.
A4: ASSUMPTIONS APPLIED
A5: Base case: no user override. Every driver is the history-derived recommendation or a disclosed model policy.
A6: WACC (%) | B6: 13.83
A7: Risk-free rate (%) | B7: 6.95
A8: Beta | B8: 1.25
A9: Equity risk premium (%) | B9: 5.5
A10: Cost of equity (%) | B10: 13.83
A11: After-tax cost of debt (%) | B11: n/a
A12: Terminal growth (%) | B12: 5
A13: Discount rate used by the primary method. Risk-free source: Reserve Bank of India 10-Yr G-Sec Benchmark Yield (7.10 GS 2034) (dated reference snapshot as of 2026-08-28) (REFERENCE_SNAPSHOT).
A15: MANAGEMENT GUIDANCE
A16: No verified guidance: FMB's guidance registry holds no sourced item for this company. Nothing is assumed or filled in.
A18: LIMITS AND SOURCE NOTES
A19: Statements: Consolidated annual figures; INR crore; fiscal year ending March. Period-length differences are normalised once and disclosed.
A20: Price: NSE official close of 2026-10-30.
A21: Peer statistics are computed from the same provider extractor for the subject and every peer; see the Peers sheet for the statistic definition.
A22: Withheld: Historical EPS (share basis) -- the statement share count (61.8 Cr) is 10.06x away from the valuation's 622 Cr, so FY24, FY25, FY26 EPS is withheld rather than shown on a basis the per-share fair value does not use. Confirm the dated split / bonus from the exchange record, then restate onto one basis.
A23: Withheld: DCF cross-check -- Not eligible by methodology: valuation methodology routes this archetype (NBFC) to RESIDUAL_INCOME_PB and prohibits the consolidated FCFF DCF . It is not forced to populate a sheet, and no DCF reading is published.
A24: Withheld: Segment analysis -- no Ind AS 108 segment disclosure was read for this issuer and the provider published no split
A25: Withheld: Line-by-line statutory statements -- no audited statutory XBRL filing was served for this issuer; the statements are not laid out line by line
A27: DATA LEGEND
A28: REPORTED | B28: Read from an audited filing or a statutory disclosure, unchanged.
A29: DERIVED | B29: Computed from reported figures by a stated formula. Not itself reported.
A30: FORECAST | B30: The model's projection for a future period. No reported figure exists.
A31: USER INPUT | B31: An analyst override of the model’s assumption for this run.
A32: STALE | B32: A real observation that is no longer current. Not the same as unavailable.
A33: UNAVAILABLE | B33: The evidence does not exist, or could not be obtained. Nothing is substituted.
A34: N/A | B34: The concept does not apply to this issuer or archetype. There is no number to miss.

Sheet Quarterly
A1: Quarterly statements (INR crore, as filed)
A2: Read from each quarter's own filed XBRL (the three-month column; the year-to-date column is never used as a quarter). Unaudited except the March quarter.
A4: UNAVAILABLE: NSE quarterly listing unreachable: RIGHTS_BLOCKED: NSE session-cookie API is paused by the owner pending legal review (nseSessionCookie); set ASTRA_ALLOW_NSE_SESSION_API=1 only after that review. No quarterly figure is estimated or interpolated.

Sheet Common Size
A1: Common-size statements, ratios, DuPont and forensic screens
A2: Common-size lines are live formulas over the statement sheets (line / revenue, line / total assets). Ratios, DuPont and the scores are the engine's published figures.
A4: INCOME STATEMENT AS % OF REVENUE (reported and forecast)
A5: % of revenue | B5: FY24A | C5: FY25A | D5: FY26A | E5: FY27E | F5: FY28E | G5: FY29E | H5: FY30E | I5: FY31E
A6: Revenue | B6: ='Income Statement'!B5/'Income Statement'!B5 -> 1 | C6: ='Income Statement'!C5/'Income Statement'!C5 -> 1 | D6: ='Income Statement'!D5/'Income Statement'!D5 -> 1 | E6: n/a | F6: n/a | G6: n/a | H6: n/a | I6: n/a
A7: Employee benefit expenses | B7: n/a | C7: n/a | D7: n/a | E7: n/a | F7: n/a | G7: n/a | H7: n/a | I7: n/a
A8: Other operating expenses | B8: n/a | C8: n/a | D8: n/a | E8: n/a | F8: n/a | G8: n/a | H8: n/a | I8: n/a
A9: Total operating expenses | B9: n/a | C9: n/a | D9: n/a | E9: n/a | F9: n/a | G9: n/a | H9: n/a | I9: n/a
A10: EBITDA | B10: n/a | C10: n/a | D10: n/a | E10: n/a | F10: n/a | G10: n/a | H10: n/a | I10: n/a
A11: Depreciation & amortisation | B11: n/a | C11: n/a | D11: n/a | E11: n/a | F11: n/a | G11: n/a | H11: n/a | I11: n/a
A12: EBIT | B12: n/a | C12: n/a | D12: n/a | E12: n/a | F12: n/a | G12: n/a | H12: n/a | I12: n/a
A13: Other income | B13: ='Income Statement'!B15/'Income Statement'!B5 -> 0.99973096 | C13: ='Income Statement'!C15/'Income Statement'!C5 -> 0.99932522 | D13: ='Income Statement'!D15/'Income Statement'!D5 -> 0.99990245 | E13: n/a | F13: n/a | G13: n/a | H13: n/a | I13: n/a
A14: Finance costs | B14: ='Income Statement'!B16/'Income Statement'!B5 -> 0.38751769 | C14: ='Income Statement'!C16/'Income Statement'!C5 -> 0.40471923 | D14: ='Income Statement'!D16/'Income Statement'!D5 -> 0.39385517 | E14: n/a | F14: n/a | G14: n/a | H14: n/a | I14: n/a
A15: Profit before tax | B15: ='Income Statement'!B18/'Income Statement'!B5 -> 0.39946316 | C15: ='Income Statement'!C18/'Income Statement'!C5 -> 0.36045807 | D15: ='Income Statement'!D18/'Income Statement'!D5 -> 0.35448064 | E15: n/a | F15: n/a | G15: n/a | H15: n/a | I15: n/a
A16: Tax | B16: ='Income Statement'!B19/'Income Statement'!B5 -> 0.10054719 | C16: ='Income Statement'!C19/'Income Statement'!C5 -> 0.086597642 | D16: ='Income Statement'!D19/'Income Statement'!D5 -> 0.089090737 | E16: n/a | F16: n/a | G16: n/a | H16: n/a | I16: n/a
A17: Net income | B17: ='Income Statement'!B20/'Income Statement'!B5 -> 0.29907532 | C17: ='Income Statement'!C20/'Income Statement'!C5 -> 0.27183771 | D17: ='Income Statement'!D20/'Income Statement'!D5 -> 0.26128868 | E17: n/a | F17: n/a | G17: n/a | H17: n/a | I17: n/a
A19: BALANCE SHEET AS % OF TOTAL ASSETS
A20: % of total assets | B20: FY24A | C20: FY25A | D20: FY26A | E20: FY27E | F20: FY28E | G20: FY29E | H20: FY30E | I20: FY31E
A21: Cash | B21: n/a | C21: n/a | D21: n/a | E21: n/a | F21: n/a | G21: n/a | H21: n/a | I21: n/a
A22: Trade receivables | B22: n/a | C22: n/a | D22: n/a | E22: n/a | F22: n/a | G22: n/a | H22: n/a | I22: n/a
A23: Inventories | B23: n/a | C23: n/a | D23: n/a | E23: n/a | F23: n/a | G23: n/a | H23: n/a | I23: n/a
A24: Current assets | B24: n/a | C24: n/a | D24: n/a | E24: n/a | F24: n/a | G24: n/a | H24: n/a | I24: n/a
A25: PPE (net) | B25: n/a | C25: n/a | D25: n/a | E25: n/a | F25: n/a | G25: n/a | H25: n/a | I25: n/a
A26: Intangibles & goodwill | B26: n/a | C26: n/a | D26: n/a | E26: n/a | F26: n/a | G26: n/a | H26: n/a | I26: n/a
A27: Non-current investments | B27: n/a | C27: n/a | D27: n/a | E27: n/a | F27: n/a | G27: n/a | H27: n/a | I27: n/a
A28: Total assets | B28: ='Balance Sheet'!B18/'Balance Sheet'!B18 -> 1 | C28: ='Balance Sheet'!C18/'Balance Sheet'!C18 -> 1 | D28: ='Balance Sheet'!D18/'Balance Sheet'!D18 -> 1 | E28: n/a | F28: n/a | G28: n/a | H28: n/a | I28: n/a
A29: Trade payables | B29: n/a | C29: n/a | D29: n/a | E29: n/a | F29: n/a | G29: n/a | H29: n/a | I29: n/a
A30: Short-term borrowings | B30: n/a | C30: n/a | D30: n/a | E30: n/a | F30: n/a | G30: n/a | H30: n/a | I30: n/a
A31: Long-term debt | B31: n/a | C31: n/a | D31: n/a | E31: n/a | F31: n/a | G31: n/a | H31: n/a | I31: n/a
A32: Total liabilities | B32: n/a | C32: n/a | D32: n/a | E32: n/a | F32: n/a | G32: n/a | H32: n/a | I32: n/a
A33: Total equity | B33: ='Balance Sheet'!B36/'Balance Sheet'!B18 -> 0.2041174 | C33: ='Balance Sheet'!C36/'Balance Sheet'!C18 -> 0.20743905 | D33: ='Balance Sheet'!D36/'Balance Sheet'!D18 -> 0.20358695 | E33: n/a | F33: n/a | G33: n/a | H33: n/a | I33: n/a
A35: RETURNS AND DUPONT (reported years; engine ratios)
B36: FY24A | C36: FY25A | D36: FY26A | E36: FY27EA | F36: FY28EA | G36: FY29EA | H36: FY30EA | I36: FY31EA
A37: Return on equity | B37: n/a | C37: n/a | D37: n/a | E37: n/a | F37: n/a | G37: n/a | H37: n/a | I37: n/a
A38: Return on assets | B38: n/a | C38: n/a | D38: n/a | E38: n/a | F38: n/a | G38: n/a | H38: n/a | I38: n/a
A39: Return on capital employed | B39: n/a | C39: n/a | D39: n/a | E39: n/a | F39: n/a | G39: n/a | H39: n/a | I39: n/a
A40: Return on invested capital | B40: n/a | C40: n/a | D40: n/a | E40: n/a | F40: n/a | G40: n/a | H40: n/a | I40: n/a
A41: DuPont: net margin | B41: n/a | C41: n/a | D41: n/a | E41: n/a | F41: n/a | G41: n/a | H41: n/a | I41: n/a
A42: DuPont: asset turnover (x) | B42: n/a | C42: n/a | D42: n/a | E42: n/a | F42: n/a | G42: n/a | H42: n/a | I42: n/a
A43: DuPont: equity multiplier (x) | B43: n/a | C43: n/a | D43: n/a | E43: n/a | F43: n/a | G43: n/a | H43: n/a | I43: n/a
...

Sheet Schedules
A1: Schedules: fixed assets, working capital, capital allocation, leverage, segments
A2: Live formulas over the statement sheets (reported and forecast on one axis). A year whose source lines are absent shows n/a.
A4: FIXED ASSETS, CAPEX AND DEPRECIATION (INR crore)
B5: FY24A | C5: FY25A | D5: FY26A | E5: FY27E | F5: FY28E | G5: FY29E | H5: FY30E | I5: FY31E
A6: Property, plant & equipment (net) | B6: n/a | C6: n/a | D6: n/a | E6: n/a | F6: n/a | G6: n/a | H6: n/a | I6: n/a
A7: Capital expenditure (outflow shown positive) | B7: n/a | C7: n/a | D7: n/a | E7: n/a | F7: n/a | G7: n/a | H7: n/a | I7: n/a
A8: Depreciation & amortisation | B8: n/a | C8: n/a | D8: n/a | E8: n/a | F8: n/a | G8: n/a | H8: n/a | I8: n/a
A9: Capex / revenue | B9: n/a | C9: n/a | D9: n/a | E9: n/a | F9: n/a | G9: n/a | H9: n/a | I9: n/a
A10: Capex / depreciation (x) | B10: n/a | C10: n/a | D10: n/a | E10: n/a | F10: n/a | G10: n/a | H10: n/a | I10: n/a
A11: Depreciation / opening net PPE | B11: n/a | C11: n/a | D11: n/a | E11: n/a | F11: n/a | G11: n/a | H11: n/a | I11: n/a
A13: WORKING CAPITAL (INR crore; days on a 365-day year)
B14: FY24A | C14: FY25A | D14: FY26A | E14: FY27E | F14: FY28E | G14: FY29E | H14: FY30E | I14: FY31E
A15: Trade receivables | B15: n/a | C15: n/a | D15: n/a | E15: n/a | F15: n/a | G15: n/a | H15: n/a | I15: n/a
A16: Inventories | B16: n/a | C16: n/a | D16: n/a | E16: n/a | F16: n/a | G16: n/a | H16: n/a | I16: n/a
A17: Trade payables | B17: n/a | C17: n/a | D17: n/a | E17: n/a | F17: n/a | G17: n/a | H17: n/a | I17: n/a
A18: Trade working capital (receivables + inventories - payables) | B18: n/a | C18: n/a | D18: n/a | E18: n/a | F18: n/a | G18: n/a | H18: n/a | I18: n/a
A19: Receivable days (on revenue) | B19: n/a | C19: n/a | D19: n/a | E19: n/a | F19: n/a | G19: n/a | H19: n/a | I19: n/a
A20: Payable days (on total operating expenses) | B20: n/a | C20: n/a | D20: n/a | E20: n/a | F20: n/a | G20: n/a | H20: n/a | I20: n/a
A21: Inventory days (on total operating expenses) | B21: n/a | C21: n/a | D21: n/a | E21: n/a | F21: n/a | G21: n/a | H21: n/a | I21: n/a
A22: Inventory and payable days use total operating expenses as the cost base because the statements do not all carry cost of goods sold; they are comparable across years of this issuer, not to a peer using cost of sales.
A24: CAPITAL ALLOCATION AND LEVERAGE (INR crore)
B25: FY24A | C25: FY25A | D25: FY26A | E25: FY27E | F25: FY28E | G25: FY29E | H25: FY30E | I25: FY31E
A26: Cash from operations | B26: n/a | C26: n/a | D26: n/a | E26: n/a | F26: n/a | G26: n/a | H26: n/a | I26: n/a
A27: Free cash flow (CFO - capex) | B27: n/a | C27: n/a | D27: n/a | E27: n/a | F27: n/a | G27: n/a | H27: n/a | I27: n/a
A28: Dividends paid (outflow shown positive) | B28: =ABS('Cash Flow'!B21) -> 1814.6 | C28: =ABS('Cash Flow'!C21) -> 2225.2 | D28: =ABS('Cash Flow'!D21) -> 3476.6 | E28: n/a | F28: n/a | G28: n/a | H28: n/a | I28: n/a
A29: Dividend payout (dividends / net income) | B29: =B28/'Income Statement'!B20 -> 0.12556743 | C29: =C28/'Income Statement'!C20 -> 0.13374364 | D29: =D28/'Income Statement'!D20 -> 0.18281153 | E29: n/a | F29: n/a | G29: n/a | H29: n/a | I29: n/a
A30: Debt issued / (repaid) | B30: n/a | C30: n/a | D30: n/a | E30: n/a | F30: n/a | G30: n/a | H30: n/a | I30: n/a
A31: Share issuance / (repurchase) | B31: n/a | C31: n/a | D31: n/a | E31: n/a | F31: n/a | G31: n/a | H31: n/a | I31: n/a
A32: Gross borrowings (short-term + long-term) | B32: n/a | C32: n/a | D32: n/a | E32: n/a | F32: n/a | G32: n/a | H32: n/a | I32: n/a
A33: Cash and short-term investments | B33: n/a | C33: n/a | D33: n/a | E33: n/a | F33: n/a | G33: n/a | H33: n/a | I33: n/a
A34: Net debt (borrowings - cash and short-term investments; excludes leases and long-term investments) | B34: n/a | C34: n/a | D34: n/a | E34: n/a | F34: n/a | G34: n/a | H34: n/a | I34: n/a
A35: Net debt / EBITDA (x) | B35: n/a | C35: n/a | D35: n/a | E35: n/a | F35: n/a | G35: n/a | H35: n/a | I35: n/a
A37: Operating segments: no Ind AS 108 segment disclosure was read for this issuer and the provider published no split.
A39: LENDER SCHEDULE: filed lines (INR crore) and derived ratios
B40: FY24A | C40: FY25A | D40: FY26A
A41: Interest income | B41: 48306.6 | C41: 61163.6 | D41: 72776
A42: Interest expense | B42: 18724.7 | C42: 24770.8 | D42: 28666
A43: Non-interest income | B43: 13 | C43: 41.3 | D43: 7.1
A44: Operating expenses | B44: 12325.2 | C44: 14926.1 | D44: 17776.3
A45: Provisions and contingencies | B45: 4630.7 | C45: 7966 | D45: 9481.9
...

Sheet Facts
A1: Facts: raw as-filed lines, canonical resolution, source documents
A2: The lines the statements were built from, by XBRL concept and fiscal year (INR crore), the canonical value against every second source with the authority that decided it, and the filings (hash, URL, retrieval time).
A4: As-filed statements: UNAVAILABLE no audited statutory XBRL filing was served for this issuer; the statements are not laid out line by line
A6: CANONICAL VS SECOND SOURCE (canonical provider NSE_LENDER_XBRL_STATUTORY; a primary filing; policy 2026-09-30.1)
A7: Rows 54: 18 agree, 3 conflict, 0 second source unavailable, 33 not comparable. The canonical value is never averaged with a second source.
A8: Field | B8: Fiscal year | C8: Canonical provider | D8: Canonical value | E8: Second provider | F8: Second value | G8: Agreement | H8: Relative difference | I8: Final value / provider
A9: Revenue from operations | B9: FY24 | C9: NSE_LENDER_XBRL_STATUTORY | D9: 48319.6 | E9: YAHOO_INDIA | F9: 34326.32 | G9: CONFLICT | H9: 0.28959842 | I9: 48319.6 (NSE_LENDER_XBRL_STATUTORY)
A10: Depreciation & amortisation | B10: FY24 | C10: NSE_LENDER_XBRL_STATUTORY | D10: n/a | E10: YAHOO_INDIA | F10: 683.32 | G10: NOT_COMPARABLE | H10: n/a | I10: null (null)
A11: Finance costs | B11: FY24 | C11: NSE_LENDER_XBRL_STATUTORY | D11: 18724.7 | E11: YAHOO_INDIA | F11: 18724.69 | G11: AGREE | H11: 5.3405395e-07 | I11: 18724.7 (NSE_LENDER_XBRL_STATUTORY)
A12: Profit before tax | B12: FY24 | C12: NSE_LENDER_XBRL_STATUTORY | D12: 19301.9 | E12: YAHOO_INDIA | F12: 19309.57 | G12: AGREE | H12: 0.00039737021 | I12: 19301.9 (NSE_LENDER_XBRL_STATUTORY)
A13: Tax expense | B13: FY24 | C13: NSE_LENDER_XBRL_STATUTORY | D13: 4858.4 | E13: YAHOO_INDIA | F13: 4858.4 | G13: AGREE | H13: 0 | I13: 4858.4 (NSE_LENDER_XBRL_STATUTORY)
A14: Profit for the period (total, incl. NCI) | B14: FY24 | C14: NSE_LENDER_XBRL_STATUTORY | D14: 14451.2 | E14: YAHOO_INDIA | F14: 14451.17 | G14: AGREE | H14: 2.0759522e-06 | I14: 14451.2 (NSE_LENDER_XBRL_STATUTORY)
A15: Profit attributable to owners | B15: FY24 | C15: NSE_LENDER_XBRL_STATUTORY | D15: n/a | E15: YAHOO_INDIA | F15: 14451.17 | G15: NOT_COMPARABLE | H15: n/a | I15: null (null)
A16: Diluted EPS (as filed, unrestated) | B16: FY24 | C16: NSE_LENDER_XBRL_STATUTORY | D16: n/a | E16: YAHOO_INDIA | F16: 23.598 | G16: NOT_COMPARABLE | H16: n/a | I16: null (null)
A17: Total assets | B17: FY24 | C17: NSE_LENDER_XBRL_STATUTORY | D17: 375741.6 | E17: YAHOO_INDIA | F17: 375741.62 | G17: AGREE | H17: 5.322807e-08 | I17: 375741.6 (NSE_LENDER_XBRL_STATUTORY)
A18: Total equity (incl. NCI) | B18: FY24 | C18: NSE_LENDER_XBRL_STATUTORY | D18: n/a | E18: YAHOO_INDIA | F18: 76695.35 | G18: NOT_COMPARABLE | H18: n/a | I18: null (null)
A19: Equity attributable to owners | B19: FY24 | C19: NSE_LENDER_XBRL_STATUTORY | D19: 76695.4 | E19: YAHOO_INDIA | F19: 76695.35 | G19: AGREE | H19: 6.5192958e-07 | I19: 76695.4 (NSE_LENDER_XBRL_STATUTORY)
A20: Equity share capital (paid-up value) | B20: FY24 | C20: NSE_LENDER_XBRL_STATUTORY | D20: n/a | E20: YAHOO_INDIA | F20: 123.8 | G20: NOT_COMPARABLE | H20: n/a | I20: null (null)
A21: Cash and cash equivalents | B21: FY24 | C21: NSE_LENDER_XBRL_STATUTORY | D21: n/a | E21: YAHOO_INDIA | F21: 7368.37 | G21: NOT_COMPARABLE | H21: n/a | I21: null (null)
A22: Cash flow from operations | B22: FY24 | C22: NSE_LENDER_XBRL_STATUTORY | D22: n/a | E22: YAHOO_INDIA | F22: -69843.31 | G22: NOT_COMPARABLE | H22: n/a | I22: null (null)
A23: Cash flow from investing | B23: FY24 | C23: NSE_LENDER_XBRL_STATUTORY | D23: n/a | E23: YAHOO_INDIA | F23: -10088.01 | G23: NOT_COMPARABLE | H23: n/a | I23: null (null)
A24: Cash flow from financing | B24: FY24 | C24: NSE_LENDER_XBRL_STATUTORY | D24: n/a | E24: YAHOO_INDIA | F24: 82415.08 | G24: NOT_COMPARABLE | H24: n/a | I24: null (null)
A25: Capital expenditure (magnitude) | B25: FY24 | C25: NSE_LENDER_XBRL_STATUTORY | D25: n/a | E25: YAHOO_INDIA | F25: -1037.78 | G25: NOT_COMPARABLE | H25: n/a | I25: null (null)
A26: Share count | B26: FY24 | C26: NSE_LENDER_XBRL_STATUTORY | D26: n/a | E26: YAHOO_INDIA | F26: 618.008 | G26: NOT_COMPARABLE | H26: n/a | I26: null (null)
A27: Revenue from operations | B27: FY25 | C27: NSE_LENDER_XBRL_STATUTORY | D27: 61204.9 | E27: YAHOO_INDIA | F27: 41479.57 | G27: CONFLICT | H27: 0.32228351 | I27: 61204.9 (NSE_LENDER_XBRL_STATUTORY)
A28: Depreciation & amortisation | B28: FY25 | C28: NSE_LENDER_XBRL_STATUTORY | D28: n/a | E28: YAHOO_INDIA | F28: 880.99 | G28: NOT_COMPARABLE | H28: n/a | I28: null (null)
A29: Finance costs | B29: FY25 | C29: NSE_LENDER_XBRL_STATUTORY | D29: 24770.8 | E29: YAHOO_INDIA | F29: 24769.75 | G29: AGREE | H29: 4.2388619e-05 | I29: 24770.8 (NSE_LENDER_XBRL_STATUTORY)
A30: Profit before tax | B30: FY25 | C30: NSE_LENDER_XBRL_STATUTORY | D30: 22061.8 | E30: YAHOO_INDIA | F30: 22079.63 | G30: AGREE | H30: 0.00080818428 | I30: 22061.8 (NSE_LENDER_XBRL_STATUTORY)
A31: Tax expense | B31: FY25 | C31: NSE_LENDER_XBRL_STATUTORY | D31: 5300.2 | E31: YAHOO_INDIA | F31: 5300.15 | G31: AGREE | H31: 9.4336063e-06 | I31: 5300.2 (NSE_LENDER_XBRL_STATUTORY)
A32: Profit for the period (total, incl. NCI) | B32: FY25 | C32: NSE_LENDER_XBRL_STATUTORY | D32: 16637.8 | E32: YAHOO_INDIA | F32: 16637.82 | G32: AGREE | H32: 1.202082e-06 | I32: 16637.8 (NSE_LENDER_XBRL_STATUTORY)
A33: Profit attributable to owners | B33: FY25 | C33: NSE_LENDER_XBRL_STATUTORY | D33: n/a | E33: YAHOO_INDIA | F33: 16637.82 | G33: NOT_COMPARABLE | H33: n/a | I33: null (null)
A34: Diluted EPS (as filed, unrestated) | B34: FY25 | C34: NSE_LENDER_XBRL_STATUTORY | D34: n/a | E34: YAHOO_INDIA | F34: 26.82 | G34: NOT_COMPARABLE | H34: n/a | I34: null (null)
A35: Total assets | B35: FY25 | C35: NSE_LENDER_XBRL_STATUTORY | D35: 466126.8 | E35: YAHOO_INDIA | F35: 466126.83 | G35: AGREE | H35: 6.436017e-08 | I35: 466126.8 (NSE_LENDER_XBRL_STATUTORY)
A36: Total equity (incl. NCI) | B36: FY25 | C36: NSE_LENDER_XBRL_STATUTORY | D36: n/a | E36: YAHOO_INDIA | F36: 98936.89 | G36: NOT_COMPARABLE | H36: n/a | I36: null (null)
A37: Equity attributable to owners | B37: FY25 | C37: NSE_LENDER_XBRL_STATUTORY | D37: 96692.9 | E37: YAHOO_INDIA | F37: 96692.87 | G37: AGREE | H37: 3.1026063e-07 | I37: 96692.9 (NSE_LENDER_XBRL_STATUTORY)
A38: Equity share capital (paid-up value) | B38: FY25 | C38: NSE_LENDER_XBRL_STATUTORY | D38: n/a | E38: YAHOO_INDIA | F38: 124.29 | G38: NOT_COMPARABLE | H38: n/a | I38: null (null)
A39: Cash and cash equivalents | B39: FY25 | C39: NSE_LENDER_XBRL_STATUTORY | D39: n/a | E39: YAHOO_INDIA | F39: 6541.48 | G39: NOT_COMPARABLE | H39: n/a | I39: null (null)
A40: Cash flow from operations | B40: FY25 | C40: NSE_LENDER_XBRL_STATUTORY | D40: n/a | E40: YAHOO_INDIA | F40: -67791.64 | G40: NOT_COMPARABLE | H40: n/a | I40: null (null)
A41: Cash flow from investing | B41: FY25 | C41: NSE_LENDER_XBRL_STATUTORY | D41: n/a | E41: YAHOO_INDIA | F41: -2765.02 | G41: NOT_COMPARABLE | H41: n/a | I41: null (null)
A42: Cash flow from financing | B42: FY25 | C42: NSE_LENDER_XBRL_STATUTORY | D42: n/a | E42: YAHOO_INDIA | F42: 70164.61 | G42: NOT_COMPARABLE | H42: n/a | I42: null (null)
...

Sheet Change Log
A1: Change log
A2: What changed, and against what. Vintages are saved snapshots of this issuer (each immutable, each with its hash); a change in fair value between two of them is the engine's, not this sheet's.
A4: SAVED SNAPSHOT VINTAGES OF THIS ISSUER (newest first; this workbook is marked)
A5: Snapshot | B5: Built at | C5: Price (INR) | D5: Price as of | E5: Primary method | F5: Fair value per share (INR) | G5: Change vs this workbook (INR) | H5: Change (%) | I5: Assumptions hash (12)
A6: snap_BAJFINANCE_NS_14a597949db9 <- THIS WORKBOOK | B6: 2026-11-01T15:05:35.584Z | C6: 939.1 | D6: 2026-10-30T00:00:00.000Z | E6: RESIDUAL_INCOME_PB | F6: 364.92 | G6: 0 | H6: 0 | I6: 74234e98afe7
A7: snap_BAJFINANCE_NS_9d96b80a9c43 | B7: 2026-11-01T15:05:35.503Z | C7: 939.1 | D7: 2026-10-30T00:00:00.000Z | E7: RESIDUAL_INCOME_PB | F7: 364.92 | G7: =F7-364.92 -> 0 | H7: =G7/364.92 -> 0 | I7: 74234e98afe7
A9: OVERRIDES APPLIED TO THIS WORKBOOK
A10: None: this is the base case (every driver is history-derived or a disclosed model policy).
A12: RESTATEMENTS, PERIOD BREAKS AND SOURCE CONFLICTS IN THE DATA
A13: Diagnostic WARNING | B13: WARN_LOW_QUALITY_CAPEX_ASSUMPTION | C13: Low quality CapEx assumption for 'BAJFINANCE.NS'. Direct statement CapEx omitted by provider; defaulted to 3.5% fallback intensity.
A14: Diagnostic INFO | B14: INFO_ROIC_INAPPLICABLE | C14: INAPPLICABLE_MODEL: return on invested capital is not defined for 'BAJFINANCE.NS', a regulated lender. Its balance sheet carries no corporate invested capital, and its terminal value is derived from residual income.
A15: Diagnostic WARNING | B15: WARN_HIST_IS_PAT_BRIDGE | C15: HIST_IS_PAT_BRIDGE: FY25: PBT 22,062 - tax 5,300 = 16,762, net income reported 16,638, 124 below it (unexplained: discontinued operations / minority / associates not itemised) | FY26: PBT 25,800 - tax 6,484 = 19,316, net income reported 19,017, 299 below it (unexplained: discontinued operations / minority / associates not itemised)
A16: Diagnostic WARNING | B16: WARN_SHARE_COUNT_MISMATCH | C16: Statement share count 61.8 (FY26) and market share count 622 differ 10.1x. A factor this large is what a combined split and bonus produces (2:1 split x 4:1 bonus = 10x) as well as what a unit error produces; the model does not choose between them without the exchange corporate-action record. Reported EPS (307.72) is on the statement count and was NOT restated, so EPS, P/E, BVPS and P/B on the statement basis are not comparable with the per-share fair value until it is confirmed.
A17: 3 provider conflict(s) between the canonical filing value and a second source are listed on the Facts sheet; the filing value stands.

Sheet Source Audit
A1: Source audit: provenance, accounting and recalculation checks, peer selection, limits
A2: Every figure carries its filing; every identity the model must satisfy is listed with its result; nothing that failed is dropped.
A4: PROVENANCE (6 sourced figures)
A5: Line item | B5: Fiscal year | C5: Value | D5: Unit | E5: Type | F5: Confidence | G5: Source filing | H5: URL | I5: sha256 of the stored filing | J5: Basis note
A6: Revenue (FY24) | B6: FY24 | C6: 48319.6 | D6: Crores | E6: REPORTED | F6: Reported / Audited | G6: NSE Reg-33 audited annual results (Ind-AS NBFC), BAJFINANCE FY24, Consolidated | H6: https://nsearchives.nseindia.com/corporate/xbrl/NBFC_INDAS_104721_1108498_25042024091449.xml | I6: n/a | J6: n/a
A7: Net Income / PAT (FY24) | B7: FY24 | C7: 14451.2 | D7: Crores | E7: REPORTED | F7: Reported / Audited | G7: NSE Reg-33 audited annual results (Ind-AS NBFC), BAJFINANCE FY24, Consolidated | H7: https://nsearchives.nseindia.com/corporate/xbrl/NBFC_INDAS_104721_1108498_25042024091449.xml | I7: n/a | J7: n/a
A8: Revenue (FY25) | B8: FY25 | C8: 61204.9 | D8: Crores | E8: REPORTED | F8: Reported / Audited | G8: NSE Reg-33 audited annual results (Ind-AS NBFC), BAJFINANCE FY25, Consolidated | H8: https://nsearchives.nseindia.com/corporate/xbrl/INTEGRATED_FILING_NBFC_INDAS_1428677_30042025123348_WEB.xml | I8: n/a | J8: n/a
A9: Net Income / PAT (FY25) | B9: FY25 | C9: 16637.8 | D9: Crores | E9: REPORTED | F9: Reported / Audited | G9: NSE Reg-33 audited annual results (Ind-AS NBFC), BAJFINANCE FY25, Consolidated | H9: https://nsearchives.nseindia.com/corporate/xbrl/INTEGRATED_FILING_NBFC_INDAS_1428677_30042025123348_WEB.xml | I9: n/a | J9: n/a
A10: Revenue (FY26) | B10: FY26 | C10: 72783.1 | D10: Crores | E10: REPORTED | F10: Reported / Audited | G10: NSE Reg-33 audited annual results (Ind-AS NBFC), BAJFINANCE FY26, Consolidated | H10: https://nsearchives.nseindia.com/corporate/xbrl/INTEGRATED_FILING_NBFC_INDAS_1661603_29042026104724_WEB.xml | I10: n/a | J10: n/a
A11: Net Income / PAT (FY26) | B11: FY26 | C11: 19017.4 | D11: Crores | E11: REPORTED | F11: Reported / Audited | G11: NSE Reg-33 audited annual results (Ind-AS NBFC), BAJFINANCE FY26, Consolidated | H11: https://nsearchives.nseindia.com/corporate/xbrl/INTEGRATED_FILING_NBFC_INDAS_1661603_29042026104724_WEB.xml | I11: n/a | J11: n/a
A13: ACCOUNTING AND RECALCULATION CHECKS (14 run; 13 pass; 1 not a plain pass, all shown first)
A14: Check | B14: Scope | C14: Status | D14: Computed | E14: Reported | F14: Difference | G14: Detail
A15: The model publishes no balancing line | B15: FORECAST | C15: FAIL | D15: n/a | E15: n/a | F15: 14.68 | G15: the share of assets absorbed by a balancing line is nil in every year -- worst difference INR 14.6800 Cr
A16: Balance sheet balances in every forecast year | B16: FORECAST | C16: PASS | D16: n/a | E16: n/a | F16: 0 | G16: assets - (deposits + borrowings + other liabilities + equity) = 0 from the published lines, with no balancing line
A17: Cash-flow closing liquidity = balance-sheet liquidity | B17: FORECAST | C17: PASS | D17: n/a | E17: n/a | F17: 0 | G17: the cash flow ends on the liquidity and investment line of the balance sheet
A18: Each year's opening liquidity = the prior year's closing | B18: FORECAST | C18: PASS | D18: n/a | E18: n/a | F18: 0 | G18: opening and closing liquidity chain across the forecast
A19: Change in liquidity = operations - dividends + net borrowing | B19: FORECAST | C19: PASS | D19: n/a | E19: n/a | F19: 0 | G19: the cash-flow sections sum to the change in liquidity
A20: Closing liquidity = opening + change in liquidity | B20: FORECAST | C20: PASS | D20: n/a | E20: n/a | F20: 0 | G20: liquidity rolls by the cash flow
A21: Equity rolls forward by profit - dividends | B21: FORECAST | C21: PASS | D21: n/a | E21: n/a | F21: 0 | G21: equity moves only by retained profit (clean surplus)
A22: Pre-provision profit - provisions - tax = profit | B22: FORECAST | C22: PASS | D22: n/a | E22: n/a | F22: 0 | G22: no unexplained reconciling item between pre-provision profit and profit
A23: Net interest income + non-interest income = net revenue | B23: FORECAST | C23: PASS | D23: n/a | E23: n/a | F23: 0 | G23: revenue is built from its two parts
A24: Liquidity as the balance-sheet residual = liquidity from the cash flow | B24: FORECAST | C24: PASS | D24: n/a | E24: n/a | F24: 0 | G24: with every other line fixed, the cash flow lands on exactly the liquidity the balance sheet needs
A25: Borrowings and liquidity are never negative | B25: FORECAST | C25: PASS | D25: n/a | E25: n/a | F25: 0 | G25: a funding shortfall is withheld by the model, not published as negative borrowings or negative liquidity
A26: No DCF reading without a DCF | B26: VALUATION | C26: PASS | D26: n/a | E26: n/a | F26: n/a | G26: no DCF ran and no reading is published
A27: No bonus / split is classified as economic dilution | B27: HISTORICAL | C27: PASS | D27: n/a | E27: n/a | F27: n/a | G27: no share-count events
A28: Canonical v1 accounting invariants | B28: Critical Integrity Checks | C28: PASS | D28: n/a | E28: n/a | F28: n/a | G28: All canonical v1 accounting invariants hold across every projected period.
A30: PEER SELECTION (status AVAILABLE)
A31: Peer set | B31: Scope | C31: Selection rule | D31: Rationale | E31: Members
A32: Whole-company comparable set | B32: COMPANY | C32: analyst-defined NBFC universe, subject excluded | D32: Listed Indian non-bank lenders: borrowed-funds balance sheets valued on book value and return on equity; a bank is not in the set because deposits and regulation differ. | E32: CHOLAFIN.NS, LICHSGFIN.NS, M&MFIN.NS, MUTHOOTFIN.NS, SHRIRAMFIN.NS
A34: PUBLICATION STATE AND LIMITS
A35: Statement perimeter | B35: Consolidated
A36: Analysis status | B36: SUCCESS
A37: Valuation status | B37: VALID
A38: Primary method | B38: RESIDUAL_INCOME_PB
A39: Model package status | B39: FAILED
A40: Confidence | B40: LOW
A41: Peer intelligence | B41: AVAILABLE
A42: Withheld / not measured | B42: Historical EPS (share basis) | C42: the statement share count (61.8 Cr) is 10.06x away from the valuation's 622 Cr, so FY24, FY25, FY26 EPS is withheld rather than shown on a basis the per-share fair value does not use. Confirm the dated split / bonus from the exchange record, then restate onto one basis.
A43: Withheld / not measured | B43: DCF cross-check | C43: Not eligible by methodology: valuation methodology routes this archetype (NBFC) to RESIDUAL_INCOME_PB and prohibits the consolidated FCFF DCF . It is not forced to populate a sheet, and no DCF reading is published.
A44: Withheld / not measured | B44: Segment analysis | C44: no Ind AS 108 segment disclosure was read for this issuer and the provider published no split
...

Sheet Chart Data
A1: Chart data (editable)
A2: The numbers behind the native charts on this sheet. Edit a cell and the chart redraws. Source is stated per block; nothing here is a forecast of its own.
A4: MONTE CARLO charts
A5: Not drawn: no Monte Carlo was published for this issuer. A distribution is not invented where the engine withheld one.
A7: FOOTBALL FIELD: value per share by method (INR); the primary method is never averaged with the cross-checks
A8: Method | B8: Low | C8: Base | D8: High | E8: Weight % | F8: Role
A9: Multi-Stage Residual Income (13.83% Ke, 5.0% g) | B9: 318.32 | C9: 364.92 | D9: 423.95 | E9: 100 | F9: PRIMARY
A10: Fundamental Justified P/B (20.6% stable ROE -> 1.76x P/B) | B10: 290.22 | C10: 323.08 | D10: 364.35 | E10: 0 | F10: cross-check
A11: Dividend Discount Model (13% forecast payout, 76% sustainable terminal payout) | B11: 297.01 | C11: 342.65 | D11: 400.68 | E11: 0 | F11: cross-check
