Workbook
Name CurrentPrice: Valuation!$B$7
Name SnapshotId: Summary!$B$41
Name SnapshotHash: Summary!$B$42
Name Years_Header: 'Income Statement'!$B$4:$J$4
Name Revenue_Series: 'Income Statement'!$B$5:$J$5
Name EBITDA_Series: 'Income Statement'!$B$10:$J$10
Name NetIncome_Series: 'Income Statement'!$B$20:$J$20
Name EPS_Series: 'Income Statement'!$B$25:$J$25
Name CFO_Series: 'Cash Flow'!$B$13:$J$13
Name Capex_Series: 'Cash Flow'!$B$15:$J$15

Sheet Summary
A1: DLF Limited (DLF.NS)
A2: Real Estate Developer . NSE . base period FY26 . ₹ Crores unless stated
A5: VALUATION AND DECISION
A6: Current price (INR) | B6: ='Valuation'!B7 -> 691.55
A7: Fair value per share (INR) | B7: WITHHELD
A8: Model valuation spread vs price (an unaudited model output, not a rating; not independently audited) | B8: n/a
A9: Primary method | B9: Sum of the parts
A10: Confidence | B10: LOW
A11: Why withheld | B11: Valuation routing failed: [REAL_ESTATE_NAV_INPUTS_UNAVAILABLE] DLF.NS: project-level saleable area, realisation, land-bank value, rental NOI, occupancy and attributed discount-rate evidence are not present in the canonical provider spine. Refusing the former carrying-value DCF floor: it used a 4% terminal growth rate, 8.5% debt cost, 1.30 beta and 25.17% tax fallback while labelling the result NAV.
A13: KEY FINANCIALS (₹ Crores)
B14: Source sheet | C14: FY23A | D14: FY24A | E14: FY25A | F14: FY26A | G14: FY27E | H14: FY28E | I14: FY29E | J14: FY30E | K14: FY31E
A15: Revenue from operations | B15: Income Statement | C15: ='Income Statement'!B5 -> 5695 | D15: ='Income Statement'!C5 -> 6427 | E15: ='Income Statement'!D5 -> 7994 | F15: ='Income Statement'!E5 -> 8194 | G15: n/a | H15: n/a | I15: n/a | J15: n/a | K15: n/a
A16: EBITDA | B16: Income Statement | C16: ='Income Statement'!B10 -> 1726 | D16: ='Income Statement'!C10 -> 2124 | E16: ='Income Statement'!D10 -> 2109 | F16: ='Income Statement'!E10 -> 1449 | G16: n/a | H16: n/a | I16: n/a | J16: n/a | K16: n/a
A17: EBITDA margin | B17: Income Statement | C17: ='Income Statement'!B11 -> 0.30307287 | D17: ='Income Statement'!C11 -> 0.33048078 | E17: ='Income Statement'!D11 -> 0.26382287 | F17: ='Income Statement'!E11 -> 0.17683671 | G17: n/a | H17: n/a | I17: n/a | J17: n/a | K17: n/a
A18: Net income | B18: Income Statement | C18: ='Income Statement'!B20 -> 2034 | D18: ='Income Statement'!C20 -> 2724 | E18: ='Income Statement'!D20 -> 4367 | F18: ='Income Statement'!E20 -> 4415 | G18: n/a | H18: n/a | I18: n/a | J18: n/a | K18: n/a
A19: Diluted EPS (INR) | B19: Income Statement | C19: ='Income Statement'!B25 -> 8.22 | D19: ='Income Statement'!C25 -> 11.01 | E19: ='Income Statement'!D25 -> 17.64 | F19: ='Income Statement'!E25 -> 17.84 | G19: n/a | H19: n/a | I19: n/a | J19: n/a | K19: n/a
A20: Free cash flow (CFO - CapEx) | B20: Cash Flow | C20: ='Cash Flow'!B30 -> 2311 | D20: ='Cash Flow'!C30 -> 2423 | E20: ='Cash Flow'!D30 -> 5139 | F20: ='Cash Flow'!E30 -> 6218 | G20: n/a | H20: n/a | I20: n/a | J20: n/a | K20: n/a
A21: Return on equity | B21: engine ratio | C21: 0.053970865 | D21: 0.070644986 | E21: 0.10653688 | F21: 0.10031469 | G21: n/a | H21: n/a | I21: n/a | J21: n/a | K21: n/a
A23: RELATIVE POSITION (subject vs peer median; detail on the Peers sheet)
A24: Metric | B24: Subject | C24: Peer median | D24: Peers (n)
A25: P/E | B25: 38.772367 | C25: ='Peers'!C14 -> 24.767779 | D25: 4
A26: EV/EBITDA | B26: n/a | C26: n/a | D26: 1
A27: P/B | B27: 3.7550179 | C27: ='Peers'!G14 -> 3.1360398 | D27: 5
A28: FCF yield | B28: 3.6324337 | C28: ='Peers'!H14 -> 0.54314834 | D28: 5
A29: ROE | B29: 9.6847786 | C29: ='Peers'!K14 -> 10.132774 | D29: 5
A31: RISKS AND INVALIDATORS
A32: - Withheld: Linked three-statement forecast
A33: - Withheld: DCF cross-check
A34: - Withheld: Reverse DCF
A35: - Withheld: Segment analysis
A37: Every figure on this sheet links to its source sheet; nothing is calculated here. Formulas appear only where they reproduce the engine's own figure.
A38: Research only; not investment advice. A withheld, low-confidence or experimental output says so rather than offering a number.
A40: EXPORT SNAPSHOT (one immutable analysis behind every export of this model)
A41: Snapshot ID | B41: snap_DLF_NS_b844a0b66419
A42: Snapshot SHA-256 | B42: b844a0b66419deb01694e6f298f621dd835c37c5430e8cd35bd6fbb1ef67b0c1
A43: Built at | B43: 2026-11-01T15:04:41.411Z
A44: Analysis status | B44: INVALID
A45: Price | B45: INR 691.55
A46: Price as of | B46: 2026-10-30T00:00:00.000Z
A47: Price stale | B47: false
...

Sheet Income Statement
A1: Income Statement (₹ Crores)
A2: DLF Limited (DLF.NS) . Consolidated . base period FY26
A3: A = reported . E = forecast . "n/a" = the source does not carry the line (never zero)
B4: FY23A | C4: FY24A | D4: FY25A | E4: FY26A | F4: FY27E | G4: FY28E | H4: FY29E | I4: FY30E | J4: FY31E
A5: Revenue from operations | B5: 5695 | C5: 6427 | D5: 7994 | E5: 8194 | F5: n/a | G5: n/a | H5: n/a | I5: n/a | J5: n/a
A6: growth (%) | B6: n/a | C6: =C5/B5-1 -> 0.1285338 | D6: =D5/C5-1 -> 0.24381515 | E6: =E5/D5-1 -> 0.025018764 | F6: n/a | G6: n/a | H6: n/a | I6: n/a | J6: n/a
A7: Employee benefit expenses | B7: n/a | C7: n/a | D7: n/a | E7: n/a | F7: n/a | G7: n/a | H7: n/a | I7: n/a | J7: n/a
A8: Other operating expenses | B8: n/a | C8: n/a | D8: n/a | E8: n/a | F8: n/a | G8: n/a | H8: n/a | I8: n/a | J8: n/a
A9: Total operating expenses | B9: 3969 | C9: 4303 | D9: 5885 | E9: 6745 | F9: n/a | G9: n/a | H9: n/a | I9: n/a | J9: n/a
A10: EBITDA (operating profit before D&A) | B10: =B5-B9 -> 1726 | C10: =C5-C9 -> 2124 | D10: =D5-D9 -> 2109 | E10: =E5-E9 -> 1449 | F10: n/a | G10: n/a | H10: n/a | I10: n/a | J10: n/a
A11: EBITDA margin (%) | B11: =B10/B5 -> 0.30307287 | C11: =C10/C5 -> 0.33048078 | D11: =D10/D5 -> 0.26382287 | E11: =E10/E5 -> 0.17683671 | F11: n/a | G11: n/a | H11: n/a | I11: n/a | J11: n/a
A12: Depreciation & amortisation | B12: 149 | C12: 148 | D12: 151 | E12: 142 | F12: n/a | G12: n/a | H12: n/a | I12: n/a | J12: n/a
A13: EBIT (operating profit) | B13: =B10-B12 -> 1577 | C13: =C10-C12 -> 1976 | D13: =D10-D12 -> 1958 | E13: =E10-E12 -> 1307 | F13: n/a | G13: n/a | H13: n/a | I13: n/a | J13: n/a
A14: EBIT margin (%) | B14: =B13/B5 -> 0.27690957 | C14: =C13/C5 -> 0.30745293 | D14: =D13/D5 -> 0.2449337 | E14: =E13/E5 -> 0.15950696 | F14: n/a | G14: n/a | H14: n/a | I14: n/a | J14: n/a
A15: Other non-operating income | B15: 317 | C15: 531 | D15: 700 | E15: 1825 | F15: n/a | G15: n/a | H15: n/a | I15: n/a | J15: n/a
A16: Finance costs | B16: 392 | C16: 356 | D16: 397 | E16: 199 | F16: n/a | G16: n/a | H16: n/a | I16: n/a | J16: n/a
A17: Exceptional items (before tax; charge negative) | B17: n/a | C17: n/a | D17: n/a | E17: n/a | F17: n/a | G17: n/a | H17: n/a | I17: n/a | J17: n/a
A18: Profit before tax | B18: =B13+B15-B16+SUM(B17) -> 1502 | C18: =C13+C15-C16+SUM(C17) -> 2151 | D18: =D13+D15-D16+SUM(D17) -> 2261 | E18: 2932 | F18: n/a | G18: n/a | H18: n/a | I18: n/a | J18: n/a
A19: Tax expense | B19: 405.5 | C19: 516.2 | D19: -429.6 | E19: 322.5 | F19: n/a | G19: n/a | H19: n/a | I19: n/a | J19: n/a
A20: Net income / profit after tax | B20: 2034 | C20: 2724 | D20: 4367 | E20: 4415 | F20: n/a | G20: n/a | H20: n/a | I20: n/a | J20: n/a
A21: net margin (%) | B21: =B20/B5 -> 0.3571554 | C21: =C20/C5 -> 0.42383694 | D21: =D20/D5 -> 0.54628471 | E21: =E20/E5 -> 0.53880888 | F21: n/a | G21: n/a | H21: n/a | I21: n/a | J21: n/a
A22: Minority interest | B22: n/a | C22: n/a | D22: n/a | E22: n/a | F22: n/a | G22: n/a | H22: n/a | I22: n/a | J22: n/a
A23: Profit attributable to shareholders | B23: n/a | C23: n/a | D23: n/a | E23: n/a | F23: n/a | G23: n/a | H23: n/a | I23: n/a | J23: n/a
A24: Diluted shares (crore) | B24: 247.5 | C24: 247.5 | D24: 247.5 | E24: 247.5 | F24: n/a | G24: n/a | H24: n/a | I24: n/a | J24: n/a
A25: Diluted EPS (INR) | B25: 8.22 | C25: 11.01 | D25: 17.64 | E25: 17.84 | F25: n/a | G25: n/a | H25: n/a | I25: n/a | J25: n/a

Sheet Balance Sheet
A1: Balance Sheet (₹ Crores)
A2: DLF Limited (DLF.NS) . Consolidated . base period FY26
A3: A = reported . E = forecast . "n/a" = the source does not carry the line (never zero)
B4: FY23A | C4: FY24A | D4: FY25A | E4: FY26A | F4: FY27E | G4: FY28E | H4: FY29E | I4: FY30E | J4: FY31E
A5: CURRENT ASSETS
A6: Cash and cash equivalents | B6: 2275 | C6: 4384 | D6: 4338 | E6: 7746 | F6: n/a | G6: n/a | H6: n/a | I6: n/a | J6: n/a
A7: Short-term investments | B7: n/a | C7: n/a | D7: n/a | E7: n/a | F7: n/a | G7: n/a | H7: n/a | I7: n/a | J7: n/a
A8: Trade receivables | B8: 549 | C8: 538 | D8: 802 | E8: 847 | F8: n/a | G8: n/a | H8: n/a | I8: n/a | J8: n/a
A9: Inventories | B9: 19361 | C9: 21154 | D9: 24621 | E9: 24717 | F9: n/a | G9: n/a | H9: n/a | I9: n/a | J9: n/a
A10: Other current assets | B10: n/a | C10: n/a | D10: n/a | E10: n/a | F10: n/a | G10: n/a | H10: n/a | I10: n/a | J10: n/a
A11: Total current assets | B11: n/a | C11: n/a | D11: n/a | E11: n/a | F11: n/a | G11: n/a | H11: n/a | I11: n/a | J11: n/a
A12: NON-CURRENT ASSETS
A13: Property, plant & equipment (net) | B13: 4785 | C13: 3880 | D13: 3502 | E13: 4114 | F13: n/a | G13: n/a | H13: n/a | I13: n/a | J13: n/a
A14: Intangibles & goodwill | B14: n/a | C14: n/a | D14: n/a | E14: n/a | F14: n/a | G14: n/a | H14: n/a | I14: n/a | J14: n/a
A15: Non-current investments | B15: 19481 | C15: 20138 | D15: 21336 | E15: 21692 | F15: n/a | G15: n/a | H15: n/a | I15: n/a | J15: n/a
A16: Other non-current assets | B16: n/a | C16: n/a | D16: n/a | E16: n/a | F16: n/a | G16: n/a | H16: n/a | I16: n/a | J16: n/a
A17: Total non-current assets | B17: n/a | C17: n/a | D17: n/a | E17: n/a | F17: n/a | G17: n/a | H17: n/a | I17: n/a | J17: n/a
A18: TOTAL ASSETS | B18: 52572 | C18: 59069 | D18: 68472 | E18: 73465 | F18: n/a | G18: n/a | H18: n/a | I18: n/a | J18: n/a
A19: CURRENT LIABILITIES
A20: Trade payables | B20: 1644 | C20: 1655 | D20: 2261 | E20: 1720 | F20: n/a | G20: n/a | H20: n/a | I20: n/a | J20: n/a
A21: Short-term borrowings | B21: n/a | C21: n/a | D21: n/a | E21: n/a | F21: n/a | G21: n/a | H21: n/a | I21: n/a | J21: n/a
A22: Other current liabilities | B22: n/a | C22: n/a | D22: n/a | E22: n/a | F22: n/a | G22: n/a | H22: n/a | I22: n/a | J22: n/a
A23: Total current liabilities | B23: n/a | C23: n/a | D23: n/a | E23: n/a | F23: n/a | G23: n/a | H23: n/a | I23: n/a | J23: n/a
A24: NON-CURRENT LIABILITIES
A25: Long-term debt | B25: n/a | C25: n/a | D25: n/a | E25: n/a | F25: n/a | G25: n/a | H25: n/a | I25: n/a | J25: n/a
A26: Lease liabilities | B26: n/a | C26: n/a | D26: n/a | E26: n/a | F26: n/a | G26: n/a | H26: n/a | I26: n/a | J26: n/a
A27: Deferred tax liabilities | B27: n/a | C27: n/a | D27: n/a | E27: n/a | F27: n/a | G27: n/a | H27: n/a | I27: n/a | J27: n/a
A28: Other non-current liabilities | B28: n/a | C28: n/a | D28: n/a | E28: n/a | F28: n/a | G28: n/a | H28: n/a | I28: n/a | J28: n/a
A29: Total non-current liabilities | B29: n/a | C29: n/a | D29: n/a | E29: n/a | F29: n/a | G29: n/a | H29: n/a | I29: n/a | J29: n/a
A30: TOTAL LIABILITIES | B30: n/a | C30: n/a | D30: n/a | E30: n/a | F30: n/a | G30: n/a | H30: n/a | I30: n/a | J30: n/a
A31: EQUITY
A32: Share capital | B32: 495 | C32: 495 | D32: 495 | E32: 495 | F32: n/a | G32: n/a | H32: n/a | I32: n/a | J32: n/a
A33: Reserves & surplus | B33: 37192 | C33: 38936 | D33: 42055 | E33: 44978 | F33: n/a | G33: n/a | H33: n/a | I33: n/a | J33: n/a
A34: Other equity | B34: n/a | C34: n/a | D34: n/a | E34: n/a | F34: n/a | G34: n/a | H34: n/a | I34: n/a | J34: n/a
A35: Non-controlling interests | B35: n/a | C35: n/a | D35: n/a | E35: n/a | F35: n/a | G35: n/a | H35: n/a | I35: n/a | J35: n/a
A36: TOTAL EQUITY | B36: n/a | C36: n/a | D36: n/a | E36: n/a | F36: n/a | G36: n/a | H36: n/a | I36: n/a | J36: n/a
A37: TOTAL LIABILITIES AND EQUITY | B37: n/a | C37: n/a | D37: n/a | E37: n/a | F37: n/a | G37: n/a | H37: n/a | I37: n/a | J37: n/a
A38: Balance check (assets - liabilities - equity) | B38: n/a | C38: n/a | D38: n/a | E38: n/a | F38: n/a | G38: n/a | H38: n/a | I38: n/a | J38: n/a

Sheet Cash Flow
A1: Cash Flow (₹ Crores)
A2: DLF Limited (DLF.NS) . Consolidated . base period FY26
A3: A = reported . E = forecast . "n/a" = the source does not carry the line (never zero)
B4: FY23A | C4: FY24A | D4: FY25A | E4: FY26A | F4: FY27E | G4: FY28E | H4: FY29E | I4: FY30E | J4: FY31E
A5: OPERATING ACTIVITIES
A6: Net income | B6: 2034 | C6: 2724 | D6: 4367 | E6: 4415 | F6: n/a | G6: n/a | H6: n/a | I6: n/a | J6: n/a
A7: Depreciation & amortisation | B7: 149 | C7: 148 | D7: 151 | E7: 142 | F7: n/a | G7: n/a | H7: n/a | I7: n/a | J7: n/a
A8: Other non-cash adjustments | B8: n/a | C8: n/a | D8: n/a | E8: n/a | F8: n/a | G8: n/a | H8: n/a | I8: n/a | J8: n/a
A9: Change in trade receivables | B9: n/a | C9: n/a | D9: n/a | E9: n/a | F9: n/a | G9: n/a | H9: n/a | I9: n/a | J9: n/a
A10: Change in inventories | B10: n/a | C10: n/a | D10: n/a | E10: n/a | F10: n/a | G10: n/a | H10: n/a | I10: n/a | J10: n/a
A11: Change in trade payables | B11: n/a | C11: n/a | D11: n/a | E11: n/a | F11: n/a | G11: n/a | H11: n/a | I11: n/a | J11: n/a
A12: Change in other working capital | B12: n/a | C12: n/a | D12: n/a | E12: n/a | F12: n/a | G12: n/a | H12: n/a | I12: n/a | J12: n/a
A13: Cash from operations (CFO) | B13: 2375 | C13: 2539 | D13: 5235 | E13: 6347 | F13: n/a | G13: n/a | H13: n/a | I13: n/a | J13: n/a
A14: INVESTING ACTIVITIES
A15: Capital expenditure | B15: -64 | C15: -116 | D15: -96 | E15: -129 | F15: n/a | G15: n/a | H15: n/a | I15: n/a | J15: n/a
A16: Net purchase / sale of investments | B16: n/a | C16: n/a | D16: n/a | E16: n/a | F16: n/a | G16: n/a | H16: n/a | I16: n/a | J16: n/a
A17: Other investing activities | B17: n/a | C17: n/a | D17: n/a | E17: n/a | F17: n/a | G17: n/a | H17: n/a | I17: n/a | J17: n/a
A18: Cash from investing (CFI) | B18: -461 | C18: -1529 | D18: -3475 | E18: 721 | F18: n/a | G18: n/a | H18: n/a | I18: n/a | J18: n/a
A19: FINANCING ACTIVITIES
A20: Debt issued / (repaid) | B20: n/a | C20: n/a | D20: n/a | E20: n/a | F20: n/a | G20: n/a | H20: n/a | I20: n/a | J20: n/a
A21: Dividends paid | B21: n/a | C21: n/a | D21: n/a | E21: n/a | F21: n/a | G21: n/a | H21: n/a | I21: n/a | J21: n/a
A22: Share issuance / (repurchase) | B22: n/a | C22: n/a | D22: n/a | E22: n/a | F22: n/a | G22: n/a | H22: n/a | I22: n/a | J22: n/a
A23: Lease payments & other financing | B23: n/a | C23: n/a | D23: n/a | E23: n/a | F23: n/a | G23: n/a | H23: n/a | I23: n/a | J23: n/a
A24: Cash from financing (CFF) | B24: -2013 | C24: 177 | D24: -2403 | E24: -5547 | F24: n/a | G24: n/a | H24: n/a | I24: n/a | J24: n/a
A25: Net change in cash | B25: =SUM(B13,B18,B24) -> -99 | C25: =SUM(C13,C18,C24) -> 1187 | D25: =SUM(D13,D18,D24) -> -643 | E25: =SUM(E13,E18,E24) -> 1521 | F25: n/a | G25: n/a | H25: n/a | I25: n/a | J25: n/a
A26: Opening cash | B26: 2374 | C26: 2275 | D26: 4384 | E26: 4338 | F26: n/a | G26: n/a | H26: n/a | I26: n/a | J26: n/a
A27: Closing cash | B27: =SUM(B26,B25) -> 2275 | C27: 4384 | D27: 4338 | E27: 7746 | F27: n/a | G27: n/a | H27: n/a | I27: n/a | J27: n/a
A29: FREE CASH FLOW (CFO - CapEx; CapEx a positive outflow; INR crore)
A30: Free cash flow (FCF) | B30: =B13-ABS(B15) -> 2311 | C30: =C13-ABS(C15) -> 2423 | D30: =D13-ABS(D15) -> 5139 | E30: =E13-ABS(E15) -> 6218 | F30: n/a | G30: n/a | H30: n/a | I30: n/a | J30: n/a
A31: FCF margin (FCF / revenue) | B31: =B30/'Income Statement'!B5 -> 0.40579456 | C31: =C30/'Income Statement'!C5 -> 0.37700327 | D31: =D30/'Income Statement'!D5 -> 0.64285714 | E31: =E30/'Income Statement'!E5 -> 0.75884794 | F31: n/a | G31: n/a | H31: n/a | I31: n/a | J31: n/a
A32: FCF conversion (FCF / net income) | B32: =B30/'Income Statement'!B20 -> 1.1361849 | C32: =C30/'Income Statement'!C20 -> 0.88950073 | D32: =D30/'Income Statement'!D20 -> 1.1767804 | E32: =E30/'Income Statement'!E20 -> 1.4083805 | F32: n/a | G32: n/a | H32: n/a | I32: n/a | J32: n/a

Sheet Operating Drivers
A1: Operating Drivers
A2: The economic drivers the forecast is built from: what history shows, what the model assumes, and why. To change a driver, use the Model Builder in the application: it rebuilds the model and re-exports (a rebuilt state is labelled).
A4: Driver | B4: FY27E | C4: FY28E | D4: FY29E | E4: FY30E | F4: FY31E
A5: Revenue growth | B5: 0.1285338 | C5: 0.10890035 | D5: 0.089266901 | E5: 0.06963345 | F5: 0.05
A6: Employee cost (% of revenue) | B6: 0 | C6: 0 | D6: 0 | E6: 0 | F6: 0
A7: Other operating expenses (% of revenue) | B7: 0.71655213 | C7: 0.71655213 | D7: 0.71655213 | E7: 0.71655213 | F7: 0.71655213
A8: Effective tax rate | B8: 0.2399814 | C8: 0.2399814 | D8: 0.2399814 | E8: 0.2399814 | F8: 0.2399814
A9: Receivable days | B9: 36 | C9: 36 | D9: 36 | E9: 36 | F9: 36
A10: Inventory days | B10: 0 | C10: 0 | D10: 0 | E10: 0 | F10: 0
A11: Payable days | B11: 25 | C11: 25 | D11: 25 | E11: 25 | F11: 25
A12: Capex (% of revenue) | B12: 0.013876117 | C12: 0.015407088 | D12: 0.016938058 | E12: 0.018469029 | F12: 0.02
A13: Dividend payout ratio | B13: 0.6 | C13: 0.6 | D13: 0.6 | E13: 0.6 | F13: 0.6
A15: This issuer has no linked three-statement driver set; the drivers above are the legacy forecast assumptions as published.
A17: Revenue driver (provenance of the topline)
A18: Basis | C18: NOT_APPLICABLE: no sector volume x price driver; revenue grows on own reported history
A19: Unit | C19: n/a
A20: Provenance | C20: Revenue growth from this company's own reported history. Sector volume x price driver UNAVAILABLE [SECTOR_DRIVER_DATA_UNAVAILABLE] for REAL_ESTATE: Presales Value = Presales Volume (msf) * Realization (INR/sqft) needs sourced Residential Presales Volume and Presales Realization per Sqft. Not held for DLF.NS: presales_volume_msf, presales_realization_per_sqft_inr. Note: presales are bookings; revenue is recognised on a different schedule, so presales x realisation is not revenue. No volume, price or growth is inferred.

Sheet Valuation
A1: Valuation
A2: One primary method, routed by the company's economics; the rest are cross-checks and are never averaged into it. A withheld valuation states why and publishes no value.
A4: PRIMARY VALUATION
A5: Method | B5: Sum of the parts
A6: Fair value per share (INR) | B6: WITHHELD
A7: Current price (INR) | B7: 691.55
A8: Model valuation spread vs price (an unaudited model output, not a rating; not independently audited)
A9: Confidence | B9: LOW | C9: No primary valuation was published.
A10: Status | B10: WITHHELD
A11: Price basis | B11: NSE official close of 2026-10-30
A12: Why withheld | B12: Valuation routing failed: [REAL_ESTATE_NAV_INPUTS_UNAVAILABLE] DLF.NS: project-level saleable area, realisation, land-bank value, rental NOI, occupancy and attributed discount-rate evidence are not present in the canonical provider spine. Refusing the former carrying-value DCF floor: it used a 4% terminal growth rate, 8.5% debt cost, 1.30 beta and 25.17% tax fallback while labelling the result NAV.

Sheet Peers
A1: Peers
A2: One peer payload, one statistic definition: the median is the headline; quartiles and the sample size sit beside it. Outliers (Tukey fences, 5+ peers) are shown struck from the statistics and listed. Statistics are live formulas over the peer cells.
A4: Whole-company comparable set . 5 peer(s) . analyst-defined REAL_ESTATE universe, subject excluded
A5: Listed Indian residential and commercial developers: project-cycle revenue recognition, lumpy cash flow, net-asset-value led.
A6: Basis: P/E and P/B for the subject and every peer are the provider's own figures, not recomputed from the model's FY26 EPS and BVPS, so the subject can differ from price / FY26 EPS (provider EPS and book-value dates are not stated by the provider).
A7: Company | B7: Comparability | C7: P/E | D7: EV/EBITDA | E7: EV/EBIT | F7: EV/Sales | G7: P/B | H7: FCF yield % | I7: Div. yield % | J7: ROIC % | K7: ROE % | L7: EBITDA margin % | M7: FCF margin % | N7: Cash conv. % | O7: Net debt/EBITDA | P7: Interest cover
A8: DLF.NS (subject) | B8: subject | C8: 38.772367 | D8: n/a | E8: n/a | F8: n/a | G8: 3.7550179 | H8: 3.6324337 | I8: 1.16 | J8: n/a | K8: 9.6847786 | L8: 17.683671 | M8: 75.884794 | N8: 140.83805 | O8: n/a | P8: 6.5678392
A9: BRIGADE.NS | B9: MEDIUM (3/4) | C9: 23.722759 | D9: n/a | E9: n/a | F9: n/a | G9: 2.4037736 | H9: -10.907611 | I9: 0.38 | J9: n/a | K9: 10.132774 | L9: 25.15359 | M9: -32.929612 | N9: -258.75862 | O9: n/a | P9: 2.7408313
A10: GODREJPROP.NS | B10: HIGH (4/4) | C10: 25.655622 | D10: n/a | E10: n/a | F10: n/a | G10: 2.4397954 | H10: -5.1003557 | I10: 0.64 | J10: n/a | K10: 9.5097887 | L10: -8.83 (outlier, excluded) | M10: -46.949912 | N10: -130.8528 | O10: n/a | P10: -4.1532847
A11: LODHA.NS | B11: HIGH (4/4) | C11: 30.20752 | D11: n/a | E11: n/a | F11: n/a | G11: 4.0986278 | H11: 0.6840856 | I11: 0.41 | J11: n/a | K11: 13.568237 | L11: 29.521468 | M11: 4.2516191 | N11: 20.664529 | O11: n/a | P11: 6.9468892
A12: OBEROIRLTY.NS | B12: HIGH (4/4) | C12: 23.879936 | D12: n/a | E12: n/a | F12: n/a | G12: 3.1360398 | H12: 1.2410844 | I12: 0.49 | J12: n/a | K12: 13.13253 | L12: 55.9 (outlier, excluded) | M12: 12.364786 | N12: 29.637016 | O12: n/a | P12: 13.394191
A13: PRESTIGE.NS | B13: HIGH (4/4) | C13: 47.97 (outlier, excluded) | D13: 21.087734 | E13: 27.942949 | F13: 6.1392984 | G13: 3.84674 | H13: 0.54314834 | I13: 0.14 (outlier, excluded) | J13: 6.7131085 | K13: 8.0194187 | L13: 29.113126 | M13: 2.6803311 | N13: 26.05364 | O13: 4.1372868 | P13: 1.7616941
A14: Peer median | C14: =MEDIAN(C9:C13) -> 24.767779 | D14: n/a | E14: n/a | F14: n/a | G14: =MEDIAN(G9:G13) -> 3.1360398 | H14: =MEDIAN(H9:H13) -> 0.54314834 | I14: =MEDIAN(I9:I13) -> 0.45 | J14: n/a | K14: =MEDIAN(K9:K13) -> 10.132774 | L14: =MEDIAN(L9:L13) -> 29.113126 | M14: =MEDIAN(M9:M13) -> 2.6803311 | N14: =MEDIAN(N9:N13) -> 20.664529 | O14: n/a | P14: =MEDIAN(P9:P13) -> 2.7408313
A15: 25th percentile | C15: =QUARTILE(C9:C13,1) -> 23.840642 | D15: n/a | E15: n/a | F15: n/a | G15: =QUARTILE(G9:G13,1) -> 2.4397954 | H15: =QUARTILE(H9:H13,1) -> -5.1003557 | I15: =QUARTILE(I9:I13,1) -> 0.4025 | J15: n/a | K15: =QUARTILE(K9:K13,1) -> 9.5097887 | L15: =QUARTILE(L9:L13,1) -> 27.133358 | M15: =QUARTILE(M9:M13,1) -> -32.929612 | N15: =QUARTILE(N9:N13,1) -> -130.8528 | O15: n/a | P15: =QUARTILE(P9:P13,1) -> 1.7616941
A16: 75th percentile | C16: =QUARTILE(C9:C13,3) -> 26.793596 | D16: n/a | E16: n/a | F16: n/a | G16: =QUARTILE(G9:G13,3) -> 3.84674 | H16: =QUARTILE(H9:H13,3) -> 0.6840856 | I16: =QUARTILE(I9:I13,3) -> 0.5275 | J16: n/a | K16: =QUARTILE(K9:K13,3) -> 13.13253 | L16: =QUARTILE(L9:L13,3) -> 29.317297 | M16: =QUARTILE(M9:M13,3) -> 4.2516191 | N16: =QUARTILE(N9:N13,3) -> 26.05364 | O16: n/a | P16: =QUARTILE(P9:P13,3) -> 6.9468892
A17: Mean | C17: =AVERAGE(C9:C13) -> 25.866459 | D17: n/a | E17: n/a | F17: n/a | G17: =AVERAGE(G9:G13) -> 3.1849953 | H17: =AVERAGE(H9:H13) -> -2.7079296 | I17: =AVERAGE(I9:I13) -> 0.48 | J17: n/a | K17: =AVERAGE(K9:K13) -> 10.87255 | L17: =AVERAGE(L9:L13) -> 27.929394 | M17: =AVERAGE(M9:M13) -> -12.116558 | N17: =AVERAGE(N9:N13) -> -62.651247 | O17: n/a | P17: =AVERAGE(P9:P13) -> 4.1380642
A18: Peers used (n) | C18: =COUNT(C9:C13) -> 4 | D18: =COUNT(D9:D13) -> 1 | E18: =COUNT(E9:E13) -> 1 | F18: =COUNT(F9:F13) -> 1 | G18: =COUNT(G9:G13) -> 5 | H18: =COUNT(H9:H13) -> 5 | I18: =COUNT(I9:I13) -> 4 | J18: =COUNT(J9:J13) -> 1 | ... P18: =COUNT(P9:P13) -> 5
A19: Sample state | C19: LOW SAMPLE | D19: INSUFFICIENT PEERS | E19: INSUFFICIENT PEERS | F19: INSUFFICIENT PEERS | G19: VALID | H19: VALID | I19: LOW SAMPLE | J19: INSUFFICIENT PEERS | K19: VALID | L19: LOW SAMPLE | M19: VALID | N19: VALID | O19: INSUFFICIENT PEERS | P19: VALID
A20: Subject vs median (%) | C20: =C8/C14-1 -> 0.56543576 | D20: n/a | E20: n/a | F20: n/a | G20: =G8/G14-1 -> 0.1973757 | H20: =H8/H14-1 -> 5.6877378 | I20: =I8/I14-1 -> 1.5777778 | J20: n/a | K20: =K8/K14-1 -> -0.044212544 | L20: =L8/L14-1 -> -0.39258769 | M20: =M8/M14-1 -> 27.311724 | N20: =N8/N14-1 -> 5.8154493 | O20: n/a | P20: =P8/P14-1 -> 1.3962946
A21: Measured vs median: P/E +14.0x . P/B +0.6x . FCF yield +3.1pp . FCFE yield +1.2pp . Dividend yield +0.7pp . ROE -0.4pp . ROA +3.1pp . EBITDA margin -11.4pp
A23: mean / median / p25 / p75 use linear-interpolation quantiles (spreadsheet QUARTILE.INC / MEDIAN); non-finite values are dropped, never zeroed; a duplicated peer counts once. Tukey fences (Q1 - 1.5 x IQR, Q3 + 1.5 x IQR) applied only with 5 or more values; outliers are excluded from the statistics and listed.
A24: FCF = CFO - CapEx (latest annual fiscal year, INR crore, CapEx a positive outflow); FCF margin = FCF / revenue; FCF conversion = FCF / net profit; FCF yield = FCF / market cap; FCFE = FCF + net borrowing (needs both borrowing balances); FCF CAGR over 3 fiscal years needs both endpoints > 0. Regulated financials carry no corporate FCF.

Sheet Scenarios & Assumptions
A1: Scenarios & Assumptions
A2: What would change the answer: scenarios, the discount-rate / growth grid, what the price implies, and the assumptions and limits behind it.
A4: ASSUMPTIONS APPLIED
A5: Base case: no user override. Every driver is the history-derived recommendation or a disclosed model policy.
A6: WACC (%) | B6: 14.43
A7: Risk-free rate (%) | B7: 6.95
A8: Beta | B8: 1.36
A9: Equity risk premium (%) | B9: 5.5
A10: Cost of equity (%) | B10: 14.43
A11: After-tax cost of debt (%) | B11: 5.99
A12: Terminal growth (%) | B12: n/a
A13: REFERENCE ONLY: the primary method does not discount. Risk-free source: CONFIGURED FALLBACK: a model policy constant, not a verified market observation (CONFIGURED_FALLBACK).
A15: MANAGEMENT GUIDANCE
A16: No verified guidance: FMB's guidance registry holds no sourced item for this company. Nothing is assumed or filled in.
A18: LIMITS AND SOURCE NOTES
A19: Statements: Consolidated annual figures; INR crore; fiscal year ending March. Period-length differences are normalised once and disclosed.
A20: Price: NSE official close of 2026-10-30.
A21: Peer statistics are computed from the same provider extractor for the subject and every peer; see the Peers sheet for the statistic definition.
A22: Withheld: Linked three-statement forecast -- the reported FY26 balance sheet does not balance as opened (assets 73465 vs liabilities + equity 47499 Cr); no forecast is built on it
A23: Withheld: DCF cross-check -- Not eligible by methodology: valuation methodology routes this archetype (REAL_ESTATE) to Sum of the parts and prohibits the consolidated FCFF DCF. It is not forced to populate a sheet, and no DCF reading is published.
A24: Withheld: Reverse DCF -- a reverse DCF inverts a consolidated FCFF DCF, which this archetype's methodology prohibits
A25: Withheld: Segment analysis -- no Ind AS 108 segment disclosure was read for this issuer and the provider published no split
A26: Withheld: Line-by-line statutory statements -- no audited statutory XBRL filing was served for this issuer; the statements are not laid out line by line
... A29: DATA LEGEND
A30: REPORTED | B30: Read from an audited filing or a statutory disclosure, unchanged.
A31: DERIVED | B31: Computed from reported figures by a stated formula. Not itself reported.
A32: FORECAST | B32: The model's projection for a future period. No reported figure exists.
A33: USER INPUT | B33: An analyst override of the model’s assumption for this run.
A34: STALE | B34: A real observation that is no longer current. Not the same as unavailable.
A35: UNAVAILABLE | B35: The evidence does not exist, or could not be obtained. Nothing is substituted.
A36: N/A | B36: The concept does not apply to this issuer or archetype. There is no number to miss.

Sheet Quarterly
A1: Quarterly statements (INR crore, as filed)
A2: Read from each quarter's own filed XBRL (the three-month column; the year-to-date column is never used as a quarter). Unaudited except the March quarter.
A4: UNAVAILABLE: NSE quarterly listing unreachable: RIGHTS_BLOCKED: NSE session-cookie API is paused by the owner pending legal review (nseSessionCookie); set ASTRA_ALLOW_NSE_SESSION_API=1 only after that review. No quarterly figure is estimated or interpolated.

Sheet Common Size
A1: Common-size statements, ratios, DuPont and forensic screens
A2: Common-size lines are live formulas over the statement sheets (line / revenue, line / total assets). Ratios, DuPont and the scores are the engine's published figures.
A4: INCOME STATEMENT AS % OF REVENUE (reported and forecast)
A5: % of revenue | B5: FY23A | C5: FY24A | D5: FY25A | E5: FY26A | F5: FY27E | G5: FY28E | H5: FY29E | I5: FY30E | J5: FY31E
A6: Revenue | B6: ='Income Statement'!B5/'Income Statement'!B5 -> 1 | C6: ='Income Statement'!C5/'Income Statement'!C5 -> 1 | D6: ='Income Statement'!D5/'Income Statement'!D5 -> 1 | E6: ='Income Statement'!E5/'Income Statement'!E5 -> 1 | F6: n/a | G6: n/a | H6: n/a | I6: n/a | J6: n/a
A7: Employee benefit expenses | B7: n/a | C7: n/a | D7: n/a | E7: n/a | F7: n/a | G7: n/a | H7: n/a | I7: n/a | J7: n/a
A8: Other operating expenses | B8: n/a | C8: n/a | D8: n/a | E8: n/a | F8: n/a | G8: n/a | H8: n/a | I8: n/a | J8: n/a
A9: Total operating expenses | B9: ='Income Statement'!B9/'Income Statement'!B5 -> 0.69692713 | C9: ='Income Statement'!C9/'Income Statement'!C5 -> 0.66951922 | D9: ='Income Statement'!D9/'Income Statement'!D5 -> 0.73617713 | E9: ='Income Statement'!E9/'Income Statement'!E5 -> 0.82316329 | F9: n/a | G9: n/a | H9: n/a | I9: n/a | J9: n/a
A10: EBITDA | B10: ='Income Statement'!B10/'Income Statement'!B5 -> 0.30307287 | C10: ='Income Statement'!C10/'Income Statement'!C5 -> 0.33048078 | D10: ='Income Statement'!D10/'Income Statement'!D5 -> 0.26382287 | E10: ='Income Statement'!E10/'Income Statement'!E5 -> 0.17683671 | F10: n/a | G10: n/a | H10: n/a | I10: n/a | J10: n/a
A11: Depreciation & amortisation | B11: ='Income Statement'!B12/'Income Statement'!B5 -> 0.026163301 | C11: ='Income Statement'!C12/'Income Statement'!C5 -> 0.023027851 | D11: ='Income Statement'!D12/'Income Statement'!D5 -> 0.018889167 | E11: ='Income Statement'!E12/'Income Statement'!E5 -> 0.017329753 | F11: n/a | G11: n/a | H11: n/a | I11: n/a | J11: n/a
A12: EBIT | B12: ='Income Statement'!B13/'Income Statement'!B5 -> 0.27690957 | C12: ='Income Statement'!C13/'Income Statement'!C5 -> 0.30745293 | D12: ='Income Statement'!D13/'Income Statement'!D5 -> 0.2449337 | E12: ='Income Statement'!E13/'Income Statement'!E5 -> 0.15950696 | F12: n/a | G12: n/a | H12: n/a | I12: n/a | J12: n/a
A13: Other income | B13: ='Income Statement'!B15/'Income Statement'!B5 -> 0.055662862 | C13: ='Income Statement'!C15/'Income Statement'!C5 -> 0.082620196 | D13: ='Income Statement'!D15/'Income Statement'!D5 -> 0.087565674 | E13: ='Income Statement'!E15/'Income Statement'!E5 -> 0.22272394 | F13: n/a | G13: n/a | H13: n/a | I13: n/a | J13: n/a
A14: Finance costs | B14: ='Income Statement'!B16/'Income Statement'!B5 -> 0.068832309 | C14: ='Income Statement'!C16/'Income Statement'!C5 -> 0.055391318 | D14: ='Income Statement'!D16/'Income Statement'!D5 -> 0.049662247 | E14: ='Income Statement'!E16/'Income Statement'!E5 -> 0.024286063 | F14: n/a | G14: n/a | H14: n/a | I14: n/a | J14: n/a
A15: Profit before tax | B15: ='Income Statement'!B18/'Income Statement'!B5 -> 0.26374012 | C15: ='Income Statement'!C18/'Income Statement'!C5 -> 0.33468181 | D15: ='Income Statement'!D18/'Income Statement'!D5 -> 0.28283713 | E15: ='Income Statement'!E18/'Income Statement'!E5 -> 0.3578228 | F15: n/a | G15: n/a | H15: n/a | I15: n/a | J15: n/a
A16: Tax | B16: ='Income Statement'!B19/'Income Statement'!B5 -> 0.071202809 | C16: ='Income Statement'!C19/'Income Statement'!C5 -> 0.080317411 | D16: ='Income Statement'!D19/'Income Statement'!D5 -> -0.053740305 | E16: ='Income Statement'!E19/'Income Statement'!E5 -> 0.039358067 | F16: n/a | G16: n/a | H16: n/a | I16: n/a | J16: n/a
A17: Net income | B17: ='Income Statement'!B20/'Income Statement'!B5 -> 0.3571554 | C17: ='Income Statement'!C20/'Income Statement'!C5 -> 0.42383694 | D17: ='Income Statement'!D20/'Income Statement'!D5 -> 0.54628471 | E17: ='Income Statement'!E20/'Income Statement'!E5 -> 0.53880888 | F17: n/a | G17: n/a | H17: n/a | I17: n/a | J17: n/a
A19: BALANCE SHEET AS % OF TOTAL ASSETS
A20: % of total assets | B20: FY23A | C20: FY24A | D20: FY25A | E20: FY26A | F20: FY27E | G20: FY28E | H20: FY29E | I20: FY30E | J20: FY31E
A21: Cash | B21: ='Balance Sheet'!B6/'Balance Sheet'!B18 -> 0.043273986 | C21: ='Balance Sheet'!C6/'Balance Sheet'!C18 -> 0.074218287 | D21: ='Balance Sheet'!D6/'Balance Sheet'!D18 -> 0.063354364 | E21: ='Balance Sheet'!E6/'Balance Sheet'!E18 -> 0.10543796 | F21: n/a | G21: n/a | H21: n/a | I21: n/a | J21: n/a
A22: Trade receivables | B22: ='Balance Sheet'!B8/'Balance Sheet'!B18 -> 0.010442821 | C22: ='Balance Sheet'!C8/'Balance Sheet'!C18 -> 0.0091079923 | D22: ='Balance Sheet'!D8/'Balance Sheet'!D18 -> 0.011712817 | E22: ='Balance Sheet'!E8/'Balance Sheet'!E18 -> 0.0115293 | F22: n/a | G22: n/a | H22: n/a | I22: n/a | J22: n/a
A23: Inventories | B23: ='Balance Sheet'!B9/'Balance Sheet'!B18 -> 0.36827589 | C23: ='Balance Sheet'!C9/'Balance Sheet'!C18 -> 0.35812355 | D23: ='Balance Sheet'!D9/'Balance Sheet'!D18 -> 0.35957764 | E23: ='Balance Sheet'!E9/'Balance Sheet'!E18 -> 0.33644593 | F23: n/a | G23: n/a | H23: n/a | I23: n/a | J23: n/a
A24: Current assets | B24: n/a | C24: n/a | D24: n/a | E24: n/a | F24: n/a | G24: n/a | H24: n/a | I24: n/a | J24: n/a
A25: PPE (net) | B25: ='Balance Sheet'!B13/'Balance Sheet'!B18 -> 0.091018032 | C25: ='Balance Sheet'!C13/'Balance Sheet'!C18 -> 0.065685893 | D25: ='Balance Sheet'!D13/'Balance Sheet'!D18 -> 0.051144994 | E25: ='Balance Sheet'!E13/'Balance Sheet'!E18 -> 0.055999456 | F25: n/a | G25: n/a | H25: n/a | I25: n/a | J25: n/a
A26: Intangibles & goodwill | B26: n/a | C26: n/a | D26: n/a | E26: n/a | F26: n/a | G26: n/a | H26: n/a | I26: n/a | J26: n/a
A27: Non-current investments | B27: ='Balance Sheet'!B15/'Balance Sheet'!B18 -> 0.37055847 | C27: ='Balance Sheet'!C15/'Balance Sheet'!C18 -> 0.34092333 | D27: ='Balance Sheet'!D15/'Balance Sheet'!D18 -> 0.31160182 | E27: ='Balance Sheet'!E15/'Balance Sheet'!E18 -> 0.29526986 | F27: n/a | G27: n/a | H27: n/a | I27: n/a | J27: n/a
A28: Total assets | B28: ='Balance Sheet'!B18/'Balance Sheet'!B18 -> 1 | C28: ='Balance Sheet'!C18/'Balance Sheet'!C18 -> 1 | D28: ='Balance Sheet'!D18/'Balance Sheet'!D18 -> 1 | E28: ='Balance Sheet'!E18/'Balance Sheet'!E18 -> 1 | F28: n/a | G28: n/a | H28: n/a | I28: n/a | J28: n/a
A29: Trade payables | B29: ='Balance Sheet'!B20/'Balance Sheet'!B18 -> 0.031271399 | C29: ='Balance Sheet'!C20/'Balance Sheet'!C18 -> 0.028018081 | D29: ='Balance Sheet'!D20/'Balance Sheet'!D18 -> 0.033020797 | E29: ='Balance Sheet'!E20/'Balance Sheet'!E18 -> 0.023412509 | F29: n/a | G29: n/a | H29: n/a | I29: n/a | J29: n/a
A30: Short-term borrowings | B30: n/a | C30: n/a | D30: n/a | E30: n/a | F30: n/a | G30: n/a | H30: n/a | I30: n/a | J30: n/a
A31: Long-term debt | B31: n/a | C31: n/a | D31: n/a | E31: n/a | F31: n/a | G31: n/a | H31: n/a | I31: n/a | J31: n/a
A32: Total liabilities | B32: n/a | C32: n/a | D32: n/a | E32: n/a | F32: n/a | G32: n/a | H32: n/a | I32: n/a | J32: n/a
A33: Total equity | B33: n/a | C33: n/a | D33: n/a | E33: n/a | F33: n/a | G33: n/a | H33: n/a | I33: n/a | J33: n/a
A35: RETURNS AND DUPONT (reported years; engine ratios)
B36: FY23A | C36: FY24A | D36: FY25A | E36: FY26A | F36: FY27EA | G36: FY28EA | H36: FY29EA | I36: FY30EA | J36: FY31EA
A37: Return on equity | B37: 0.053970865 | C37: 0.070644986 | D37: 0.10653688 | E37: 0.10031469 | F37: n/a | G37: n/a | H37: n/a | I37: n/a | J37: n/a
A38: Return on assets | B38: 0.038689797 | C38: 0.048799276 | D38: 0.06847994 | E38: 0.062210699 | F38: n/a | G38: n/a | H38: n/a | I38: n/a | J38: n/a
A39: Return on capital employed | B39: n/a | C39: n/a | D39: n/a | E39: n/a | F39: n/a | G39: n/a | H39: n/a | I39: n/a | J39: n/a
A40: Return on invested capital | B40: n/a | C40: n/a | D40: n/a | E40: n/a | F40: n/a | G40: n/a | H40: n/a | I40: n/a | J40: n/a
A41: DuPont: net margin | B41: 0.3571554 | C41: 0.42383694 | D41: 0.54628471 | E41: 0.53880888 | F41: n/a | G41: n/a | H41: n/a | I41: n/a | J41: n/a
A42: DuPont: asset turnover (x) | B42: 0.10832763 | C42: 0.11513691 | D42: 0.12535577 | E42: 0.11545968 | F42: n/a | G42: n/a | H42: n/a | I42: n/a | J42: n/a
A43: DuPont: equity multiplier (x) | B43: 1.3949638 | C43: 1.4476646 | D43: 1.5557385 | E43: 1.612499 | F43: n/a | G43: n/a | H43: n/a | I43: n/a | J43: n/a
...

Sheet Schedules
A1: Schedules: fixed assets, working capital, capital allocation, leverage, segments
A2: Live formulas over the statement sheets (reported and forecast on one axis). A year whose source lines are absent shows n/a.
A4: FIXED ASSETS, CAPEX AND DEPRECIATION (INR crore)
B5: FY23A | C5: FY24A | D5: FY25A | E5: FY26A | F5: FY27E | G5: FY28E | H5: FY29E | I5: FY30E | J5: FY31E
A6: Property, plant & equipment (net) | B6: ='Balance Sheet'!B13 -> 4785 | C6: ='Balance Sheet'!C13 -> 3880 | D6: ='Balance Sheet'!D13 -> 3502 | E6: ='Balance Sheet'!E13 -> 4114 | F6: n/a | G6: n/a | H6: n/a | I6: n/a | J6: n/a
A7: Capital expenditure (outflow shown positive) | B7: =ABS('Cash Flow'!B15) -> 64 | C7: =ABS('Cash Flow'!C15) -> 116 | D7: =ABS('Cash Flow'!D15) -> 96 | E7: =ABS('Cash Flow'!E15) -> 129 | F7: n/a | G7: n/a | H7: n/a | I7: n/a | J7: n/a
A8: Depreciation & amortisation | B8: ='Income Statement'!B12 -> 149 | C8: ='Income Statement'!C12 -> 148 | D8: ='Income Statement'!D12 -> 151 | E8: ='Income Statement'!E12 -> 142 | F8: n/a | G8: n/a | H8: n/a | I8: n/a | J8: n/a
A9: Capex / revenue | B9: =B7/'Income Statement'!B5 -> 0.011237928 | C9: =C7/'Income Statement'!C5 -> 0.018048856 | D9: =D7/'Income Statement'!D5 -> 0.012009007 | E9: =E7/'Income Statement'!E5 -> 0.015743227 | F9: n/a | G9: n/a | H9: n/a | I9: n/a | J9: n/a
A10: Capex / depreciation (x) | B10: =B7/B8 -> 0.4295302 | C10: =C7/C8 -> 0.78378378 | D10: =D7/D8 -> 0.63576159 | E10: =E7/E8 -> 0.9084507 | F10: n/a | G10: n/a | H10: n/a | I10: n/a | J10: n/a
A11: Depreciation / opening net PPE | B11: n/a | C11: =C8/B6 -> 0.03092999 | D11: =D8/C6 -> 0.038917526 | E11: =E8/D6 -> 0.040548258 | F11: n/a | G11: n/a | H11: n/a | I11: n/a | J11: n/a
A12: Maintenance capex (CAPEX_BELOW_DEPRECIATION) | B12: 64 | C12: 116 | D12: 96 | E12: 129 | F12: n/a | G12: n/a | H12: n/a | I12: n/a | J12: n/a
A13: Growth capex (total less maintenance) | B13: 0 | C13: 0 | D13: 0 | E13: 0 | F13: n/a | G13: n/a | H13: n/a | I13: n/a | J13: n/a
A14: Maintenance share ranged 0.0pp across 4 years (100.0% to 100.0%).
A16: WORKING CAPITAL (INR crore; days on a 365-day year)
B17: FY23A | C17: FY24A | D17: FY25A | E17: FY26A | F17: FY27E | G17: FY28E | H17: FY29E | I17: FY30E | J17: FY31E
A18: Trade receivables | B18: ='Balance Sheet'!B8 -> 549 | C18: ='Balance Sheet'!C8 -> 538 | D18: ='Balance Sheet'!D8 -> 802 | E18: ='Balance Sheet'!E8 -> 847 | F18: n/a | G18: n/a | H18: n/a | I18: n/a | J18: n/a
A19: Inventories | B19: ='Balance Sheet'!B9 -> 19361 | C19: ='Balance Sheet'!C9 -> 21154 | D19: ='Balance Sheet'!D9 -> 24621 | E19: ='Balance Sheet'!E9 -> 24717 | F19: n/a | G19: n/a | H19: n/a | I19: n/a | J19: n/a
A20: Trade payables | B20: ='Balance Sheet'!B20 -> 1644 | C20: ='Balance Sheet'!C20 -> 1655 | D20: ='Balance Sheet'!D20 -> 2261 | E20: ='Balance Sheet'!E20 -> 1720 | F20: n/a | G20: n/a | H20: n/a | I20: n/a | J20: n/a
A21: Trade working capital (receivables + inventories - payables) | B21: =B18+B19-B20 -> 18266 | C21: =C18+C19-C20 -> 20037 | D21: =D18+D19-D20 -> 23162 | E21: =E18+E19-E20 -> 23844 | F21: n/a | G21: n/a | H21: n/a | I21: n/a | J21: n/a
A22: Receivable days (on revenue) | B22: =B18/'Income Statement'!B5*365 -> 35.186128 | C22: =C18/'Income Statement'!C5*365 -> 30.553913 | D22: =D18/'Income Statement'!D5*365 -> 36.618714 | E22: =E18/'Income Statement'!E5*365 -> 37.729436 | F22: n/a | G22: n/a | H22: n/a | I22: n/a | J22: n/a
A23: Payable days (on total operating expenses) | B23: =B20/'Income Statement'!B9*365 -> 151.1867 | C23: =C20/'Income Statement'!C9*365 -> 140.38462 | D23: =D20/'Income Statement'!D9*365 -> 140.23195 | E23: =E20/'Income Statement'!E9*365 -> 93.076353 | F23: n/a | G23: n/a | H23: n/a | I23: n/a | J23: n/a
A24: Inventory days (on total operating expenses) | B24: =B19/'Income Statement'!B9*365 -> 1780.49 | C24: =C19/'Income Statement'!C9*365 -> 1794.3783 | D24: =D19/'Income Statement'!D9*365 -> 1527.0459 | E24: =E19/'Income Statement'!E9*365 -> 1337.5397 | F24: n/a | G24: n/a | H24: n/a | I24: n/a | J24: n/a
A25: Inventory and payable days use total operating expenses as the cost base because the statements do not all carry cost of goods sold; they are comparable across years of this issuer, not to a peer using cost of sales.
A27: CAPITAL ALLOCATION AND LEVERAGE (INR crore)
B28: FY23A | C28: FY24A | D28: FY25A | E28: FY26A | F28: FY27E | G28: FY28E | H28: FY29E | I28: FY30E | J28: FY31E
A29: Cash from operations | B29: ='Cash Flow'!B13 -> 2375 | C29: ='Cash Flow'!C13 -> 2539 | D29: ='Cash Flow'!D13 -> 5235 | E29: ='Cash Flow'!E13 -> 6347 | F29: n/a | G29: n/a | H29: n/a | I29: n/a | J29: n/a
A30: Free cash flow (CFO - capex) | B30: =B29-B7 -> 2311 | C30: =C29-C7 -> 2423 | D30: =D29-D7 -> 5139 | E30: =E29-E7 -> 6218 | F30: n/a | G30: n/a | H30: n/a | I30: n/a | J30: n/a
A31: Dividends paid (outflow shown positive) | B31: n/a | C31: n/a | D31: n/a | E31: n/a | F31: n/a | G31: n/a | H31: n/a | I31: n/a | J31: n/a
A32: Dividend payout (dividends / net income) | B32: n/a | C32: n/a | D32: n/a | E32: n/a | F32: n/a | G32: n/a | H32: n/a | I32: n/a | J32: n/a
A33: Debt issued / (repaid) | B33: n/a | C33: n/a | D33: n/a | E33: n/a | F33: n/a | G33: n/a | H33: n/a | I33: n/a | J33: n/a
A34: Share issuance / (repurchase) | B34: n/a | C34: n/a | D34: n/a | E34: n/a | F34: n/a | G34: n/a | H34: n/a | I34: n/a | J34: n/a
A35: Gross borrowings (short-term + long-term) | B35: n/a | C35: n/a | D35: n/a | E35: n/a | F35: n/a | G35: n/a | H35: n/a | I35: n/a | J35: n/a
A36: Cash and short-term investments | B36: n/a | C36: n/a | D36: n/a | E36: n/a | F36: n/a | G36: n/a | H36: n/a | I36: n/a | J36: n/a
A37: Net debt (borrowings - cash and short-term investments; excludes leases and long-term investments) | B37: n/a | C37: n/a | D37: n/a | E37: n/a | F37: n/a | G37: n/a | H37: n/a | I37: n/a | J37: n/a
A38: Net debt / EBITDA (x) | B38: n/a | C38: n/a | D38: n/a | E38: n/a | F38: n/a | G38: n/a | H38: n/a | I38: n/a | J38: n/a
A40: Operating segments: no Ind AS 108 segment disclosure was read for this issuer and the provider published no split.
A42: SECTOR SCHEDULE (REAL_ESTATE)
A43: Sector template | B43: Generic Operating Business
A44: Primary revenue method | B44: historical_trend_fallback
A45: Key drivers | B45: revenueGrowth; ebitdaMargin; capexPercentOfRevenue; workingCapitalRatio
...

Sheet Facts
A1: Facts: raw as-filed lines, canonical resolution, source documents
A2: The lines the statements were built from, by XBRL concept and fiscal year (INR crore), the canonical value against every second source with the authority that decided it, and the filings (hash, URL, retrieval time).
A4: As-filed statements: UNAVAILABLE no audited statutory XBRL filing was served for this issuer; the statements are not laid out line by line
A6: CANONICAL VS SECOND SOURCE (canonical provider SCREENER_INDIA; NOT a primary filing; policy 2026-09-30.1)
A7: Rows 80: 37 agree, 20 conflict, 0 second source unavailable, 23 not comparable. The canonical value is never averaged with a second source.
A8: Field | B8: Fiscal year | C8: Canonical provider | D8: Canonical value | E8: Second provider | F8: Second value | G8: Agreement | H8: Relative difference | I8: Final value / provider
A9: Revenue from operations | B9: FY23 | C9: SCREENER_INDIA | D9: 5695 | E9: YAHOO_INDIA | F9: 5681.972 | G9: AGREE | H9: 0.0022876207 | I9: 5695 (SCREENER_INDIA)
A10: Depreciation & amortisation | B10: FY23 | C10: SCREENER_INDIA | D10: 149 | E10: YAHOO_INDIA | F10: 148.633 | G10: AGREE | H10: 0.0024630872 | I10: 149 (SCREENER_INDIA)
A11: Finance costs | B11: FY23 | C11: SCREENER_INDIA | D11: 392 | E11: YAHOO_INDIA | F11: 364.258 | G11: CONFLICT | H11: 0.070770408 | I11: 392 (SCREENER_INDIA)
A12: Profit before tax | B12: FY23 | C12: SCREENER_INDIA | D12: 1502 | E12: YAHOO_INDIA | F12: 1502.419 | G12: AGREE | H12: 0.00027896138 | I12: 1502 (SCREENER_INDIA)
A13: Tax expense | B13: FY23 | C13: SCREENER_INDIA | D13: 405.54 | E13: YAHOO_INDIA | F13: 401.502 | G13: CONFLICT | H13: 0.0099570942 | I13: 405.54 (SCREENER_INDIA)
A14: Profit for the period (total, incl. NCI) | B14: FY23 | C14: SCREENER_INDIA | D14: 2034 | E14: YAHOO_INDIA | F14: 2035.825 | G14: AGREE | H14: 0.0008972468 | I14: 2034 (SCREENER_INDIA)
A15: Profit attributable to owners | B15: FY23 | C15: SCREENER_INDIA | D15: n/a | E15: YAHOO_INDIA | F15: 2035.825 | G15: NOT_COMPARABLE | H15: n/a | I15: null (null)
A16: Diluted EPS (as filed, unrestated) | B16: FY23 | C16: SCREENER_INDIA | D16: n/a | E16: YAHOO_INDIA | F16: 8.22 | G16: NOT_COMPARABLE | H16: n/a | I16: null (null)
A17: Total assets | B17: FY23 | C17: SCREENER_INDIA | D17: 52572 | E17: YAHOO_INDIA | F17: 53927.991 | G17: CONFLICT | H17: 0.025793027 | I17: 52572 (SCREENER_INDIA)
A18: Total equity (incl. NCI) | B18: FY23 | C18: SCREENER_INDIA | D18: n/a | E18: YAHOO_INDIA | F18: 37691.898 | G18: NOT_COMPARABLE | H18: n/a | I18: null (null)
A19: Equity attributable to owners | B19: FY23 | C19: SCREENER_INDIA | D19: 37687 | E19: YAHOO_INDIA | F19: 37687.534 | G19: AGREE | H19: 1.4169342e-05 | I19: 37687 (SCREENER_INDIA)
A20: Equity share capital (paid-up value) | B20: FY23 | C20: SCREENER_INDIA | D20: 495 | E20: YAHOO_INDIA | F20: 495.062 | G20: AGREE | H20: 0.00012525253 | I20: 495 (SCREENER_INDIA)
A21: Borrowings (non-current) | B21: FY23 | C21: SCREENER_INDIA | D21: n/a | E21: YAHOO_INDIA | F21: 1049.659 | G21: NOT_COMPARABLE | H21: n/a | I21: null (null)
A22: Borrowings (current) | B22: FY23 | C22: SCREENER_INDIA | D22: n/a | E22: YAHOO_INDIA | F22: 2053.426 | G22: NOT_COMPARABLE | H22: n/a | I22: null (null)
A23: Cash and cash equivalents | B23: FY23 | C23: SCREENER_INDIA | D23: 2275 | E23: YAHOO_INDIA | F23: 165.525 | G23: CONFLICT | H23: 0.92724176 | I23: 2275 (SCREENER_INDIA)
A24: Cash flow from operations | B24: FY23 | C24: SCREENER_INDIA | D24: 2375 | E24: YAHOO_INDIA | F24: 2375.264 | G24: AGREE | H24: 0.00011115789 | I24: 2375 (SCREENER_INDIA)
A25: Cash flow from investing | B25: FY23 | C25: SCREENER_INDIA | D25: -461 | E25: YAHOO_INDIA | F25: -462.624 | G25: AGREE | H25: 0.0035227766 | I25: -461 (SCREENER_INDIA)
A26: Cash flow from financing | B26: FY23 | C26: SCREENER_INDIA | D26: -2013 | E26: YAHOO_INDIA | F26: -2013.151 | G26: AGREE | H26: 7.5012419e-05 | I26: -2013 (SCREENER_INDIA)
A27: Capital expenditure (magnitude) | B27: FY23 | C27: SCREENER_INDIA | D27: -64 | E27: YAHOO_INDIA | F27: -63.743 | G27: AGREE | H27: 0.004015625 | I27: -64 (SCREENER_INDIA)
A28: Share count | B28: FY23 | C28: SCREENER_INDIA | D28: n/a | E28: YAHOO_INDIA | F28: 247.531 | G28: NOT_COMPARABLE | H28: n/a | I28: null (null)
A29: Revenue from operations | B29: FY24 | C29: SCREENER_INDIA | D29: 6427 | E29: YAHOO_INDIA | F29: 6249.21 | G29: CONFLICT | H29: 0.027662984 | I29: 6427 (SCREENER_INDIA)
A30: Depreciation & amortisation | B30: FY24 | C30: SCREENER_INDIA | D30: 148 | E30: YAHOO_INDIA | F30: 147.947 | G30: AGREE | H30: 0.00035810811 | I30: 148 (SCREENER_INDIA)
A31: Finance costs | B31: FY24 | C31: SCREENER_INDIA | D31: 356 | E31: YAHOO_INDIA | F31: 330.436 | G31: CONFLICT | H31: 0.071808989 | I31: 356 (SCREENER_INDIA)
A32: Profit before tax | B32: FY24 | C32: SCREENER_INDIA | D32: 2151 | E32: YAHOO_INDIA | F32: 2150.545 | G32: AGREE | H32: 0.00021152952 | I32: 2151 (SCREENER_INDIA)
A33: Tax expense | B33: FY24 | C33: SCREENER_INDIA | D33: 516.24 | E33: YAHOO_INDIA | F33: 520.13 | G33: CONFLICT | H33: 0.0075352549 | I33: 516.24 (SCREENER_INDIA)
A34: Profit for the period (total, incl. NCI) | B34: FY24 | C34: SCREENER_INDIA | D34: 2724 | E34: YAHOO_INDIA | F34: 2727.105 | G34: AGREE | H34: 0.0011398678 | I34: 2724 (SCREENER_INDIA)
A35: Profit attributable to owners | B35: FY24 | C35: SCREENER_INDIA | D35: n/a | E35: YAHOO_INDIA | F35: 2727.105 | G35: NOT_COMPARABLE | H35: n/a | I35: null (null)
A36: Diluted EPS (as filed, unrestated) | B36: FY24 | C36: SCREENER_INDIA | D36: n/a | E36: YAHOO_INDIA | F36: 11.02 | G36: NOT_COMPARABLE | H36: n/a | I36: null (null)
A37: Total assets | B37: FY24 | C37: SCREENER_INDIA | D37: 59069 | E37: YAHOO_INDIA | F37: 60262.397 | G37: CONFLICT | H37: 0.02020344 | I37: 59069 (SCREENER_INDIA)
A38: Total equity (incl. NCI) | B38: FY24 | C38: SCREENER_INDIA | D38: n/a | E38: YAHOO_INDIA | F38: 39431.617 | G38: NOT_COMPARABLE | H38: n/a | I38: null (null)
A39: Equity attributable to owners | B39: FY24 | C39: SCREENER_INDIA | D39: 39431 | E39: YAHOO_INDIA | F39: 39430.814 | G39: AGREE | H39: 4.7171008e-06 | I39: 39431 (SCREENER_INDIA)
A40: Equity share capital (paid-up value) | B40: FY24 | C40: SCREENER_INDIA | D40: 495 | E40: YAHOO_INDIA | F40: 495.062 | G40: AGREE | H40: 0.00012525253 | I40: 495 (SCREENER_INDIA)
A41: Borrowings (non-current) | B41: FY24 | C41: SCREENER_INDIA | D41: n/a | E41: YAHOO_INDIA | F41: 2438.987 | G41: NOT_COMPARABLE | H41: n/a | I41: null (null)
A42: Borrowings (current) | B42: FY24 | C42: SCREENER_INDIA | D42: n/a | E42: YAHOO_INDIA | F42: 2159.725 | G42: NOT_COMPARABLE | H42: n/a | I42: null (null)
...

Sheet Change Log
A1: Change log
A2: What changed, and against what. Vintages are saved snapshots of this issuer (each immutable, each with its hash); a change in fair value between two of them is the engine's, not this sheet's.
A4: SAVED SNAPSHOT VINTAGES OF THIS ISSUER (newest first; this workbook is marked)
A5: Snapshot | B5: Built at | C5: Price (INR) | D5: Price as of | E5: Primary method | F5: Fair value per share (INR) | G5: Change vs this workbook (INR) | H5: Change (%) | I5: Assumptions hash (12)
A6: snap_DLF_NS_b844a0b66419 <- THIS WORKBOOK | B6: 2026-11-01T15:04:41.411Z | C6: 691.55 | D6: 2026-10-30T00:00:00.000Z | E6: SOTP_SUM_OF_PARTS | F6: n/a | G6: 0 | H6: 0 | I6: 74234e98afe7
A7: snap_DLF_NS_fe75977cdfb5 | B7: 2026-11-01T15:04:41.361Z | C7: 691.55 | D7: 2026-10-30T00:00:00.000Z | E7: SOTP_SUM_OF_PARTS | F7: n/a | G7: n/a | H7: n/a | I7: 74234e98afe7
A9: OVERRIDES APPLIED TO THIS WORKBOOK
A10: None: this is the base case (every driver is history-derived or a disclosed model policy).
A12: RESTATEMENTS, PERIOD BREAKS AND SOURCE CONFLICTS IN THE DATA
A13: Diagnostic WARNING | B13: WARN_LEGACY_COMPATIBILITY_WITHHELD | C13: The legacy compatibility forecast, multi-stage DCF, scenarios and sensitivities are withheld: ERROR_INPUT_UNAVAILABLE: the FY26 statements do not serve otherCurrentAssets, intangibleAssetsAndGoodwill, otherNonCurrentAssets, shortTermBorrowings, otherCurrentLiabilities, longTermDebt, leaseLiabilities, deferredTaxLiabilities, otherNonCurrentLiabilities, otherEquity, minorityInterest; the integrated forecast rolls every one of them forward. Refusing to open them at 0.
A14: Diagnostic WARNING | B14: WARN_HIST_IS_PAT_BRIDGE | C14: HIST_IS_PAT_BRIDGE: FY23: PBT 1,502 - tax 406 = 1,097, net income reported 2,034, 938 above it (unexplained: discontinued operations / minority / associates not itemised) | FY24: PBT 2,151 - tax 516 = 1,635, net income reported 2,724, 1,089 above it (unexplained: discontinued operations / minority / associates not itemised) | FY25: PBT 2,261 - tax -430 = 2,691, net income reported 4,367, 1,676 above it (unexplained: discontinued operations / minority / associates not itemised) | FY26: PBT 2,932 - tax 323 = 2,610, net income reported 4,415, 1,806 above it (unexplained: discontinued operations / minority / associates not itemised)
A15: Diagnostic WARNING | B15: WARN_HIST_CASH_ROLL | C15: HIST_CASH_ROLL: FY24: opening 2,275 + net change 1,187 = 3,462, closing reported 4,384 | FY25: opening 4,384 + net change -643 = 3,741, closing reported 4,338 | FY26: opening 4,338 + net change 1,521 = 5,859, closing reported 7,746
A16: 20 provider conflict(s) between the canonical filing value and a second source are listed on the Facts sheet; the filing value stands.

Sheet Source Audit
A1: Source audit: provenance, accounting and recalculation checks, peer selection, limits
A2: Every figure carries its filing; every identity the model must satisfy is listed with its result; nothing that failed is dropped.
A4: PROVENANCE (8 sourced figures)
A5: Line item | B5: Fiscal year | C5: Value | D5: Unit | E5: Type | F5: Confidence | G5: Source filing | H5: URL | I5: sha256 of the stored filing | J5: Basis note
A6: Revenue (FY23) | B6: FY23 | C6: 5695 | D6: Crores | E6: PROVIDER_REPORTED | F6: Provider Reported | G6: Screener.in structured statements (Consolidated; secondary aggregator) | H6: n/a | I6: n/a | J6: REVENUE_BASIS_NOT_ASSESSED: this is the aggregator's "Sales" line. It is not reconciled to the filed Revenue from operations and can be lower where the aggregator nets excise duty or cess. Compare with the audited filing before reading margins.
A7: Net Income / PAT (FY23) | B7: FY23 | C7: 2034 | D7: Crores | E7: PROVIDER_REPORTED | F7: Provider Reported | G7: Screener.in structured statements (Consolidated; secondary aggregator) | H7: n/a | I7: n/a | J7: n/a
A8: Revenue (FY24) | B8: FY24 | C8: 6427 | D8: Crores | E8: PROVIDER_REPORTED | F8: Provider Reported | G8: Screener.in structured statements (Consolidated; secondary aggregator) | H8: n/a | I8: n/a | J8: REVENUE_BASIS_NOT_ASSESSED: this is the aggregator's "Sales" line. It is not reconciled to the filed Revenue from operations and can be lower where the aggregator nets excise duty or cess. Compare with the audited filing before reading margins.
A9: Net Income / PAT (FY24) | B9: FY24 | C9: 2724 | D9: Crores | E9: PROVIDER_REPORTED | F9: Provider Reported | G9: Screener.in structured statements (Consolidated; secondary aggregator) | H9: n/a | I9: n/a | J9: n/a
A10: Revenue (FY25) | B10: FY25 | C10: 7994 | D10: Crores | E10: PROVIDER_REPORTED | F10: Provider Reported | G10: Screener.in structured statements (Consolidated; secondary aggregator) | H10: n/a | I10: n/a | J10: REVENUE_BASIS_NOT_ASSESSED: this is the aggregator's "Sales" line. It is not reconciled to the filed Revenue from operations and can be lower where the aggregator nets excise duty or cess. Compare with the audited filing before reading margins.
A11: Net Income / PAT (FY25) | B11: FY25 | C11: 4367 | D11: Crores | E11: PROVIDER_REPORTED | F11: Provider Reported | G11: Screener.in structured statements (Consolidated; secondary aggregator) | H11: n/a | I11: n/a | J11: n/a
A12: Revenue (FY26) | B12: FY26 | C12: 8194 | D12: Crores | E12: PROVIDER_REPORTED | F12: Provider Reported | G12: Screener.in structured statements (Consolidated; secondary aggregator) | H12: n/a | I12: n/a | J12: REVENUE_BASIS_NOT_ASSESSED: this is the aggregator's "Sales" line. It is not reconciled to the filed Revenue from operations and can be lower where the aggregator nets excise duty or cess. Compare with the audited filing before reading margins.
A13: Net Income / PAT (FY26) | B13: FY26 | C13: 4415 | D13: Crores | E13: PROVIDER_REPORTED | F13: Provider Reported | G13: Screener.in structured statements (Consolidated; secondary aggregator) | H13: n/a | I13: n/a | J13: n/a
A15: ACCOUNTING AND RECALCULATION CHECKS (3 run; 3 pass; 0 not a plain pass, all shown first)
A16: Check | B16: Scope | C16: Status | D16: Computed | E16: Reported | F16: Difference | G16: Detail
A17: No DCF reading without a DCF | B17: VALUATION | C17: PASS | D17: n/a | E17: n/a | F17: n/a | G17: no DCF ran and no reading is published
A18: No bonus / split is classified as economic dilution | B18: HISTORICAL | C18: PASS | D18: n/a | E18: n/a | F18: n/a | G18: no share-count events
A19: Canonical v1 accounting invariants | B19: Critical Integrity Checks | C19: PASS | D19: n/a | E19: n/a | F19: n/a | G19: All canonical v1 accounting invariants hold across every projected period.
A21: PEER SELECTION (status AVAILABLE)
A22: Peer set | B22: Scope | C22: Selection rule | D22: Rationale | E22: Members
A23: Whole-company comparable set | B23: COMPANY | C23: analyst-defined REAL_ESTATE universe, subject excluded | D23: Listed Indian residential and commercial developers: project-cycle revenue recognition, lumpy cash flow, net-asset-value led. | E23: BRIGADE.NS, GODREJPROP.NS, LODHA.NS, OBEROIRLTY.NS, PRESTIGE.NS
A25: PUBLICATION STATE AND LIMITS
A26: Statement perimeter | B26: Consolidated
A27: Analysis status | B27: INVALID
A28: Valuation status | B28: INVALID
A29: Primary method | B29: SOTP_SUM_OF_PARTS
A30: Model package status | B30: EXECUTED_WITHHELD
A31: Confidence | B31: LOW
A32: Peer intelligence | B32: AVAILABLE
A33: Withheld / not measured | B33: Linked three-statement forecast | C33: the reported FY26 balance sheet does not balance as opened (assets 73465 vs liabilities + equity 47499 Cr); no forecast is built on it
A34: Withheld / not measured | B34: DCF cross-check | C34: Not eligible by methodology: valuation methodology routes this archetype (REAL_ESTATE) to Sum of the parts and prohibits the consolidated FCFF DCF. It is not forced to populate a sheet, and no DCF reading is published.
A35: Withheld / not measured | B35: Reverse DCF | C35: a reverse DCF inverts a consolidated FCFF DCF, which this archetype's methodology prohibits
A36: Withheld / not measured | B36: Segment analysis | C36: no Ind AS 108 segment disclosure was read for this issuer and the provider published no split
A37: Withheld / not measured | B37: Line-by-line statutory statements | C37: no audited statutory XBRL filing was served for this issuer; the statements are not laid out line by line
A38: Withheld / not measured | B38: Audited-filing statements | C38: The statements are a secondary tier's (SCREENER_INDIA); NSE corporate actions: RIGHTS_BLOCKED: NSE session-cookie API is paused by the owner pending legal review (nseSessionCookie); set ASTRA_ALLOW_NSE_SESSION_API=1 only after that review | NSE audited XBRL: NSE filing index unreachable: RIGHTS_BLOCKED: NSE session-cookie API is paused by the owner pending legal review (nseSessionCookie); set ASTRA_ALLOW_NSE_SESSION_API=1 only after that review.
A39: Confidence gate | B39: Reported statutory provenance coverage is low (0% of fields read from a filing; a further 100% are provider-reported statements, which are attributed but not statutory).
A40: Confidence gate | B40: ONE_OFF_UNMEASURED: FY26: PBT 2,932 - tax 323 = 2,610, reported profit 4,415; 1,806 Cr (61.6% of PBT) is not itemised by the data source (a share of associates / JVs, discontinued operations or exceptional items would each produce it; only the filing says which). This is a gap in the served data, not a finding of an accounting problem. No plug is inserted. Trailing P/E and EPS built on this profit are withheld; the EBIT-based FCFF does not read it.
A42: SAVED RECORD AND VERIFIER RECEIPTS
A43: This snapshot's saved record (provenance, publication states, discrepancies, peer selection, limits and every verifier receipt) is kept by FMB beside the exported files: GET /api/export/snapshot/snap_DLF_NS_b844a0b66419/record. Receipts are appended as verifiers run (workbook formula re-derivation, independent Monte Carlo), so they are read from the record, not stored in this file.

Sheet Chart Data
A1: Chart data (editable)
A2: The numbers behind the native charts on this sheet. Edit a cell and the chart redraws. Source is stated per block; nothing here is a forecast of its own.
A4: MONTE CARLO charts
A5: Not drawn: no Monte Carlo was published for this issuer. A distribution is not invented where the engine withheld one.
