Workbook
Name FairValuePerShare: Valuation!$B$6
Name CurrentPrice: Valuation!$B$7
Name UpsidePct: Valuation!$B$8
Name WACC_Pct: Valuation!$B$19
Name SnapshotId: Summary!$B$42
Name SnapshotHash: Summary!$B$43
Name Years_Header: 'Income Statement'!$B$4:$J$4
Name Revenue_Series: 'Income Statement'!$B$5:$J$5
Name EBITDA_Series: 'Income Statement'!$B$10:$J$10
Name NetIncome_Series: 'Income Statement'!$B$20:$J$20
Name EPS_Series: 'Income Statement'!$B$25:$J$25
Name CFO_Series: 'Cash Flow'!$B$13:$J$13
Name Capex_Series: 'Cash Flow'!$B$15:$J$15

Sheet Summary
A1: Bharti Airtel Limited (BHARTIARTL.NS)
A2: Telecommunications & Digital Network Infrastructure . NSE . base period FY26 . ₹ Crores unless stated
A5: VALUATION AND DECISION
A6: Current price (INR) | B6: ='Valuation'!B7 -> 1973.7
A7: Fair value per share (INR) | B7: ='Valuation'!B6 -> 2359.67
A8: Upside / (downside) | B8: ='Valuation'!B8 -> 0.19555657
A9: Primary method | B9: FCFF_DCF_3STAGE - 3-Stage FCFF DCF (100%)
A10: Confidence | B10: MEDIUM
A11: Status | B11: Telecommunications & Digital Network Infrastructure valued via FCFF_DCF_3STAGE. 59/59 accounting invariants passed; reasonableness verdict REQUIRES_ANALYST_JUSTIFICATION.
A13: KEY FINANCIALS (₹ Crores)
B14: Source sheet | C14: FY23A | D14: FY24A | E14: FY25A | F14: FY26A | G14: FY27E | H14: FY28E | I14: FY29E | J14: FY30E | K14: FY31E
A15: Revenue from operations | B15: Income Statement | C15: ='Income Statement'!B5 -> 139145 | D15: ='Income Statement'!C5 -> 149982 | E15: ='Income Statement'!D5 -> 172985 | F15: ='Income Statement'!E5 -> 210973 | G15: n/a | H15: n/a | I15: n/a | J15: n/a | K15: n/a
A16: EBITDA | B16: Income Statement | C16: ='Income Statement'!B10 -> 71274 | D16: ='Income Statement'!C10 -> 77893 | E16: ='Income Statement'!D10 -> 85060 | F16: ='Income Statement'!E10 -> 116514 | G16: n/a | H16: n/a | I16: n/a | J16: n/a | K16: n/a
A17: EBITDA margin | B17: Income Statement | C17: ='Income Statement'!B11 -> 0.51222825 | D17: ='Income Statement'!C11 -> 0.51934899 | E17: ='Income Statement'!D11 -> 0.49171894 | F17: ='Income Statement'!E11 -> 0.55226972 | G17: n/a | H17: n/a | I17: n/a | J17: n/a | K17: n/a
A18: Net income | B18: Income Statement | C18: ='Income Statement'!B20 -> 12287 | D18: ='Income Statement'!C20 -> 8558 | E18: ='Income Statement'!D20 -> 37481 | F18: ='Income Statement'!E20 -> 33823 | G18: n/a | H18: n/a | I18: n/a | J18: n/a | K18: n/a
A19: Diluted EPS (INR) | B19: Income Statement | C19: ='Income Statement'!B25 -> 20.16 | D19: ='Income Statement'!C25 -> 14.04 | E19: ='Income Statement'!D25 -> 61.5 | F19: ='Income Statement'!E25 -> 55.5 | G19: n/a | H19: n/a | I19: n/a | J19: n/a | K19: n/a
A20: Free cash flow (CFO - CapEx) | B20: Cash Flow | C20: ='Cash Flow'!B30 -> 38787 | D20: ='Cash Flow'!C30 -> 38846 | E20: ='Cash Flow'!D30 -> 58652 | F20: ='Cash Flow'!E30 -> 75516 | G20: n/a | H20: n/a | I20: n/a | J20: n/a | K20: n/a
A21: Return on equity | B21: engine ratio | C21: 0.15841316 | D21: 0.1072552 | E21: 0.38306309 | F21: 0.25747443 | G21: n/a | H21: n/a | I21: n/a | J21: n/a | K21: n/a
A23: RELATIVE POSITION (subject vs peer median; detail on the Peers sheet)
A24: Metric | B24: Subject | C24: Peer median | D24: Peers (n)
A25: P/E | B25: 36.422168 | C25: n/a | D25: 2
A26: EV/EBITDA | B26: 11.989478 | C26: n/a | D26: 1
A27: P/B | B27: 8.2646706 | C27: n/a | D27: 1
A28: FCF yield | B28: 6.1300082 | C28: n/a | D28: 2
A29: ROE | B29: 22.691319 | C29: n/a | D29: 1
A31: RISKS AND INVALIDATORS
A32: - Withheld: Linked three-statement forecast
A33: - Withheld: Segment analysis
A34: - Withheld: Line-by-line statutory statements
A35: - Withheld: Audited-filing statements
A36: - Market expectation: balanced realistic expectations (implied growth 15.4% vs model 14.88%)
A38: Every figure on this sheet links to its source sheet; nothing is calculated here. Formulas appear only where they reproduce the engine's own figure.
A39: Research only; not investment advice. A withheld, low-confidence or experimental output says so rather than offering a number.
A41: EXPORT SNAPSHOT (one immutable analysis behind every export of this model)
A42: Snapshot ID | B42: snap_BHARTIARTL_NS_24392f289409
A43: Snapshot SHA-256 | B43: 24392f289409666d0e762d32625c202a7f04b9ccbc4e042222fa8ae2b255fd9e
A44: Built at | B44: 2026-11-01T14:58:12.989Z
A45: Analysis status | B45: SUCCESS
A46: Price | B46: INR 1973.7
A47: Price as of | B47: 2026-10-30T00:00:00.000Z
...

Sheet Income Statement
A1: Income Statement (₹ Crores)
A2: Bharti Airtel Limited (BHARTIARTL.NS) . Consolidated . base period FY26
A3: A = reported . E = forecast . "n/a" = the source does not carry the line (never zero)
B4: FY23A | C4: FY24A | D4: FY25A | E4: FY26A | F4: FY27E | G4: FY28E | H4: FY29E | I4: FY30E | J4: FY31E
A5: Revenue from operations | B5: 139145 | C5: 149982 | D5: 172985 | E5: 210973 | F5: n/a | G5: n/a | H5: n/a | I5: n/a | J5: n/a
A6: growth (%) | B6: n/a | C6: =C5/B5-1 -> 0.077882784 | D6: =D5/C5-1 -> 0.15337174 | E6: =E5/D5-1 -> 0.21960286 | F6: n/a | G6: n/a | H6: n/a | I6: n/a | J6: n/a
A7: Employee benefit expenses | B7: n/a | C7: n/a | D7: n/a | E7: n/a | F7: n/a | G7: n/a | H7: n/a | I7: n/a | J7: n/a
A8: Other operating expenses | B8: n/a | C8: n/a | D8: n/a | E8: n/a | F8: n/a | G8: n/a | H8: n/a | I8: n/a | J8: n/a
A9: Total operating expenses | B9: 67871 | C9: 72089 | D9: 87925 | E9: 94459 | F9: n/a | G9: n/a | H9: n/a | I9: n/a | J9: n/a
A10: EBITDA (operating profit before D&A) | B10: =B5-B9 -> 71274 | C10: =C5-C9 -> 77893 | D10: =D5-D9 -> 85060 | E10: =E5-E9 -> 116514 | F10: n/a | G10: n/a | H10: n/a | I10: n/a | J10: n/a
A11: EBITDA margin (%) | B11: =B10/B5 -> 0.51222825 | C11: =C10/C5 -> 0.51934899 | D11: =D10/D5 -> 0.49171894 | E11: =E10/E5 -> 0.55226972 | F11: n/a | G11: n/a | H11: n/a | I11: n/a | J11: n/a
A12: Depreciation & amortisation | B12: 36432 | C12: 39538 | D12: 45570 | E12: 52711 | F12: n/a | G12: n/a | H12: n/a | I12: n/a | J12: n/a
A13: EBIT (operating profit) | B13: =B10-B12 -> 34842 | C13: =C10-C12 -> 38355 | D13: =D10-D12 -> 39490 | E13: =E10-E12 -> 63803 | F13: n/a | G13: n/a | H13: n/a | I13: n/a | J13: n/a
A14: EBIT margin (%) | B14: =B13/B5 -> 0.25040066 | C14: =C13/C5 -> 0.25573069 | D14: =D13/D5 -> 0.22828569 | E14: =E13/E5 -> 0.30242258 | F14: n/a | G14: n/a | H14: n/a | I14: n/a | J14: n/a
A15: Other non-operating income | B15: 1019 | C15: -3028 | D15: 20662 | E15: 2925 | F15: n/a | G15: n/a | H15: n/a | I15: n/a | J15: n/a
A16: Finance costs | B16: 19300 | C16: 22648 | D16: 21754 | E16: 21555 | F16: n/a | G16: n/a | H16: n/a | I16: n/a | J16: n/a
A17: Exceptional items (before tax; charge negative) | B17: n/a | C17: n/a | D17: n/a | E17: n/a | F17: n/a | G17: n/a | H17: n/a | I17: n/a | J17: n/a
A18: Profit before tax | B18: =B13+B15-B16+SUM(B17) -> 16561 | C18: =C13+C15-C16+SUM(C17) -> 12679 | D18: =D13+D15-D16+SUM(D17) -> 38398 | E18: =E13+E15-E16+SUM(E17) -> 45173 | F18: n/a | G18: n/a | H18: n/a | I18: n/a | J18: n/a
A19: Tax expense | B19: 4305.9 | C19: 4057.3 | D19: 768 | E19: 11293.3 | F19: n/a | G19: n/a | H19: n/a | I19: n/a | J19: n/a
A20: Net income / profit after tax | B20: 12287 | C20: 8558 | D20: 37481 | E20: 33823 | F20: n/a | G20: n/a | H20: n/a | I20: n/a | J20: n/a
A21: net margin (%) | B21: =B20/B5 -> 0.088303568 | C21: =C20/C5 -> 0.057060181 | D21: =D20/D5 -> 0.21667197 | E21: =E20/E5 -> 0.16031909 | F21: n/a | G21: n/a | H21: n/a | I21: n/a | J21: n/a
A22: Minority interest | B22: n/a | C22: n/a | D22: n/a | E22: n/a | F22: n/a | G22: n/a | H22: n/a | I22: n/a | J22: n/a
A23: Profit attributable to shareholders | B23: n/a | C23: n/a | D23: n/a | E23: n/a | F23: n/a | G23: n/a | H23: n/a | I23: n/a | J23: n/a
A24: Diluted shares (crore) | B24: 609.4 | C24: 609.4 | D24: 609.4 | E24: 609.4 | F24: n/a | G24: n/a | H24: n/a | I24: n/a | J24: n/a
A25: Diluted EPS (INR) | B25: 20.16 | C25: 14.04 | D25: 61.5 | E25: 55.5 | F25: n/a | G25: n/a | H25: n/a | I25: n/a | J25: n/a

Sheet Balance Sheet
A1: Balance Sheet (₹ Crores)
A2: Bharti Airtel Limited (BHARTIARTL.NS) . Consolidated . base period FY26
A3: A = reported . E = forecast . "n/a" = the source does not carry the line (never zero)
B4: FY23A | C4: FY24A | D4: FY25A | E4: FY26A | F4: FY27E | G4: FY28E | H4: FY29E | I4: FY30E | J4: FY31E
A5: CURRENT ASSETS
A6: Cash and cash equivalents | B6: 13419 | C6: 16340 | D6: 16720 | E6: 30377 | F6: n/a | G6: n/a | H6: n/a | I6: n/a | J6: n/a
A7: Short-term investments | B7: n/a | C7: n/a | D7: n/a | E7: n/a | F7: n/a | G7: n/a | H7: n/a | I7: n/a | J7: n/a
A8: Trade receivables | B8: 3982 | C8: 4728 | D8: 7456 | E8: 7978 | F8: n/a | G8: n/a | H8: n/a | I8: n/a | J8: n/a
A9: Inventories | B9: 258 | C9: 364 | D9: 452 | E9: 601 | F9: n/a | G9: n/a | H9: n/a | I9: n/a | J9: n/a
A10: Other current assets | B10: n/a | C10: n/a | D10: n/a | E10: n/a | F10: n/a | G10: n/a | H10: n/a | I10: n/a | J10: n/a
A11: Total current assets | B11: n/a | C11: n/a | D11: n/a | E11: n/a | F11: n/a | G11: n/a | H11: n/a | I11: n/a | J11: n/a
A12: NON-CURRENT ASSETS
A13: Property, plant & equipment (net) | B13: 277394 | C13: 303303 | D13: 388468 | E13: 406337 | F13: n/a | G13: n/a | H13: n/a | I13: n/a | J13: n/a
A14: Intangibles & goodwill | B14: n/a | C14: n/a | D14: n/a | E14: n/a | F14: n/a | G14: n/a | H14: n/a | I14: n/a | J14: n/a
A15: Non-current investments | B15: 32954 | C15: 31602 | D15: 5838 | E15: 18901 | F15: n/a | G15: n/a | H15: n/a | I15: n/a | J15: n/a
A16: Other non-current assets | B16: n/a | C16: n/a | D16: n/a | E16: n/a | F16: n/a | G16: n/a | H16: n/a | I16: n/a | J16: n/a
A17: Total non-current assets | B17: n/a | C17: n/a | D17: n/a | E17: n/a | F17: n/a | G17: n/a | H17: n/a | I17: n/a | J17: n/a
A18: TOTAL ASSETS | B18: 444557 | C18: 442019 | D18: 505006 | E18: 545373 | F18: n/a | G18: n/a | H18: n/a | I18: n/a | J18: n/a
A19: CURRENT LIABILITIES
A20: Trade payables | B20: 32895 | C20: 35132 | D20: 38154 | E20: 45015 | F20: n/a | G20: n/a | H20: n/a | I20: n/a | J20: n/a
A21: Short-term borrowings | B21: n/a | C21: n/a | D21: n/a | E21: n/a | F21: n/a | G21: n/a | H21: n/a | I21: n/a | J21: n/a
A22: Other current liabilities | B22: n/a | C22: n/a | D22: n/a | E22: n/a | F22: n/a | G22: n/a | H22: n/a | I22: n/a | J22: n/a
A23: Total current liabilities | B23: n/a | C23: n/a | D23: n/a | E23: n/a | F23: n/a | G23: n/a | H23: n/a | I23: n/a | J23: n/a
A24: NON-CURRENT LIABILITIES
A25: Long-term debt | B25: n/a | C25: n/a | D25: n/a | E25: n/a | F25: n/a | G25: n/a | H25: n/a | I25: n/a | J25: n/a
A26: Lease liabilities | B26: n/a | C26: n/a | D26: n/a | E26: n/a | F26: n/a | G26: n/a | H26: n/a | I26: n/a | J26: n/a
A27: Deferred tax liabilities | B27: n/a | C27: n/a | D27: n/a | E27: n/a | F27: n/a | G27: n/a | H27: n/a | I27: n/a | J27: n/a
A28: Other non-current liabilities | B28: n/a | C28: n/a | D28: n/a | E28: n/a | F28: n/a | G28: n/a | H28: n/a | I28: n/a | J28: n/a
A29: Total non-current liabilities | B29: n/a | C29: n/a | D29: n/a | E29: n/a | F29: n/a | G29: n/a | H29: n/a | I29: n/a | J29: n/a
A30: TOTAL LIABILITIES | B30: n/a | C30: n/a | D30: n/a | E30: n/a | F30: n/a | G30: n/a | H30: n/a | I30: n/a | J30: n/a
A31: EQUITY
A32: Share capital | B32: 2837 | C32: 2877 | D32: 2900 | E32: 3047 | F32: n/a | G32: n/a | H32: n/a | I32: n/a | J32: n/a
A33: Reserves & surplus | B33: 74726 | C33: 79142 | D33: 110772 | E33: 146010 | F33: n/a | G33: n/a | H33: n/a | I33: n/a | J33: n/a
A34: Other equity | B34: n/a | C34: n/a | D34: n/a | E34: n/a | F34: n/a | G34: n/a | H34: n/a | I34: n/a | J34: n/a
A35: Non-controlling interests | B35: n/a | C35: n/a | D35: n/a | E35: n/a | F35: n/a | G35: n/a | H35: n/a | I35: n/a | J35: n/a
A36: TOTAL EQUITY | B36: n/a | C36: n/a | D36: n/a | E36: n/a | F36: n/a | G36: n/a | H36: n/a | I36: n/a | J36: n/a
A37: TOTAL LIABILITIES AND EQUITY | B37: n/a | C37: n/a | D37: n/a | E37: n/a | F37: n/a | G37: n/a | H37: n/a | I37: n/a | J37: n/a
A38: Balance check (assets - liabilities - equity) | B38: n/a | C38: n/a | D38: n/a | E38: n/a | F38: n/a | G38: n/a | H38: n/a | I38: n/a | J38: n/a

Sheet Cash Flow
A1: Cash Flow (₹ Crores)
A2: Bharti Airtel Limited (BHARTIARTL.NS) . Consolidated . base period FY26
A3: A = reported . E = forecast . "n/a" = the source does not carry the line (never zero)
B4: FY23A | C4: FY24A | D4: FY25A | E4: FY26A | F4: FY27E | G4: FY28E | H4: FY29E | I4: FY30E | J4: FY31E
A5: OPERATING ACTIVITIES
A6: Net income | B6: 12287 | C6: 8558 | D6: 37481 | E6: 33823 | F6: n/a | G6: n/a | H6: n/a | I6: n/a | J6: n/a
A7: Depreciation & amortisation | B7: 36432 | C7: 39538 | D7: 45570 | E7: 52711 | F7: n/a | G7: n/a | H7: n/a | I7: n/a | J7: n/a
A8: Other non-cash adjustments | B8: n/a | C8: n/a | D8: n/a | E8: n/a | F8: n/a | G8: n/a | H8: n/a | I8: n/a | J8: n/a
A9: Change in trade receivables | B9: n/a | C9: n/a | D9: n/a | E9: n/a | F9: n/a | G9: n/a | H9: n/a | I9: n/a | J9: n/a
A10: Change in inventories | B10: n/a | C10: n/a | D10: n/a | E10: n/a | F10: n/a | G10: n/a | H10: n/a | I10: n/a | J10: n/a
A11: Change in trade payables | B11: n/a | C11: n/a | D11: n/a | E11: n/a | F11: n/a | G11: n/a | H11: n/a | I11: n/a | J11: n/a
A12: Change in other working capital | B12: n/a | C12: n/a | D12: n/a | E12: n/a | F12: n/a | G12: n/a | H12: n/a | I12: n/a | J12: n/a
A13: Cash from operations (CFO) | B13: 65325 | C13: 78898 | D13: 98332 | E13: 122230 | F13: n/a | G13: n/a | H13: n/a | I13: n/a | J13: n/a
A14: INVESTING ACTIVITIES
A15: Capital expenditure | B15: -26538 | C15: -40052 | D15: -39680 | E15: -46714 | F15: n/a | G15: n/a | H15: n/a | I15: n/a | J15: n/a
A16: Net purchase / sale of investments | B16: n/a | C16: n/a | D16: n/a | E16: n/a | F16: n/a | G16: n/a | H16: n/a | I16: n/a | J16: n/a
A17: Other investing activities | B17: n/a | C17: n/a | D17: n/a | E17: n/a | F17: n/a | G17: n/a | H17: n/a | I17: n/a | J17: n/a
A18: Cash from investing (CFI) | B18: -39232 | C18: -51089 | D18: -60198 | E18: -56205 | F18: n/a | G18: n/a | H18: n/a | I18: n/a | J18: n/a
A19: FINANCING ACTIVITIES
A20: Debt issued / (repaid) | B20: n/a | C20: n/a | D20: n/a | E20: n/a | F20: n/a | G20: n/a | H20: n/a | I20: n/a | J20: n/a
A21: Dividends paid | B21: n/a | C21: n/a | D21: n/a | E21: n/a | F21: n/a | G21: n/a | H21: n/a | I21: n/a | J21: n/a
A22: Share issuance / (repurchase) | B22: n/a | C22: n/a | D22: n/a | E22: n/a | F22: n/a | G22: n/a | H22: n/a | I22: n/a | J22: n/a
A23: Lease payments & other financing | B23: n/a | C23: n/a | D23: n/a | E23: n/a | F23: n/a | G23: n/a | H23: n/a | I23: n/a | J23: n/a
A24: Cash from financing (CFF) | B24: -24470 | C24: -27778 | D24: -36533 | E24: -52293 | F24: n/a | G24: n/a | H24: n/a | I24: n/a | J24: n/a
A25: Net change in cash | B25: =SUM(B13,B18,B24) -> 1623 | C25: =SUM(C13,C18,C24) -> 31 | D25: =SUM(D13,D18,D24) -> 1601 | E25: =SUM(E13,E18,E24) -> 13732 | F25: n/a | G25: n/a | H25: n/a | I25: n/a | J25: n/a
A26: Opening cash | B26: 11796 | C26: 13419 | D26: 16340 | E26: 16720 | F26: n/a | G26: n/a | H26: n/a | I26: n/a | J26: n/a
A27: Closing cash | B27: =SUM(B26,B25) -> 13419 | C27: 16340 | D27: 16720 | E27: 30377 | F27: n/a | G27: n/a | H27: n/a | I27: n/a | J27: n/a
A29: FREE CASH FLOW (CFO - CapEx; CapEx a positive outflow; INR crore)
A30: Free cash flow (FCF) | B30: =B13-ABS(B15) -> 38787 | C30: =C13-ABS(C15) -> 38846 | D30: =D13-ABS(D15) -> 58652 | E30: =E13-ABS(E15) -> 75516 | F30: n/a | G30: n/a | H30: n/a | I30: n/a | J30: n/a
A31: FCF margin (FCF / revenue) | B31: =B30/'Income Statement'!B5 -> 0.27875238 | C31: =C30/'Income Statement'!C5 -> 0.25900441 | D31: =D30/'Income Statement'!D5 -> 0.3390583 | E31: =E30/'Income Statement'!E5 -> 0.35794154 | F31: n/a | G31: n/a | H31: n/a | I31: n/a | J31: n/a
A32: FCF conversion (FCF / net income) | B32: =B30/'Income Statement'!B20 -> 3.156751 | C32: =C30/'Income Statement'!C20 -> 4.5391447 | D32: =D30/'Income Statement'!D20 -> 1.5648462 | E32: =E30/'Income Statement'!E20 -> 2.2326819 | F32: n/a | G32: n/a | H32: n/a | I32: n/a | J32: n/a

Sheet Operating Drivers
A1: Operating Drivers
A2: The economic drivers the forecast is built from: what history shows, what the model assumes, and why. To change a driver, use the Model Builder in the application: it rebuilds the model and re-exports (a rebuilt state is labelled).
A4: Driver | B4: FY27E | C4: FY28E | D4: FY29E | E4: FY30E | F4: FY31E
A5: Revenue growth | B5: 0.15337174 | C5: 0.1275288 | D5: 0.10168587 | E5: 0.075842934 | F5: 0.05
A6: Employee cost (% of revenue) | B6: 0 | C6: 0 | D6: 0 | E6: 0 | F6: 0
A7: Other operating expenses (% of revenue) | B7: 0.48421138 | C7: 0.48421138 | D7: 0.48421138 | E7: 0.48421138 | F7: 0.48421138
A8: Effective tax rate | B8: 0.26000242 | C8: 0.26000242 | D8: 0.26000242 | E8: 0.26000242 | F8: 0.26000242
A9: Receivable days | B9: 13 | C9: 13 | D9: 13 | E9: 13 | F9: 13
A10: Inventory days | B10: 0 | C10: 0 | D10: 0 | E10: 0 | F10: 0
A11: Payable days | B11: 25 | C11: 25 | D11: 25 | E11: 25 | F11: 25
A12: Capex (% of revenue) | B12: 0.22540287 | C12: 0.20849766 | D12: 0.19159244 | E12: 0.17468723 | F12: 0.15778201
A13: Dividend payout ratio | B13: 0.6 | C13: 0.6 | D13: 0.6 | E13: 0.6 | F13: 0.6
A15: This issuer has no linked three-statement driver set; the drivers above are the legacy forecast assumptions as published.
A17: Revenue driver (provenance of the topline)
A18: Basis | C18: NOT_APPLICABLE: no sector volume x price driver; revenue grows on own reported history
A19: Unit | C19: n/a
A20: Provenance | C20: Revenue growth from this company's own reported history. Sector volume x price driver UNAVAILABLE [SECTOR_DRIVER_DATA_UNAVAILABLE] for TELECOM: Wireless Revenue = Subscribers (Million) * ARPU (INR/month) * 12 / 10 needs sourced Wireless Subscriber Base and Average Revenue Per User (ARPU). Not held for BHARTIARTL.NS: wireless_subscribers_million, arpu_inr_month. Note: subscribers x ARPU prices the wireless line only; consolidated revenue includes lines that equation does not cover, so it cannot reconcile to the entity. No volume, price or growth is inferred.

Sheet Valuation
A1: Valuation
A2: One primary method, routed by the company's economics; the rest are cross-checks and are never averaged into it. A withheld valuation states why and publishes no value.
A4: PRIMARY VALUATION
A5: Method | B5: FCFF_DCF_3STAGE - 3-Stage FCFF DCF (100%)
A6: Fair value per share (INR) | B6: =B30 -> 2359.67
A7: Current price (INR) | B7: 1973.7
A8: Upside / (downside) | B8: =B6/B7-1 -> 0.19555657
A9: Confidence | B9: MEDIUM | C9: Confidence of the primary method as stated by the model (MEDIUM).
A10: Status | B10: VALID
A11: Price basis | B11: NSE official close of 2026-10-30
A14: 3-Stage FCFF DCF (Economic ROIC Fade): free cash flow to firm and enterprise-to-equity bridge (INR crore)
B15: FY27E | C15: FY28E | D15: FY29E | E15: FY30E | F15: FY31E | G15: FY32E | H15: FY33E | I15: FY34E | J15: FY35E | K15: FY36E
A16: FCFF | B16: 33069 | C16: 61379 | D16: 68594 | E16: 77156 | F16: 87228 | G16: 70981.569 | H16: 83846.712 | I16: 98808.631 | J16: 115835.88 | K16: 134639.84
A17: Stage | B17: EXPLICIT | C17: EXPLICIT | D17: EXPLICIT | E17: EXPLICIT | F17: EXPLICIT | G17: FADE | H17: FADE | I17: FADE | J17: FADE | K17: FADE
A19: WACC (%) | B19: 9.995016
A20: Terminal growth (%) | B20: 5
A21: PV of explicit-period FCFF | B21: 492435
A22: PV of terminal value | B22: 1091681
A23: Enterprise value | B23: =B21+B22 -> 1584116
A24: Less: net debt (borrowings + preferred - cash) | B24: 165035
A25: Less: lease liabilities | B25: n/a
A26: Less: minority interest | B26: n/a
A27: Plus: non-operating investments at book (non-current + equity-method) | B27: 18901
A28: Equity value | B28: =B23-B24+B27 -> 1437982
A29: Shares (crore) | B29: 609.4
A30: Fair value per share (INR) | B30: =B28/B29 -> 2359.67
A32: METHOD RANGES (INR per share) -- cross-checks beside the primary method
A33: Method | B33: Low | C33: Base | D33: High | E33: Weight % | F33: Role
A34: 3-Stage FCFF DCF (ROIC Fade) | B34: 2171 | C34: 2359.67 | D34: 2596 | E34: 100 | F34: PRIMARY
A35: 2-Stage FCFF DCF (Gordon Growth) | B35: 1837 | C35: 2040.61 | D35: 2285 | E35: 0 | F35: cross-check
A36: Exit Multiple DCF (10.5x EV/EBITDA) | B36: 2216 | C36: 2517.69 | D36: 2895 | E36: 0 | F36: cross-check
A37: Peer Trading Comps (25.8x trailing P/E; EV/EBITDA route withheld) | B37: 1289 | C37: 1431.96 | D37: 1575 | E37: 0 | F37: cross-check
A39: MARKET CROSS-CHECKS
A40: Trading comparables (implied price) | B40: 1431.96
A41: Reverse valuation (what the price implies) | B41: AVAILABLE | C41: At 1973.70 (NSE official close (UDiFF bhavcopy) + Screener.in structured dataset, as of 2026-10-30) the market prices in a 10-year FCFF growth rate of 15.40% against a bottom-up fundamental base case of 14.88%, a gap of +52 bps. Discounted at 10.00% with 5.00% perpetual growth (mid-year convention). This describes market EXPECTATIONS, not fair value.
A43: NOT MEASURED -- stated, bounded where a bound exists, never filled
A44: Item | B44: Direction | C44: Bound (INR/share) | D44: Why
A45: Linked three-statement forecast | B45: withheld | D45: the reported FY26 balance sheet does not balance as opened (assets 545373 vs liabilities + equity 389484 Cr); no forecast is built on it
A46: Segment analysis | B46: withheld | D46: no Ind AS 108 segment disclosure was read for this issuer and the provider published no split
A47: Line-by-line statutory statements | B47: withheld | D47: no audited statutory XBRL filing was served for this issuer; the statements are not laid out line by line
...

Sheet Peers
A1: Peers
A2: One peer payload, one statistic definition: the median is the headline; quartiles and the sample size sit beside it. Outliers (Tukey fences, 5+ peers) are shown struck from the statistics and listed. Statistics are live formulas over the peer cells.
A4: Whole-company comparable set . 2 peer(s) . analyst-defined TELECOM universe, subject excluded
A5: Listed Indian telecom operators (a small set: Jio sits inside RELIANCE, BSNL is unlisted, tower companies are not operators).
A6: Basis: P/E and P/B for the subject and every peer are the provider's own figures, not recomputed from the model's FY26 EPS and BVPS, so the subject can differ from price / FY26 EPS (provider EPS and book-value dates are not stated by the provider).
A7: Company | B7: Comparability | C7: P/E | D7: EV/EBITDA | E7: EV/EBIT | F7: EV/Sales | G7: P/B | H7: FCF yield % | I7: Div. yield % | J7: ROIC % | K7: ROE % | L7: EBITDA margin % | M7: FCF margin % | N7: Cash conv. % | O7: Net debt/EBITDA | P7: Interest cover
A8: BHARTIARTL.NS (subject) | B8: subject | C8: 36.422168 | D8: 11.989478 | E8: 21.894613 | F8: 6.6214255 | G8: 8.2646706 | H8: 6.1300082 | I8: 1.22 | J8: 15.235106 | K8: 22.691319 | L8: 55.226972 | M8: 35.794154 | N8: 223.26819 | O8: 1.4164392 | P8: 2.9600093
A9: IDEA.NS | B9: HIGH (4/5) | C9: 3.7094814 | D9: 16.701151 | E9: n/a | F9: 7.0190761 | G9: n/a | H9: 6.5787626 | I9: 0 | J9: -2.1511 | K9: n/a | L9: 42.0275 | M9: 18.79081 | N9: 24.403797 | O9: 9.904926 | P9: -0.15115143
A10: TATACOMM.NS | B10: MEDIUM (3/4) | C10: 47.90672 | D10: n/a | E10: n/a | F10: n/a | G10: 14.043811 | H10: 4.2836505 | I10: 1.04 | J10: n/a | K10: 29.314907 | L10: 19.441197 | M10: 8.2490021 | N10: 205.21565 | O10: n/a | P10: 2.6181102
A11: Peer median | C11: n/a | D11: n/a | E11: n/a | F11: n/a | G11: n/a | H11: n/a | I11: n/a | J11: n/a | K11: n/a | L11: n/a | M11: n/a | N11: n/a | O11: n/a | P11: n/a
A12: 25th percentile | C12: n/a | D12: n/a | E12: n/a | F12: n/a | G12: n/a | H12: n/a | I12: n/a | J12: n/a | K12: n/a | L12: n/a | M12: n/a | N12: n/a | O12: n/a | P12: n/a
A13: 75th percentile | C13: n/a | D13: n/a | E13: n/a | F13: n/a | G13: n/a | H13: n/a | I13: n/a | J13: n/a | K13: n/a | L13: n/a | M13: n/a | N13: n/a | O13: n/a | P13: n/a
A14: Mean | C14: n/a | D14: n/a | E14: n/a | F14: n/a | G14: n/a | H14: n/a | I14: n/a | J14: n/a | K14: n/a | L14: n/a | M14: n/a | N14: n/a | O14: n/a | P14: n/a
A15: Peers used (n) | C15: =COUNT(C9:C10) -> 2 | D15: =COUNT(D9:D10) -> 1 | E15: =COUNT(E9:E10) -> 0 | F15: =COUNT(F9:F10) -> 1 | G15: =COUNT(G9:G10) -> 1 | H15: =COUNT(H9:H10) -> 2 | I15: =COUNT(I9:I10) -> 2 | J15: =COUNT(J9:J10) -> 1 | ... P15: =COUNT(P9:P10) -> 2
A16: Sample state | C16: INSUFFICIENT PEERS | D16: INSUFFICIENT PEERS | E16: INSUFFICIENT PEERS | F16: INSUFFICIENT PEERS | G16: INSUFFICIENT PEERS | H16: INSUFFICIENT PEERS | I16: INSUFFICIENT PEERS | J16: INSUFFICIENT PEERS | K16: INSUFFICIENT PEERS | L16: INSUFFICIENT PEERS | M16: INSUFFICIENT PEERS | N16: INSUFFICIENT PEERS | O16: INSUFFICIENT PEERS | P16: INSUFFICIENT PEERS
A17: Subject vs median (%) | C17: n/a | D17: n/a | E17: n/a | F17: n/a | G17: n/a | H17: n/a | I17: n/a | J17: n/a | K17: n/a | L17: n/a | M17: n/a | N17: n/a | O17: n/a | P17: n/a
A19: mean / median / p25 / p75 use linear-interpolation quantiles (spreadsheet QUARTILE.INC / MEDIAN); non-finite values are dropped, never zeroed; a duplicated peer counts once. Tukey fences (Q1 - 1.5 x IQR, Q3 + 1.5 x IQR) applied only with 5 or more values; outliers are excluded from the statistics and listed.
A20: FCF = CFO - CapEx (latest annual fiscal year, INR crore, CapEx a positive outflow); FCF margin = FCF / revenue; FCF conversion = FCF / net profit; FCF yield = FCF / market cap; FCFE = FCF + net borrowing (needs both borrowing balances); FCF CAGR over 3 fiscal years needs both endpoints > 0. Regulated financials carry no corporate FCF.

Sheet Scenarios & Assumptions
A1: Scenarios & Assumptions
A2: What would change the answer: scenarios, the discount-rate / growth grid, what the price implies, and the assumptions and limits behind it.
A4: SENSITIVITY: implied value per share (INR) -- WACC (%) down, Terminal Growth Rate (%) across
A5: WACC (%) \ Terminal Growth Rate (%) | B5: 3.5% | C5: 4% | D5: 4.5% | E5: 5% | F5: 5.5% | G5: 6%
A6: 8.5% | B6: 2756.51 | C6: 2956.15 | D6: 3204.73 | E6: 3523.24 | F6: 3946.72 | G6: 4538.23
A7: 9% | B7: 2463 | C7: 2617.05 | D7: 2804.51 | E7: 3037.92 | F7: 3336.99 | G7: 3734.58
A8: 9.5% | B8: 2219.17 | C8: 2340.28 | D8: 2484.91 | E8: 2660.9 | F8: 2880.02 | G8: 3160.76
A9: 10% | B9: 2013.5 | C9: 2110.22 | D9: 2223.91 | E9: 2359.67 | F9: 2524.85 | G9: 2730.5
A10: 10.5% | B10: 1837.8 | C10: 1916.06 | D10: 2006.83 | E10: 2113.53 | F10: 2240.92 | G10: 2395.92
A11: 11% | B11: 1686.05 | C11: 1750.09 | D11: 1823.52 | E11: 1908.69 | F11: 2008.79 | G11: 2128.3
A13: REVERSE VALUATION: what the current price implies (expectations, not fair value)
A14: Market price (INR) | B14: 1973.7
A15: Implied 10-year revenue growth (CAGR %) | B15: 15.4
A16: Model base-case revenue growth (CAGR %) | B16: 14.88
A17: Expectation gap (bps) | B17: 52
A18: Implied terminal ROIC (%) | B18: 30.74
A19: Verdict | B19: balanced realistic expectations
A20: At 1973.70 (NSE official close (UDiFF bhavcopy) + Screener.in structured dataset, as of 2026-10-30) the market prices in a 10-year FCFF growth rate of 15.40% against a bottom-up fundamental base case of 14.88%, a gap of +52 bps. Discounted at 10.00% with 5.00% perpetual growth (mid-year convention). This describes market EXPECTATIONS, not fair value.
A22: MONTE CARLO (20000 valid paths, seed 133742): distribution of value per share (INR)
A23: P5 | B23: P25 | C23: P50 | D23: P75 | E23: P95 | F23: Mean | G23: P(value > price) %
A24: 673.7 | B24: 1033.2 | C24: 1364.5 | D24: 1789.7 | E24: 2600.8 | F24: 1467 | G24: 17.6
A26: ASSUMPTIONS APPLIED
A27: Base case: no user override. Every driver is the history-derived recommendation or a disclosed model policy.
A28: WACC (%) | B28: 9.995016
A29: Risk-free rate (%) | B29: 6.95
A30: Beta | B30: 0.661
A31: Equity risk premium (%) | B31: 5.5
A32: Cost of equity (%) | B32: 10.5855
A33: After-tax cost of debt (%) | B33: 6.36055
A34: Terminal growth (%) | B34: 5
A35: Discount rate used by the primary method. Risk-free source: Reserve Bank of India 10-Yr G-Sec Benchmark Yield (7.10 GS 2034) (dated reference snapshot as of 2026-08-28; not read live) (REFERENCE_SNAPSHOT).
A37: MANAGEMENT GUIDANCE
A38: No verified guidance: FMB's guidance registry holds no sourced item for this company. Nothing is assumed or filled in.
A40: LIMITS AND SOURCE NOTES
A41: Statements: Consolidated annual figures; INR crore; fiscal year ending March. Period-length differences are normalised once and disclosed.
A42: Price: NSE official close of 2026-10-30.
A43: Peer statistics are computed from the same provider extractor for the subject and every peer; see the Peers sheet for the statistic definition.
A44: Withheld: Linked three-statement forecast -- the reported FY26 balance sheet does not balance as opened (assets 545373 vs liabilities + equity 389484 Cr); no forecast is built on it
A45: Withheld: Segment analysis -- no Ind AS 108 segment disclosure was read for this issuer and the provider published no split
A46: Withheld: Line-by-line statutory statements -- no audited statutory XBRL filing was served for this issuer; the statements are not laid out line by line
...

Sheet Quarterly
A1: Quarterly statements (INR crore, as filed)
A2: Read from each quarter's own filed XBRL (the three-month column; the year-to-date column is never used as a quarter). Unaudited except the March quarter.
A4: UNAVAILABLE: NSE quarterly listing unreachable: RIGHTS_BLOCKED: NSE session-cookie API is paused by the owner pending legal review (nseSessionCookie); set ASTRA_ALLOW_NSE_SESSION_API=1 only after that review. No quarterly figure is estimated or interpolated.

Sheet Common Size
A1: Common-size statements, ratios, DuPont and forensic screens
A2: Common-size lines are live formulas over the statement sheets (line / revenue, line / total assets). Ratios, DuPont and the scores are the engine's published figures.
A4: INCOME STATEMENT AS % OF REVENUE (reported and forecast)
A5: % of revenue | B5: FY23A | C5: FY24A | D5: FY25A | E5: FY26A | F5: FY27E | G5: FY28E | H5: FY29E | I5: FY30E | J5: FY31E
A6: Revenue | B6: ='Income Statement'!B5/'Income Statement'!B5 -> 1 | C6: ='Income Statement'!C5/'Income Statement'!C5 -> 1 | D6: ='Income Statement'!D5/'Income Statement'!D5 -> 1 | E6: ='Income Statement'!E5/'Income Statement'!E5 -> 1 | F6: n/a | G6: n/a | H6: n/a | I6: n/a | J6: n/a
A7: Employee benefit expenses | B7: n/a | C7: n/a | D7: n/a | E7: n/a | F7: n/a | G7: n/a | H7: n/a | I7: n/a | J7: n/a
A8: Other operating expenses | B8: n/a | C8: n/a | D8: n/a | E8: n/a | F8: n/a | G8: n/a | H8: n/a | I8: n/a | J8: n/a
A9: Total operating expenses | B9: ='Income Statement'!B9/'Income Statement'!B5 -> 0.48777175 | C9: ='Income Statement'!C9/'Income Statement'!C5 -> 0.48065101 | D9: ='Income Statement'!D9/'Income Statement'!D5 -> 0.50828106 | E9: ='Income Statement'!E9/'Income Statement'!E5 -> 0.44773028 | F9: n/a | G9: n/a | H9: n/a | I9: n/a | J9: n/a
A10: EBITDA | B10: ='Income Statement'!B10/'Income Statement'!B5 -> 0.51222825 | C10: ='Income Statement'!C10/'Income Statement'!C5 -> 0.51934899 | D10: ='Income Statement'!D10/'Income Statement'!D5 -> 0.49171894 | E10: ='Income Statement'!E10/'Income Statement'!E5 -> 0.55226972 | F10: n/a | G10: n/a | H10: n/a | I10: n/a | J10: n/a
A11: Depreciation & amortisation | B11: ='Income Statement'!B12/'Income Statement'!B5 -> 0.26182759 | C11: ='Income Statement'!C12/'Income Statement'!C5 -> 0.2636183 | D11: ='Income Statement'!D12/'Income Statement'!D5 -> 0.26343325 | E11: ='Income Statement'!E12/'Income Statement'!E5 -> 0.24984714 | F11: n/a | G11: n/a | H11: n/a | I11: n/a | J11: n/a
A12: EBIT | B12: ='Income Statement'!B13/'Income Statement'!B5 -> 0.25040066 | C12: ='Income Statement'!C13/'Income Statement'!C5 -> 0.25573069 | D12: ='Income Statement'!D13/'Income Statement'!D5 -> 0.22828569 | E12: ='Income Statement'!E13/'Income Statement'!E5 -> 0.30242258 | F12: n/a | G12: n/a | H12: n/a | I12: n/a | J12: n/a
A13: Other income | B13: ='Income Statement'!B15/'Income Statement'!B5 -> 0.0073232958 | C13: ='Income Statement'!C15/'Income Statement'!C5 -> -0.020189089 | D13: ='Income Statement'!D15/'Income Statement'!D5 -> 0.11944388 | E13: ='Income Statement'!E15/'Income Statement'!E5 -> 0.013864333 | F13: n/a | G13: n/a | H13: n/a | I13: n/a | J13: n/a
A14: Finance costs | B14: ='Income Statement'!B16/'Income Statement'!B5 -> 0.13870423 | C14: ='Income Statement'!C16/'Income Statement'!C5 -> 0.15100479 | D14: ='Income Statement'!D16/'Income Statement'!D5 -> 0.12575657 | E14: ='Income Statement'!E16/'Income Statement'!E5 -> 0.10216947 | F14: n/a | G14: n/a | H14: n/a | I14: n/a | J14: n/a
A15: Profit before tax | B15: ='Income Statement'!B18/'Income Statement'!B5 -> 0.11901973 | C15: ='Income Statement'!C18/'Income Statement'!C5 -> 0.084536811 | D15: ='Income Statement'!D18/'Income Statement'!D5 -> 0.221973 | E15: ='Income Statement'!E18/'Income Statement'!E5 -> 0.21411745 | F15: n/a | G15: n/a | H15: n/a | I15: n/a | J15: n/a
A16: Tax | B16: ='Income Statement'!B19/'Income Statement'!B5 -> 0.030945417 | C16: ='Income Statement'!C19/'Income Statement'!C5 -> 0.027051913 | D16: ='Income Statement'!D19/'Income Statement'!D5 -> 0.0044396913 | E16: ='Income Statement'!E19/'Income Statement'!E5 -> 0.053529599 | F16: n/a | G16: n/a | H16: n/a | I16: n/a | J16: n/a
A17: Net income | B17: ='Income Statement'!B20/'Income Statement'!B5 -> 0.088303568 | C17: ='Income Statement'!C20/'Income Statement'!C5 -> 0.057060181 | D17: ='Income Statement'!D20/'Income Statement'!D5 -> 0.21667197 | E17: ='Income Statement'!E20/'Income Statement'!E5 -> 0.16031909 | F17: n/a | G17: n/a | H17: n/a | I17: n/a | J17: n/a
A19: BALANCE SHEET AS % OF TOTAL ASSETS
A20: % of total assets | B20: FY23A | C20: FY24A | D20: FY25A | E20: FY26A | F20: FY27E | G20: FY28E | H20: FY29E | I20: FY30E | J20: FY31E
A21: Cash | B21: ='Balance Sheet'!B6/'Balance Sheet'!B18 -> 0.030185106 | C21: ='Balance Sheet'!C6/'Balance Sheet'!C18 -> 0.036966737 | D21: ='Balance Sheet'!D6/'Balance Sheet'!D18 -> 0.033108518 | E21: ='Balance Sheet'!E6/'Balance Sheet'!E18 -> 0.055699494 | F21: n/a | G21: n/a | H21: n/a | I21: n/a | J21: n/a
A22: Trade receivables | B22: ='Balance Sheet'!B8/'Balance Sheet'!B18 -> 0.0089572316 | C22: ='Balance Sheet'!C8/'Balance Sheet'!C18 -> 0.010696373 | D22: ='Balance Sheet'!D8/'Balance Sheet'!D18 -> 0.014764181 | E22: ='Balance Sheet'!E8/'Balance Sheet'!E18 -> 0.01462852 | F22: n/a | G22: n/a | H22: n/a | I22: n/a | J22: n/a
A23: Inventories | B23: ='Balance Sheet'!B9/'Balance Sheet'!B18 -> 0.00058035303 | C23: ='Balance Sheet'!C9/'Balance Sheet'!C18 -> 0.00082349401 | D23: ='Balance Sheet'!D9/'Balance Sheet'!D18 -> 0.00089503887 | E23: ='Balance Sheet'!E9/'Balance Sheet'!E18 -> 0.0011019981 | F23: n/a | G23: n/a | H23: n/a | I23: n/a | J23: n/a
A24: Current assets | B24: n/a | C24: n/a | D24: n/a | E24: n/a | F24: n/a | G24: n/a | H24: n/a | I24: n/a | J24: n/a
A25: PPE (net) | B25: ='Balance Sheet'!B13/'Balance Sheet'!B18 -> 0.62397848 | C25: ='Balance Sheet'!C13/'Balance Sheet'!C18 -> 0.68617639 | D25: ='Balance Sheet'!D13/'Balance Sheet'!D18 -> 0.76923442 | E25: ='Balance Sheet'!E13/'Balance Sheet'!E18 -> 0.74506255 | F25: n/a | G25: n/a | H25: n/a | I25: n/a | J25: n/a
A26: Intangibles & goodwill | B26: n/a | C26: n/a | D26: n/a | E26: n/a | F26: n/a | G26: n/a | H26: n/a | I26: n/a | J26: n/a
A27: Non-current investments | B27: ='Balance Sheet'!B15/'Balance Sheet'!B18 -> 0.074127727 | C27: ='Balance Sheet'!C15/'Balance Sheet'!C18 -> 0.071494664 | D27: ='Balance Sheet'!D15/'Balance Sheet'!D18 -> 0.011560259 | E27: ='Balance Sheet'!E15/'Balance Sheet'!E18 -> 0.034657015 | F27: n/a | G27: n/a | H27: n/a | I27: n/a | J27: n/a
A28: Total assets | B28: ='Balance Sheet'!B18/'Balance Sheet'!B18 -> 1 | C28: ='Balance Sheet'!C18/'Balance Sheet'!C18 -> 1 | D28: ='Balance Sheet'!D18/'Balance Sheet'!D18 -> 1 | E28: ='Balance Sheet'!E18/'Balance Sheet'!E18 -> 1 | F28: n/a | G28: n/a | H28: n/a | I28: n/a | J28: n/a
A29: Trade payables | B29: ='Balance Sheet'!B20/'Balance Sheet'!B18 -> 0.073995011 | C29: ='Balance Sheet'!C20/'Balance Sheet'!C18 -> 0.079480746 | D29: ='Balance Sheet'!D20/'Balance Sheet'!D18 -> 0.075551578 | E29: ='Balance Sheet'!E20/'Balance Sheet'!E18 -> 0.08253984 | F29: n/a | G29: n/a | H29: n/a | I29: n/a | J29: n/a
A30: Short-term borrowings | B30: n/a | C30: n/a | D30: n/a | E30: n/a | F30: n/a | G30: n/a | H30: n/a | I30: n/a | J30: n/a
A31: Long-term debt | B31: n/a | C31: n/a | D31: n/a | E31: n/a | F31: n/a | G31: n/a | H31: n/a | I31: n/a | J31: n/a
A32: Total liabilities | B32: n/a | C32: n/a | D32: n/a | E32: n/a | F32: n/a | G32: n/a | H32: n/a | I32: n/a | J32: n/a
A33: Total equity | B33: n/a | C33: n/a | D33: n/a | E33: n/a | F33: n/a | G33: n/a | H33: n/a | I33: n/a | J33: n/a
A35: RETURNS AND DUPONT (reported years; engine ratios)
B36: FY23A | C36: FY24A | D36: FY25A | E36: FY26A | F36: FY27EA | G36: FY28EA | H36: FY29EA | I36: FY30EA | J36: FY31EA
A37: Return on equity | B37: 0.15841316 | C37: 0.1072552 | D37: 0.38306309 | E37: 0.25747443 | F37: n/a | G37: n/a | H37: n/a | I37: n/a | J37: n/a
A38: Return on assets | B38: 0.02763875 | C38: 0.019305734 | D38: 0.079155249 | E38: 0.064401516 | F38: n/a | G38: n/a | H38: n/a | I38: n/a | J38: n/a
A39: Return on capital employed | B39: n/a | C39: n/a | D39: n/a | E39: n/a | F39: n/a | G39: n/a | H39: n/a | I39: n/a | J39: n/a
A40: Return on invested capital | B40: n/a | C40: n/a | D40: n/a | E40: n/a | F40: n/a | G40: n/a | H40: n/a | I40: n/a | J40: n/a
A41: DuPont: net margin | B41: 0.088303568 | C41: 0.057060181 | D41: 0.21667197 | E41: 0.16031909 | F41: n/a | G41: n/a | H41: n/a | I41: n/a | J41: n/a
A42: DuPont: asset turnover (x) | B42: 0.31299698 | C42: 0.33833986 | D42: 0.36532299 | E42: 0.40170834 | F42: n/a | G42: n/a | H42: n/a | I42: n/a | J42: n/a
A43: DuPont: equity multiplier (x) | B43: 5.7315602 | C43: 5.555614 | D43: 4.8393897 | E43: 3.9979561 | F43: n/a | G43: n/a | H43: n/a | I43: n/a | J43: n/a
...

Sheet Schedules
A1: Schedules: fixed assets, working capital, capital allocation, leverage, segments
A2: Live formulas over the statement sheets (reported and forecast on one axis). A year whose source lines are absent shows n/a.
A4: FIXED ASSETS, CAPEX AND DEPRECIATION (INR crore)
B5: FY23A | C5: FY24A | D5: FY25A | E5: FY26A | F5: FY27E | G5: FY28E | H5: FY29E | I5: FY30E | J5: FY31E
A6: Property, plant & equipment (net) | B6: ='Balance Sheet'!B13 -> 277394 | C6: ='Balance Sheet'!C13 -> 303303 | D6: ='Balance Sheet'!D13 -> 388468 | E6: ='Balance Sheet'!E13 -> 406337 | F6: n/a | G6: n/a | H6: n/a | I6: n/a | J6: n/a
A7: Capital expenditure (outflow shown positive) | B7: =ABS('Cash Flow'!B15) -> 26538 | C7: =ABS('Cash Flow'!C15) -> 40052 | D7: =ABS('Cash Flow'!D15) -> 39680 | E7: =ABS('Cash Flow'!E15) -> 46714 | F7: n/a | G7: n/a | H7: n/a | I7: n/a | J7: n/a
A8: Depreciation & amortisation | B8: ='Income Statement'!B12 -> 36432 | C8: ='Income Statement'!C12 -> 39538 | D8: ='Income Statement'!D12 -> 45570 | E8: ='Income Statement'!E12 -> 52711 | F8: n/a | G8: n/a | H8: n/a | I8: n/a | J8: n/a
A9: Capex / revenue | B9: =B7/'Income Statement'!B5 -> 0.19072191 | C9: =C7/'Income Statement'!C5 -> 0.26704538 | D9: =D7/'Income Statement'!D5 -> 0.22938405 | E9: =E7/'Income Statement'!E5 -> 0.2214217 | F9: n/a | G9: n/a | H9: n/a | I9: n/a | J9: n/a
A10: Capex / depreciation (x) | B10: =B7/B8 -> 0.72842556 | C10: =C7/C8 -> 1.0130002 | D10: =D7/D8 -> 0.8707483 | E10: =E7/E8 -> 0.88622868 | F10: n/a | G10: n/a | H10: n/a | I10: n/a | J10: n/a
A11: Depreciation / opening net PPE | B11: n/a | C11: =C8/B6 -> 0.14253372 | D11: =D8/C6 -> 0.15024579 | E11: =E8/D6 -> 0.13568943 | F11: n/a | G11: n/a | H11: n/a | I11: n/a | J11: n/a
A12: Maintenance capex (CAPEX_BELOW_DEPRECIATION) | B12: 26538 | C12: 39538 | D12: 39680 | E12: 46714 | F12: n/a | G12: n/a | H12: n/a | I12: n/a | J12: n/a
A13: Growth capex (total less maintenance) | B13: 0 | C13: 514 | D13: 0 | E13: 0 | F13: n/a | G13: n/a | H13: n/a | I13: n/a | J13: n/a
A14: Maintenance share ranged 1.3pp across 4 years (98.7% to 100.0%).
A16: WORKING CAPITAL (INR crore; days on a 365-day year)
B17: FY23A | C17: FY24A | D17: FY25A | E17: FY26A | F17: FY27E | G17: FY28E | H17: FY29E | I17: FY30E | J17: FY31E
A18: Trade receivables | B18: ='Balance Sheet'!B8 -> 3982 | C18: ='Balance Sheet'!C8 -> 4728 | D18: ='Balance Sheet'!D8 -> 7456 | E18: ='Balance Sheet'!E8 -> 7978 | F18: n/a | G18: n/a | H18: n/a | I18: n/a | J18: n/a
A19: Inventories | B19: ='Balance Sheet'!B9 -> 258 | C19: ='Balance Sheet'!C9 -> 364 | D19: ='Balance Sheet'!D9 -> 452 | E19: ='Balance Sheet'!E9 -> 601 | F19: n/a | G19: n/a | H19: n/a | I19: n/a | J19: n/a
A20: Trade payables | B20: ='Balance Sheet'!B20 -> 32895 | C20: ='Balance Sheet'!C20 -> 35132 | D20: ='Balance Sheet'!D20 -> 38154 | E20: ='Balance Sheet'!E20 -> 45015 | F20: n/a | G20: n/a | H20: n/a | I20: n/a | J20: n/a
A21: Trade working capital (receivables + inventories - payables) | B21: =B18+B19-B20 -> -28655 | C21: =C18+C19-C20 -> -30040 | D21: =D18+D19-D20 -> -30246 | E21: =E18+E19-E20 -> -36436 | F21: n/a | G21: n/a | H21: n/a | I21: n/a | J21: n/a
A22: Receivable days (on revenue) | B22: =B18/'Income Statement'!B5*365 -> 10.445435 | C22: =C18/'Income Statement'!C5*365 -> 11.506181 | D22: =D18/'Income Statement'!D5*365 -> 15.732231 | E22: =E18/'Income Statement'!E5*365 -> 13.802572 | F22: n/a | G22: n/a | H22: n/a | I22: n/a | J22: n/a
A23: Payable days (on total operating expenses) | B23: =B20/'Income Statement'!B9*365 -> 176.90435 | C23: =C20/'Income Statement'!C9*365 -> 177.87984 | D23: =D20/'Income Statement'!D9*365 -> 158.38738 | E23: =E20/'Income Statement'!E9*365 -> 173.94293 | F23: n/a | G23: n/a | H23: n/a | I23: n/a | J23: n/a
A24: Inventory days (on total operating expenses) | B24: =B19/'Income Statement'!B9*365 -> 1.3874851 | C24: =C19/'Income Statement'!C9*365 -> 1.8429996 | D24: =D19/'Income Statement'!D9*365 -> 1.8763719 | E24: =E19/'Income Statement'!E9*365 -> 2.3223303 | F24: n/a | G24: n/a | H24: n/a | I24: n/a | J24: n/a
A25: Inventory and payable days use total operating expenses as the cost base because the statements do not all carry cost of goods sold; they are comparable across years of this issuer, not to a peer using cost of sales.
A27: CAPITAL ALLOCATION AND LEVERAGE (INR crore)
B28: FY23A | C28: FY24A | D28: FY25A | E28: FY26A | F28: FY27E | G28: FY28E | H28: FY29E | I28: FY30E | J28: FY31E
A29: Cash from operations | B29: ='Cash Flow'!B13 -> 65325 | C29: ='Cash Flow'!C13 -> 78898 | D29: ='Cash Flow'!D13 -> 98332 | E29: ='Cash Flow'!E13 -> 122230 | F29: n/a | G29: n/a | H29: n/a | I29: n/a | J29: n/a
A30: Free cash flow (CFO - capex) | B30: =B29-B7 -> 38787 | C30: =C29-C7 -> 38846 | D30: =D29-D7 -> 58652 | E30: =E29-E7 -> 75516 | F30: n/a | G30: n/a | H30: n/a | I30: n/a | J30: n/a
A31: Dividends paid (outflow shown positive) | B31: n/a | C31: n/a | D31: n/a | E31: n/a | F31: n/a | G31: n/a | H31: n/a | I31: n/a | J31: n/a
A32: Dividend payout (dividends / net income) | B32: n/a | C32: n/a | D32: n/a | E32: n/a | F32: n/a | G32: n/a | H32: n/a | I32: n/a | J32: n/a
A33: Debt issued / (repaid) | B33: n/a | C33: n/a | D33: n/a | E33: n/a | F33: n/a | G33: n/a | H33: n/a | I33: n/a | J33: n/a
A34: Share issuance / (repurchase) | B34: n/a | C34: n/a | D34: n/a | E34: n/a | F34: n/a | G34: n/a | H34: n/a | I34: n/a | J34: n/a
A35: Gross borrowings (short-term + long-term) | B35: n/a | C35: n/a | D35: n/a | E35: n/a | F35: n/a | G35: n/a | H35: n/a | I35: n/a | J35: n/a
A36: Cash and short-term investments | B36: n/a | C36: n/a | D36: n/a | E36: n/a | F36: n/a | G36: n/a | H36: n/a | I36: n/a | J36: n/a
A37: Net debt (borrowings - cash and short-term investments; excludes leases and long-term investments) | B37: n/a | C37: n/a | D37: n/a | E37: n/a | F37: n/a | G37: n/a | H37: n/a | I37: n/a | J37: n/a
A38: Net debt / EBITDA (x) | B38: n/a | C38: n/a | D38: n/a | E38: n/a | F38: n/a | G38: n/a | H38: n/a | I38: n/a | J38: n/a
A40: Operating segments: no Ind AS 108 segment disclosure was read for this issuer and the provider published no split.
A42: SECTOR SCHEDULE (TELECOM)
A43: Sector template | B43: Telecommunications & Digital Infrastructure
A44: Primary revenue method | B44: subscriber_arpu_build
A45: Key drivers | B45: subscriberGrowth; arpuGrowth; ebitdaMargin; capexPercentOfRevenue; netDebtToEbitda
...

Sheet Facts
A1: Facts: raw as-filed lines, canonical resolution, source documents
A2: The lines the statements were built from, by XBRL concept and fiscal year (INR crore), the canonical value against every second source with the authority that decided it, and the filings (hash, URL, retrieval time).
A4: As-filed statements: UNAVAILABLE no audited statutory XBRL filing was served for this issuer; the statements are not laid out line by line
A6: CANONICAL VS SECOND SOURCE (canonical provider SCREENER_INDIA; NOT a primary filing; policy 2026-09-30.1)
A7: Rows 80: 36 agree, 21 conflict, 0 second source unavailable, 23 not comparable. The canonical value is never averaged with a second source.
A8: Field | B8: Fiscal year | C8: Canonical provider | D8: Canonical value | E8: Second provider | F8: Second value | G8: Agreement | H8: Relative difference | I8: Final value / provider
A9: Revenue from operations | B9: FY23 | C9: SCREENER_INDIA | D9: 139145 | E9: YAHOO_INDIA | F9: 139144.8 | G9: AGREE | H9: 1.4373495e-06 | I9: 139145 (SCREENER_INDIA)
A10: Depreciation & amortisation | B10: FY23 | C10: SCREENER_INDIA | D10: 36432 | E10: YAHOO_INDIA | F10: 36431.8 | G10: AGREE | H10: 5.4896794e-06 | I10: 36432 (SCREENER_INDIA)
A11: Finance costs | B11: FY23 | C11: SCREENER_INDIA | D11: 19300 | E11: YAHOO_INDIA | F11: 14295.5 | G11: CONFLICT | H11: 0.25930052 | I11: 19300 (SCREENER_INDIA)
A12: Profit before tax | B12: FY23 | C12: SCREENER_INDIA | D12: 16561 | E12: YAHOO_INDIA | F12: 16560.7 | G12: AGREE | H12: 1.8114848e-05 | I12: 16561 (SCREENER_INDIA)
A13: Tax expense | B13: FY23 | C13: SCREENER_INDIA | D13: 4305.86 | E13: YAHOO_INDIA | F13: 4273.3 | G13: CONFLICT | H13: 0.0075617879 | I13: 4305.86 (SCREENER_INDIA)
A14: Profit for the period (total, incl. NCI) | B14: FY23 | C14: SCREENER_INDIA | D14: 12287 | E14: YAHOO_INDIA | F14: 8345.9 | G14: CONFLICT | H14: 0.32075364 | I14: 12287 (SCREENER_INDIA)
A15: Profit attributable to owners | B15: FY23 | C15: SCREENER_INDIA | D15: n/a | E15: YAHOO_INDIA | F15: 8345.9 | G15: NOT_COMPARABLE | H15: n/a | I15: null (null)
A16: Diluted EPS (as filed, unrestated) | B16: FY23 | C16: SCREENER_INDIA | D16: n/a | E16: YAHOO_INDIA | F16: 14.57 | G16: NOT_COMPARABLE | H16: n/a | I16: null (null)
A17: Total assets | B17: FY23 | C17: SCREENER_INDIA | D17: 444557 | E17: YAHOO_INDIA | F17: 446633.2 | G17: AGREE | H17: 0.0046702673 | I17: 444557 (SCREENER_INDIA)
A18: Total equity (incl. NCI) | B18: FY23 | C18: SCREENER_INDIA | D18: n/a | E18: YAHOO_INDIA | F18: 106444.3 | G18: NOT_COMPARABLE | H18: n/a | I18: null (null)
A19: Equity attributable to owners | B19: FY23 | C19: SCREENER_INDIA | D19: 77563 | E19: YAHOO_INDIA | F19: 77562.9 | G19: AGREE | H19: 1.2892745e-06 | I19: 77563 (SCREENER_INDIA)
A20: Equity share capital (paid-up value) | B20: FY23 | C20: SCREENER_INDIA | D20: 2837 | E20: YAHOO_INDIA | F20: 2836.6 | G20: AGREE | H20: 0.00014099401 | I20: 2837 (SCREENER_INDIA)
A21: Borrowings (non-current) | B21: FY23 | C21: SCREENER_INDIA | D21: n/a | E21: YAHOO_INDIA | F21: 151568.6 | G21: NOT_COMPARABLE | H21: n/a | I21: null (null)
A22: Borrowings (current) | B22: FY23 | C22: SCREENER_INDIA | D22: n/a | E22: YAHOO_INDIA | F22: 13976.2 | G22: NOT_COMPARABLE | H22: n/a | I22: null (null)
A23: Cash and cash equivalents | B23: FY23 | C23: SCREENER_INDIA | D23: 13419 | E23: YAHOO_INDIA | F23: 7179.4 | G23: CONFLICT | H23: 0.46498249 | I23: 13419 (SCREENER_INDIA)
A24: Cash flow from operations | B24: FY23 | C24: SCREENER_INDIA | D24: 65325 | E24: YAHOO_INDIA | F24: 65324.6 | G24: AGREE | H24: 6.12323e-06 | I24: 65325 (SCREENER_INDIA)
A25: Cash flow from investing | B25: FY23 | C25: SCREENER_INDIA | D25: -39232 | E25: YAHOO_INDIA | F25: -39080.2 | G25: AGREE | H25: 0.0038692904 | I25: -39232 (SCREENER_INDIA)
A26: Cash flow from financing | B26: FY23 | C26: SCREENER_INDIA | D26: -24470 | E26: YAHOO_INDIA | F26: -24469.5 | G26: AGREE | H26: 2.0433183e-05 | I26: -24470 (SCREENER_INDIA)
A27: Capital expenditure (magnitude) | B27: FY23 | C27: SCREENER_INDIA | D27: -26538 | E27: YAHOO_INDIA | F27: -26538.5 | G27: AGREE | H27: 1.8840907e-05 | I27: -26538 (SCREENER_INDIA)
A28: Share count | B28: FY23 | C28: SCREENER_INDIA | D28: n/a | E28: YAHOO_INDIA | F28: 596.45 | G28: NOT_COMPARABLE | H28: n/a | I28: null (null)
A29: Revenue from operations | B29: FY24 | C29: SCREENER_INDIA | D29: 149982 | E29: YAHOO_INDIA | F29: 149982.4 | G29: AGREE | H29: 2.6669867e-06 | I29: 149982 (SCREENER_INDIA)
A30: Depreciation & amortisation | B30: FY24 | C30: SCREENER_INDIA | D30: 39538 | E30: YAHOO_INDIA | F30: 39537.6 | G30: AGREE | H30: 1.011685e-05 | I30: 39538 (SCREENER_INDIA)
A31: Finance costs | B31: FY24 | C31: SCREENER_INDIA | D31: 22648 | E31: YAHOO_INDIA | F31: 15955.9 | G31: CONFLICT | H31: 0.29548304 | I31: 22648 (SCREENER_INDIA)
A32: Profit before tax | B32: FY24 | C32: SCREENER_INDIA | D32: 12679 | E32: YAHOO_INDIA | F32: 12679 | G32: AGREE | H32: 0 | I32: 12679 (SCREENER_INDIA)
A33: Tax expense | B33: FY24 | C33: SCREENER_INDIA | D33: 4057.28 | E33: YAHOO_INDIA | F33: 4121 | G33: CONFLICT | H33: 0.015705103 | I33: 4057.28 (SCREENER_INDIA)
A34: Profit for the period (total, incl. NCI) | B34: FY24 | C34: SCREENER_INDIA | D34: 8558 | E34: YAHOO_INDIA | F34: 7467 | G34: CONFLICT | H34: 0.12748306 | I34: 8558 (SCREENER_INDIA)
A35: Profit attributable to owners | B35: FY24 | C35: SCREENER_INDIA | D35: n/a | E35: YAHOO_INDIA | F35: 7467 | G35: NOT_COMPARABLE | H35: n/a | I35: null (null)
A36: Diluted EPS (as filed, unrestated) | B36: FY24 | C36: SCREENER_INDIA | D36: n/a | E36: YAHOO_INDIA | F36: 12.8 | G36: NOT_COMPARABLE | H36: n/a | I36: null (null)
A37: Total assets | B37: FY24 | C37: SCREENER_INDIA | D37: 442019 | E37: YAHOO_INDIA | F37: 444531 | G37: CONFLICT | H37: 0.0056830136 | I37: 442019 (SCREENER_INDIA)
A38: Total equity (incl. NCI) | B38: FY24 | C38: SCREENER_INDIA | D38: n/a | E38: YAHOO_INDIA | F38: 105563.9 | G38: NOT_COMPARABLE | H38: n/a | I38: null (null)
A39: Equity attributable to owners | B39: FY24 | C39: SCREENER_INDIA | D39: 82019 | E39: YAHOO_INDIA | F39: 82018.8 | G39: AGREE | H39: 2.4384594e-06 | I39: 82019 (SCREENER_INDIA)
A40: Equity share capital (paid-up value) | B40: FY24 | C40: SCREENER_INDIA | D40: 2877 | E40: YAHOO_INDIA | F40: 2876.6 | G40: AGREE | H40: 0.00013903372 | I40: 2877 (SCREENER_INDIA)
A41: Borrowings (non-current) | B41: FY24 | C41: SCREENER_INDIA | D41: n/a | E41: YAHOO_INDIA | F41: 130962.6 | G41: NOT_COMPARABLE | H41: n/a | I41: null (null)
A42: Borrowings (current) | B42: FY24 | C42: SCREENER_INDIA | D42: n/a | E42: YAHOO_INDIA | F42: 20953.9 | G42: NOT_COMPARABLE | H42: n/a | I42: null (null)
...

Sheet Change Log
A1: Change log
A2: What changed, and against what. Vintages are saved snapshots of this issuer (each immutable, each with its hash); a change in fair value between two of them is the engine's, not this sheet's.
A4: SAVED SNAPSHOT VINTAGES OF THIS ISSUER (newest first; this workbook is marked)
A5: Snapshot | B5: Built at | C5: Price (INR) | D5: Price as of | E5: Primary method | F5: Fair value per share (INR) | G5: Change vs this workbook (INR) | H5: Change (%) | I5: Assumptions hash (12)
A6: snap_BHARTIARTL_NS_24392f289409 <- THIS WORKBOOK | B6: 2026-11-01T14:58:12.989Z | C6: 1973.7 | D6: 2026-10-30T00:00:00.000Z | E6: FCFF_DCF_3STAGE | F6: 2359.67 | G6: 0 | H6: 0 | I6: 74234e98afe7
A7: snap_BHARTIARTL_NS_7195e2e64806 | B7: 2026-11-01T14:58:12.919Z | C7: 1973.7 | D7: 2026-10-30T00:00:00.000Z | E7: FCFF_DCF_3STAGE | F7: 2359.67 | G7: =F7-2359.67 -> 0 | H7: =G7/2359.67 -> 0 | I7: 74234e98afe7
A8: snap_BHARTIARTL_NS_99ed6aabf652 | B8: 2026-11-01T14:56:15.406Z | C8: 1973.7 | D8: 2026-10-30T00:00:00.000Z | E8: FCFF_DCF_3STAGE | F8: 2359.67 | G8: =F8-2359.67 -> 0 | H8: =G8/2359.67 -> 0 | I8: 74234e98afe7
A9: snap_BHARTIARTL_NS_1cb45ecbf0ba | B9: 2026-11-01T14:56:15.338Z | C9: 1973.7 | D9: 2026-10-30T00:00:00.000Z | E9: FCFF_DCF_3STAGE | F9: 2359.67 | G9: =F9-2359.67 -> 0 | H9: =G9/2359.67 -> 0 | I9: 74234e98afe7
A10: snap_BHARTIARTL_NS_8488fd8785e3 | B10: 2026-11-01T14:53:10.113Z | C10: 1973.7 | D10: 2026-10-30T00:00:00.000Z | E10: FCFF_DCF_3STAGE | F10: 2359.67 | G10: =F10-2359.67 -> 0 | H10: =G10/2359.67 -> 0 | I10: 74234e98afe7
A11: snap_BHARTIARTL_NS_6360ae76accb | B11: 2026-11-01T14:53:10.033Z | C11: 1973.7 | D11: 2026-10-30T00:00:00.000Z | E11: FCFF_DCF_3STAGE | F11: 2359.67 | G11: =F11-2359.67 -> 0 | H11: =G11/2359.67 -> 0 | I11: 74234e98afe7
A13: OVERRIDES APPLIED TO THIS WORKBOOK
A14: None: this is the base case (every driver is history-derived or a disclosed model policy).
A16: RESTATEMENTS, PERIOD BREAKS AND SOURCE CONFLICTS IN THE DATA
A17: Diagnostic WARNING | B17: WARN_LEGACY_COMPATIBILITY_WITHHELD | C17: The legacy compatibility forecast, multi-stage DCF, scenarios and sensitivities are withheld: ERROR_INPUT_UNAVAILABLE: the FY26 statements do not serve otherCurrentAssets, intangibleAssetsAndGoodwill, otherNonCurrentAssets, shortTermBorrowings, otherCurrentLiabilities, longTermDebt, leaseLiabilities, deferredTaxLiabilities, otherNonCurrentLiabilities, otherEquity, minorityInterest; the integrated forecast rolls every one of them forward. Refusing to open them at 0.
A18: Diagnostic WARNING | B18: WARN_HIST_CASH_ROLL | C18: HIST_CASH_ROLL: FY24: opening 13,419 + net change 31 = 13,450, closing reported 16,340 | FY25: opening 16,340 + net change 1,601 = 17,941, closing reported 16,720
A19: 21 provider conflict(s) between the canonical filing value and a second source are listed on the Facts sheet; the filing value stands.

Sheet Source Audit
A1: Source audit: provenance, accounting and recalculation checks, peer selection, limits
A2: Every figure carries its filing; every identity the model must satisfy is listed with its result; nothing that failed is dropped.
A4: PROVENANCE (8 sourced figures)
A5: Line item | B5: Fiscal year | C5: Value | D5: Unit | E5: Type | F5: Confidence | G5: Source filing | H5: URL | I5: sha256 of the stored filing | J5: Basis note
A6: Revenue (FY23) | B6: FY23 | C6: 139145 | D6: Crores | E6: PROVIDER_REPORTED | F6: Provider Reported | G6: Screener.in structured statements (Consolidated; secondary aggregator) | H6: n/a | I6: n/a | J6: REVENUE_BASIS_NOT_ASSESSED: this is the aggregator's "Sales" line. It is not reconciled to the filed Revenue from operations and can be lower where the aggregator nets excise duty or cess. Compare with the audited filing before reading margins.
A7: Net Income / PAT (FY23) | B7: FY23 | C7: 12287 | D7: Crores | E7: PROVIDER_REPORTED | F7: Provider Reported | G7: Screener.in structured statements (Consolidated; secondary aggregator) | H7: n/a | I7: n/a | J7: n/a
A8: Revenue (FY24) | B8: FY24 | C8: 149982 | D8: Crores | E8: PROVIDER_REPORTED | F8: Provider Reported | G8: Screener.in structured statements (Consolidated; secondary aggregator) | H8: n/a | I8: n/a | J8: REVENUE_BASIS_NOT_ASSESSED: this is the aggregator's "Sales" line. It is not reconciled to the filed Revenue from operations and can be lower where the aggregator nets excise duty or cess. Compare with the audited filing before reading margins.
A9: Net Income / PAT (FY24) | B9: FY24 | C9: 8558 | D9: Crores | E9: PROVIDER_REPORTED | F9: Provider Reported | G9: Screener.in structured statements (Consolidated; secondary aggregator) | H9: n/a | I9: n/a | J9: n/a
A10: Revenue (FY25) | B10: FY25 | C10: 172985 | D10: Crores | E10: PROVIDER_REPORTED | F10: Provider Reported | G10: Screener.in structured statements (Consolidated; secondary aggregator) | H10: n/a | I10: n/a | J10: REVENUE_BASIS_NOT_ASSESSED: this is the aggregator's "Sales" line. It is not reconciled to the filed Revenue from operations and can be lower where the aggregator nets excise duty or cess. Compare with the audited filing before reading margins.
A11: Net Income / PAT (FY25) | B11: FY25 | C11: 37481 | D11: Crores | E11: PROVIDER_REPORTED | F11: Provider Reported | G11: Screener.in structured statements (Consolidated; secondary aggregator) | H11: n/a | I11: n/a | J11: n/a
A12: Revenue (FY26) | B12: FY26 | C12: 210973 | D12: Crores | E12: PROVIDER_REPORTED | F12: Provider Reported | G12: Screener.in structured statements (Consolidated; secondary aggregator) | H12: n/a | I12: n/a | J12: REVENUE_BASIS_NOT_ASSESSED: this is the aggregator's "Sales" line. It is not reconciled to the filed Revenue from operations and can be lower where the aggregator nets excise duty or cess. Compare with the audited filing before reading margins.
A13: Net Income / PAT (FY26) | B13: FY26 | C13: 33823 | D13: Crores | E13: PROVIDER_REPORTED | F13: Provider Reported | G13: Screener.in structured statements (Consolidated; secondary aggregator) | H13: n/a | I13: n/a | J13: n/a
A15: ACCOUNTING AND RECALCULATION CHECKS (3 run; 3 pass; 0 not a plain pass, all shown first)
A16: Check | B16: Scope | C16: Status | D16: Computed | E16: Reported | F16: Difference | G16: Detail
A17: No DCF stance without a DCF | B17: VALUATION | C17: PASS | D17: n/a | E17: n/a | F17: n/a | G17: DCF ran; stance derived from it only
A18: No bonus / split is classified as economic dilution | B18: HISTORICAL | C18: PASS | D18: n/a | E18: n/a | F18: n/a | G18: no share-count events
A19: Canonical v1 accounting invariants | B19: Critical Integrity Checks | C19: PASS | D19: n/a | E19: n/a | F19: n/a | G19: All canonical v1 accounting invariants hold across every projected period.
A21: PEER SELECTION (status UNAVAILABLE)
A22: peer sample too small for statistics (n=2); peer values are shown, no median/quartile is claimed
A23: Peer set | B23: Scope | C23: Selection rule | D23: Rationale | E23: Members
A24: Whole-company comparable set | B24: COMPANY | C24: analyst-defined TELECOM universe, subject excluded | D24: Listed Indian telecom operators (a small set: Jio sits inside RELIANCE, BSNL is unlisted, tower companies are not operators). | E24: IDEA.NS, TATACOMM.NS
A26: PUBLICATION STATE AND LIMITS
A27: Statement perimeter | B27: Consolidated
A28: Analysis status | B28: SUCCESS
A29: Valuation status | B29: VALID
A30: Primary method | B30: FCFF_DCF_3STAGE
A31: Model package status | B31: EXECUTED_WITHHELD
A32: Confidence | B32: MEDIUM
A33: Peer intelligence | B33: UNAVAILABLE
A34: Withheld / not measured | B34: Linked three-statement forecast | C34: the reported FY26 balance sheet does not balance as opened (assets 545373 vs liabilities + equity 389484 Cr); no forecast is built on it
A35: Withheld / not measured | B35: Segment analysis | C35: no Ind AS 108 segment disclosure was read for this issuer and the provider published no split
A36: Withheld / not measured | B36: Line-by-line statutory statements | C36: no audited statutory XBRL filing was served for this issuer; the statements are not laid out line by line
A37: Withheld / not measured | B37: Audited-filing statements | C37: The statements are a secondary tier's (SCREENER_INDIA); NSE corporate actions: RIGHTS_BLOCKED: NSE session-cookie API is paused by the owner pending legal review (nseSessionCookie); set ASTRA_ALLOW_NSE_SESSION_API=1 only after that review | NSE audited XBRL: NSE filing index unreachable: RIGHTS_BLOCKED: NSE session-cookie API is paused by the owner pending legal review (nseSessionCookie); set ASTRA_ALLOW_NSE_SESSION_API=1 only after that review.
A38: Confidence gate | B38: Reported statutory provenance coverage is low (0% of fields read from a filing; a further 100% are provider-reported statements, which are attributed but not statutory).
A40: SAVED RECORD AND VERIFIER RECEIPTS
